Workbook

Sheet Anleitung
A1: Crowdfunding-Rechner — so wird er benutzt
A2: Aufgabe A-21 · erstellt 16.09.2026, fortgeschrieben 21.09.2026 · Grundlage: Handbuch B (Kapitalfahrplan, Abopreise, Einmalkosten), finanzmodell.xlsx (Szenario realistisch), Plattformseiten abgerufen am 16.09.2026 · ENTWURF — die Tabelle rechnet, entscheiden tun die Gründer.
A3: LEGENDE: Gelb mit blauer Schrift = Eingabe (Voreinstellung mit Herkunft, änderbar). Alles andere rechnet. ANNAHME = kein Erfahrungswert, bewusst gesetzt.
A5: # | B5: Schritt
A6: 1 | B6: Blatt „Plattformen“: Gebühren vor dem Start neu prüfen. Stand der Werte ist der 16.09.2026; leere gelbe Felder heißen „nicht belegt“.
A7: 2 | B7: Blatt „Stufen“: Preise, Limits und die erwartete Verteilung der Unterstützer festlegen (Entscheidung Nr. 60). Die Anteile müssen zusammen 100 % ergeben — die Prüfzeile sagt es.
A8: 3 | B8: Blatt „PLUS-Wert“: die beiden Annahmen zum Umsatzverzicht prüfen — wie viele Unterstützer hätten PLUS ohnehin gekauft, und wie lange?
A9: 4 | B9: Blatt „Rechner“: Plattform wählen, Besteuerung mit dem Steuerberater klären, Nettobedarf prüfen. Das Blatt nennt Break-even, Mindestbetrag und Wunschbetrag.
A10: 5 | B10: Blatt „Plattformvergleich“: dieselbe Rechnung für alle Plattformen nebeneinander.
A11: 6 | B11: Blatt „Warteliste“: welcher Anteil der Liste unterstützen müsste — und ob die Liste überhaupt angeschrieben werden darf (Nr. 59).
A12: ! | B12: Die Tabelle rechnet nur. Plattform, Stufen, Preise und Zeitpunkt entscheiden die Gründer; die Kampagne startet frühestens, wenn die Warteliste über 1.000 liegt (Handbuch B).
A13: ! | B13: Umsatzsteuer auf Gegenleistungen und Kleinunternehmerregelung sind nicht geklärt — Schalter im Blatt „Rechner“, Fragen im Konzept, Abschnitt 9.
A15: Blätter
A16: # | B16: Blatt und Inhalt
A17: 1 | B17: Rechner — Eingaben, Nettobedarf, Break-even, Mindest- und Wunschbetrag, Faustregeln der Plattform
A18: 2 | B18: Stufen — sechs Gegenleistungsstufen mit Umsatzsteuer, Gebühren, Umsatzverzicht und Beitrag je Stück
A19: 3 | B19: PLUS-Wert — Abopreise aus Handbuch B und der spätere Erlös, den die PLUS-Stufen kosten
A20: 4 | B20: Plattformvergleich — dieselben Stufen bei allen Plattformen
A21: 5 | B21: Warteliste — nötiger Anteil der Liste bei fünf Listengrößen
A22: 6 | B22: Plattformen — Gebühren, Modell, Sitz, Regeln und Quellen
A23: 7 | B23: Quellen — alle Fundstellen mit Abrufdatum
A25: Konzept dazu: 40-finanzen-foerderung/crowdfunding/crowdfunding-konzept.md · Video-Skript: kampagnenvideo-skript-ENTWURF.md

Sheet Rechner
A1: Crowdfunding-Rechner — Break-even, Mindestbetrag, Wunschbetrag
A2: Aufgabe A-21 · erstellt 16.09.2026, fortgeschrieben 21.09.2026 (Nr. 60, A-52) · Grundlage: Handbuch B (Kapitalfahrplan, Abopreise, Einmalkosten), finanzmodell.xlsx (Szenario realistisch), Plattformseiten abgerufen am 16.09.2026 · ENTWURF — die Tabelle rechnet, entscheiden tun die Gründer.
A3: LEGENDE: Gelb mit blauer Schrift = Eingabe (Voreinstellung mit Herkunft, änderbar). Alles andere rechnet. ANNAHME = kein Erfahrungswert, bewusst gesetzt.
A5: Größe | B5: Wert | C5: Herkunft und Hinweis
A6: Eingaben
A7: Plattform | B7: Startnext Basis | C7: Auswahl aus dem Blatt „Plattformen“. Voreinstellung: die deutsche Plattform mit der niedrigsten Provision. Zulässigkeit einer Cruising-App vorher schriftlich klären (Konzept, Abschnitt 3).
A8: Umsatzsteuersatz | B8: 0.19 | C8: Regelsatz. Ob er auf jede Stufe anfällt, klärt der Steuerberater (Konzept, Abschnitt 9).
A9: Umsatzsteuer auf Gegenleistungen abführen? (ja = Regelbesteuerung, nein = Kleinunternehmer) | B9: ja | C9: Voreinstellung wie Handbuch B („Kleinunternehmerregelung greift bei einer GmbH nicht“). Nach IHK Hannover (Stand 22.05.2026) gilt sie auch für Kapitalgesellschaften — offene Entscheidung Nr. 11.
A10: Fixkosten der Kampagne | B10: 300 | C10: Zwei Monatsbudgets „Druck, Material, Reisekosten, Werkzeuge“ vor dem Start (Handbuch B: 150 € je Monat). Video mit eigenem Gerät. Rechtliche Prüfung über die Rückstellung Rechtsberatung aus Handbuch B, hier nicht doppelt gezählt.
A11: Sind die Gebühren der gewählten Plattform belegt? | B11: =IF(INDEX(Plattformen!$D$6:$D$11,MATCH(Rechner!$B$7,Plattformen!$A$6:$A$11,0))="","nein","ja") -> ja | C11: Bei „nein“ sind alle Ergebnisse unten unbrauchbar — andere Plattform wählen.
A13: Nettobedarf — wofür das Geld ist
A14: Penetrationstest | B14: 4000 | C14: Handbuch B, Einmalkosten: Monat 8–9, „Schwerpunkt Standort- und Bildarchitektur. Vor dem öffentlichen Start.“
A15: Barrierefreiheitsprüfung | B15: 1500 | C15: Handbuch B, Einmalkosten: Monat 8, „Durch Betroffene.“
A16: Nettobedarf für den Mindestbetrag | B16: =B14+B15 -> 5500 | C16: Was vor dem öffentlichen Start geprüft sein muss. Das Finanzmodell setzt beides in Monat 8 — die Kampagne liegt davor.
A17: Kosten der Roadmapmonate 6 bis 10, Szenario realistisch | B17: 20677.28 | C17: finanzmodell.xlsx nach A-52, Blatt „Realistisch“, Zeile „Kosten gesamt“, M6–M10 (4.360 + 2.496 + 8.135 + 2.777 + 2.910 €), abgelesen am 21.09.2026. Enthält die beiden Prüfungen; die Code-Prüfung nach Nr. 73 liegt im Modell in Monat 1 und ist hier nicht enthalten (Nr. 88).
A18: Nettobedarf für den Wunschbetrag | B18: =B17 -> 20677.28 | C18: Die Kosten der fünf Monate, in denen Handbuch B das Crowdfunding ansetzt („Monat 6–10“).
A20: Ergebnis bei der gewählten Plattform
A21: Durchschnittliche Unterstützung (brutto) | B21: =Stufen!D13 -> 44.75 | C21: Gewichtet mit der Verteilung auf die Stufen (Blatt „Stufen“, ANNAHME).
A22: Abzüge je Euro — Kasse (Umsatzsteuer, Gebühren, direkte Kosten) | B22: =IF($B$11<>"ja","Gebühren fehlen",IF(OR(ROUND(Stufen!F13,4)<>1,NOT(ISNUMBER(Stufen!N13))),"Stufen prüfen",Stufen!N13)) -> 0.23752805 | C22: Was von jedem eingesammelten Euro sofort abgeht.
A23: Abzüge je Euro — wirtschaftlich (zusätzlich Umsatzverzicht bei PLUS) | B23: =IF($B$11<>"ja","Gebühren fehlen",IF(OR(ROUND(Stufen!F13,4)<>1,NOT(ISNUMBER(Stufen!O13))),"Stufen prüfen",Stufen!O13)) -> 0.46035289 | C23: Umsatzverzicht: PLUS-Erlös, der später fehlt, weil ihn die Unterstützung vorwegnimmt (Blatt „PLUS-Wert“).
A24: Break-even der Kampagne (brutto) | B24: =IF(ISNUMBER(B23),IF(B23>=1,"nie",ROUNDUP(B10/(1-B23),0)),"—") -> 556 | C24: Ab dieser Summe trägt die Kampagne sich selbst: Fixkosten, Gebühren, Steuer, Gegenleistungen und Umsatzverzicht sind gedeckt.
A25: Mindestbetrag — Kasse | B25: =IF(ISNUMBER(B22),ROUNDUP((B16+B10)/(1-B22)/100,0)*100,"—") -> 7700 | C25: Deckt die Prüfungen und die Fixkosten in bar, aufgerundet auf volle 100 €.
A26: Mindestbetrag — wirtschaftlich (Vorschlag für die Alles-oder-nichts-Schwelle) | B26: =IF(ISNUMBER(B23),ROUNDUP((B16+B10)/(1-B23)/100,0)*100,"—") -> 10800 | C26: Wie oben, zusätzlich mit dem Umsatzverzicht, weil er später als Erlös fehlt.
A27: Wunschbetrag — wirtschaftlich | B27: =IF(ISNUMBER(B23),ROUNDUP((B18+B10)/(1-B23)/100,0)*100,"—") -> 38900 | C27: Deckt die Kosten der Roadmapmonate 6 bis 10.
A28: Mindestbetrag im Verhältnis zur Spanne aus Handbuch B (10.000–60.000 €) | B28: =IF(ISNUMBER(B26),IF(B26<10000,"unter der Spanne",IF(B26>60000,"über der Spanne","in der Spanne")),"—") -> in der Spanne | C28: Handbuch B, Finanzierungswege: „Crowdfunding · 10–60 T€ · 0 % · Monat 6–10“.
A29: Wunschbetrag im Verhältnis zur Spanne | B29: =IF(ISNUMBER(B27),IF(B27<10000,"unter der Spanne",IF(B27>60000,"über der Spanne","in der Spanne")),"—") -> in der Spanne
A30: Unterstützer nötig für den Mindestbetrag | B30: =IF(AND(ISNUMBER(B26),B21>0),ROUNDUP(B26/B21,0),"—") -> 242
A31: Unterstützer nötig für den Wunschbetrag | B31: =IF(AND(ISNUMBER(B27),B21>0),ROUNDUP(B27/B21,0),"—") -> 870
A32: Besuche der Projektseite nötig für den Mindestbetrag | B32: =IF(AND(ISNUMBER(B26),B43>0),ROUNDUP(B26/B43,0),"—") -> 10800 | C32: Faustregel der Plattform: rund 1 € je Besuch (Zeile 43).
A33: Besuche der Projektseite nötig für den Wunschbetrag | B33: =IF(AND(ISNUMBER(B27),B43>0),ROUNDUP(B27/B43,0),"—") -> 38900
A34: Ziel für die ersten 72 Stunden — unterer Wert | B34: =IF(ISNUMBER(B26),ROUND(B26*B45,-2),"—") -> 2200 | C34: Startnext: „Idealerweise erreichst du 20-40% Prozent deines Mindest- oder Wunschbetrages innerhalb der ersten 72 Stunden.“
A35: Ziel für die ersten 72 Stunden — oberer Wert | B35: =IF(ISNUMBER(B26),ROUND(B26*B46,-2),"—") -> 4300
A36: Netto aus dem Mindestbetrag (Kasse, nach Fixkosten) | B36: =IF(AND(ISNUMBER(B26),ISNUMBER(B22)),B26*(1-B22)-B10,"—") -> 7934.6971 | C36: Das Bargeld, das nach Abzügen und Fixkosten übrig bleibt.
A37: Deckt der Mindestbetrag den Nettobedarf? | B37: =IF(ISNUMBER(B36),IF(B36>=B16,"ja","nein"),"—") -> ja
A38: Reichen die Limits der Stufen beim Wunschbetrag? | B38: =Stufen!Q13 -> ja | C38: Stückzahl je Stufe = nötige Unterstützer × Anteil der Stufe.
A39: Liegt die Durchschnittsunterstützung im typischen Warenkorb der Plattform? | B39: =IF(AND(B21>=B47,B21<=B48),"ja","nein") -> ja | C39: Startnext: „Der Warenkorb einer typischen Unterstützung auf Startnext liegt bei etwa 35-75€.“
A41: Faustregeln der Plattform (Startnext-Handbuch „Kommunikation“ und „Dankeschöns“, abgerufen 16.09.2026)
A42: Durchschnittliche Unterstützung laut Plattform | B42: 35 | C42: „Beitrag einer Unterstützer:in im Durchschnitt bei 35€ liegt“ — zum Vergleich mit Zeile 21.
A43: Euro je Besuch der Projektseite | B43: 1 | C43: „… jede:r Besucher:in deiner Projektseite im Durchschnitt für ca. 1€ Fundingsumme steht.“
A44: Unterstützer je 100 Besuche | B44: 3 | C44: „Von 100 Besucher:innen auf deiner Projektseite unterstützen im Durchschnitt ca. 3 tatsächlich dein Projekt.“
...

Sheet Stufen
A1: Gegenleistungsstufen — Preis, Abzüge, Beitrag je Stück
A2: Aufgabe A-21 · erstellt 16.09.2026, Stufen nach Nr. 60 neu gefasst am 21.09.2026 · Grundlage: Handbuch B (Kapitalfahrplan, Abopreise, Einmalkosten), finanzmodell.xlsx (Szenario realistisch), Plattformseiten abgerufen am 16.09.2026 · ENTWURF — die Tabelle rechnet, entscheiden tun die Gründer.
A3: LEGENDE: Gelb mit blauer Schrift = Eingabe (Voreinstellung mit Herkunft, änderbar). Alles andere rechnet. ANNAHME = kein Erfahrungswert, bewusst gesetzt.
A5: Nr | B5: Stufe | C5: Inhalt | D5: Preis brutto | E5: Limit (Stück, leer = ohne) | F5: Anteil der Unterstützer (ANNAHME) | G5: Umsatzsteuer fällig? | H5: Direkte Kosten je Stück | I5: Umsatzsteuer je Stück | J5: Gebühren je Stück | K5: Umsatzverzicht je Stück | L5: Beitrag Kasse je Stück | M5: Beitrag wirtschaftlich je Stück | N5: Abzüge Kasse (Anteil) | O5: Abzüge wirtschaftlich (Anteil) | P5: Stück beim Wunschbetrag | Q5: Limit reicht? | R5: Hinweis
A6: S1 | B6: Danke | C6: Name oder Pseudonym auf der Unterstützerliste in der App — nur wenn du das willst, jederzeit widerrufbar. Dazu die Kampagnen-Updates. | D6: 10 | F6: 0.2 | G6: ja | H6: 0 | I6: =IF(AND(Rechner!$B$9="ja",G6="ja"),D6*Rechner!$B$8/(1+Rechner!$B$8),0) -> 1.5966387 | J6: =D6*N(INDEX(Plattformen!$D$6:$D$11,MATCH(Rechner!$B$7,Plattformen!$A$6:$A$11,0)))*(1+IF(Rechner!$B$9="ja",0,Rechner!$B$8))+IF(D6<N(INDEX(Plattformen!$G$6:$G$11,MATCH(Rechner!$B$7,Plattformen!$A$6:$A$11,0))),D6*N(INDEX(Plattformen!$H$6:$H$11,MATCH(Rechner!$B$7,Plattformen!$A$6:$A$11,0)))+N(INDEX(Plattformen!$I$6:$I$11,MATCH(Rechner!$B$7,Plattformen!$A$6:$A$11,0))),D6*N(INDEX(Plattformen!$E$6:$E$11,MATCH(Rechner!$B$7,Plattformen!$A$6:$A$11,0)))+N(INDEX(Plattformen!$F$6:$F$11,MATCH(Rechner!$B$7,Plattformen!$A$6:$A$11,0)))) -> 0.85 | K6: 0 | L6: =D6-H6-I6-J6 -> 7.5533613 | M6: =L6-K6 -> 7.5533613 | N6: =IF(D6=0,"",(H6+I6+J6)/D6) -> 0.24466387 | O6: =IF(D6=0,"",(H6+I6+J6+K6)/D6) -> 0.24466387 | P6: =IF(ISNUMBER(Rechner!$B$31),ROUNDUP(Rechner!$B$31*F6,0),"") -> 174 | Q6: =IF(P6="","—",IF(E6="","ohne Limit",IF(P6<=E6,"ja","nein"))) -> ohne Limit | R6: Nach einer älteren Auskunft (Existenzgründungsportal, März 2016) ist die bloße Namensnennung keine Leistung — dann „nein“. Vorsichtig gerechnet: ja.
A7: S2 | B7: Gründungsunterstützer | C7: Wie S1, dazu das Abzeichen „Gründungsunterstützer“ im eigenen Konto; für andere sichtbar nur, wenn du es einschaltest. Kein Einfluss auf Sortierung oder Reichweite. | D7: 25 | F7: 0.25 | G7: ja | H7: 0 | I7: =IF(AND(Rechner!$B$9="ja",G7="ja"),D7*Rechner!$B$8/(1+Rechner!$B$8),0) -> 3.9915966 | J7: =D7*N(INDEX(Plattformen!$D$6:$D$11,MATCH(Rechner!$B$7,Plattformen!$A$6:$A$11,0)))*(1+IF(Rechner!$B$9="ja",0,Rechner!$B$8))+IF(D7<N(INDEX(Plattformen!$G$6:$G$11,MATCH(Rechner!$B$7,Plattformen!$A$6:$A$11,0))),D7*N(INDEX(Plattformen!$H$6:$H$11,MATCH(Rechner!$B$7,Plattformen!$A$6:$A$11,0)))+N(INDEX(Plattformen!$I$6:$I$11,MATCH(Rechner!$B$7,Plattformen!$A$6:$A$11,0))),D7*N(INDEX(Plattformen!$E$6:$E$11,MATCH(Rechner!$B$7,Plattformen!$A$6:$A$11,0)))+N(INDEX(Plattformen!$F$6:$F$11,MATCH(Rechner!$B$7,Plattformen!$A$6:$A$11,0)))) -> 2.125 | K7: 0 | L7: =D7-H7-I7-J7 -> 18.883403 | M7: =L7-K7 -> 18.883403 | N7: =IF(D7=0,"",(H7+I7+J7)/D7) -> 0.24466387 | O7: =IF(D7=0,"",(H7+I7+J7+K7)/D7) -> 0.24466387 | P7: =IF(ISNUMBER(Rechner!$B$31),ROUNDUP(Rechner!$B$31*F7,0),"") -> 218 | Q7: =IF(P7="","—",IF(E7="","ohne Limit",IF(P7<=E7,"ja","nein"))) -> ohne Limit | R7: Abzeichen und Liste kosten kein Geld, aber Entwicklungszeit — gehören in die Produktspezifikation (A-29).
A8: S3 | B8: Blick in die Werkstatt | C8: Wie S2, dazu eine Online-Führung durch die Entwicklung: 60 Minuten, Gruppe, Termin nach der Kampagne. | D8: 45 | E8: 100 | F8: 0.1 | G8: ja | H8: 0 | I8: =IF(AND(Rechner!$B$9="ja",G8="ja"),D8*Rechner!$B$8/(1+Rechner!$B$8),0) -> 7.1848739 | J8: =D8*N(INDEX(Plattformen!$D$6:$D$11,MATCH(Rechner!$B$7,Plattformen!$A$6:$A$11,0)))*(1+IF(Rechner!$B$9="ja",0,Rechner!$B$8))+IF(D8<N(INDEX(Plattformen!$G$6:$G$11,MATCH(Rechner!$B$7,Plattformen!$A$6:$A$11,0))),D8*N(INDEX(Plattformen!$H$6:$H$11,MATCH(Rechner!$B$7,Plattformen!$A$6:$A$11,0)))+N(INDEX(Plattformen!$I$6:$I$11,MATCH(Rechner!$B$7,Plattformen!$A$6:$A$11,0))),D8*N(INDEX(Plattformen!$E$6:$E$11,MATCH(Rechner!$B$7,Plattformen!$A$6:$A$11,0)))+N(INDEX(Plattformen!$F$6:$F$11,MATCH(Rechner!$B$7,Plattformen!$A$6:$A$11,0)))) -> 3.825 | K8: 0 | L8: =D8-H8-I8-J8 -> 33.990126 | M8: =L8-K8 -> 33.990126 | N8: =IF(D8=0,"",(H8+I8+J8)/D8) -> 0.24466387 | O8: =IF(D8=0,"",(H8+I8+J8+K8)/D8) -> 0.24466387 | P8: =IF(ISNUMBER(Rechner!$B$31),ROUNDUP(Rechner!$B$31*F8,0),"") -> 87 | Q8: =IF(P8="","—",IF(E8="","ohne Limit",IF(P8<=E8,"ja","nein"))) -> ja | R8: Kostet Gründerzeit, kein Bargeld: bei 20 Personen je Termin fünf Termine. Videodienst mit EU-Sitz (Handbuch A).
A9: S4 | B9: Ein Jahr PLUS | C9: Wie S2, dazu 12 Monate PLUS, gerechnet ab dem Tag, an dem PLUS startet; per Einlösecode im Web. | D9: 60 | F9: 0.2 | G9: ja | H9: 0 | I9: =IF(AND(Rechner!$B$9="ja",G9="ja"),D9*Rechner!$B$8/(1+Rechner!$B$8),0) -> 9.5798319 | J9: =D9*N(INDEX(Plattformen!$D$6:$D$11,MATCH(Rechner!$B$7,Plattformen!$A$6:$A$11,0)))*(1+IF(Rechner!$B$9="ja",0,Rechner!$B$8))+IF(D9<N(INDEX(Plattformen!$G$6:$G$11,MATCH(Rechner!$B$7,Plattformen!$A$6:$A$11,0))),D9*N(INDEX(Plattformen!$H$6:$H$11,MATCH(Rechner!$B$7,Plattformen!$A$6:$A$11,0)))+N(INDEX(Plattformen!$I$6:$I$11,MATCH(Rechner!$B$7,Plattformen!$A$6:$A$11,0))),D9*N(INDEX(Plattformen!$E$6:$E$11,MATCH(Rechner!$B$7,Plattformen!$A$6:$A$11,0)))+N(INDEX(Plattformen!$F$6:$F$11,MATCH(Rechner!$B$7,Plattformen!$A$6:$A$11,0)))) -> 5.1 | K9: ='PLUS-Wert'!B22 -> 26.970588 | L9: =D9-H9-I9-J9 -> 45.320168 | M9: =L9-K9 -> 18.34958 | N9: =IF(D9=0,"",(H9+I9+J9)/D9) -> 0.24466387 | O9: =IF(D9=0,"",(H9+I9+J9+K9)/D9) -> 0.69417367 | P9: =IF(ISNUMBER(Rechner!$B$31),ROUNDUP(Rechner!$B$31*F9,0),"") -> 174 | Q9: =IF(P9="","—",IF(E9="","ohne Limit",IF(P9<=E9,"ja","nein"))) -> ohne Limit | R9: Vorverkauf wie in finanzmodell.xlsx, Finanzierungswege („Vorverkauf von Jahresabos an die Warteliste“). Regulär 70 €. Bringt vor allem Liquidität nach vorn.
A10: S5 | B10: Ein Jahr PRO | C10: Wie S2, dazu 12 Monate PRO als Code (Codesystem, Art U), eingelöst auf der Webseite und gültig ab dem Tag, an dem die Abos starten. Befristet einlösbar; verfällt bei Auflösung oder Insolvenz (Nr. 60). | D10: 120 | F10: 0.15 | G10: ja | H10: 0 | I10: =IF(AND(Rechner!$B$9="ja",G10="ja"),D10*Rechner!$B$8/(1+Rechner!$B$8),0) -> 19.159664 | J10: =D10*N(INDEX(Plattformen!$D$6:$D$11,MATCH(Rechner!$B$7,Plattformen!$A$6:$A$11,0)))*(1+IF(Rechner!$B$9="ja",0,Rechner!$B$8))+IF(D10<N(INDEX(Plattformen!$G$6:$G$11,MATCH(Rechner!$B$7,Plattformen!$A$6:$A$11,0))),D10*N(INDEX(Plattformen!$H$6:$H$11,MATCH(Rechner!$B$7,Plattformen!$A$6:$A$11,0)))+N(INDEX(Plattformen!$I$6:$I$11,MATCH(Rechner!$B$7,Plattformen!$A$6:$A$11,0))),D10*N(INDEX(Plattformen!$E$6:$E$11,MATCH(Rechner!$B$7,Plattformen!$A$6:$A$11,0)))+N(INDEX(Plattformen!$F$6:$F$11,MATCH(Rechner!$B$7,Plattformen!$A$6:$A$11,0)))) -> 10.2 | K10: ='PLUS-Wert'!B28 -> 30.515294 | L10: =D10-H10-I10-J10 -> 90.640336 | M10: =L10-K10 -> 60.125042 | N10: =IF(D10=0,"",(H10+I10+J10)/D10) -> 0.24466387 | O10: =IF(D10=0,"",(H10+I10+J10+K10)/D10) -> 0.49895798 | P10: =IF(ISNUMBER(Rechner!$B$31),ROUNDUP(Rechner!$B$31*F10,0),"") -> 131 | Q10: =IF(P10="","—",IF(E10="","ohne Limit",IF(P10<=E10,"ja","nein"))) -> ohne Limit | R10: Seit Nr. 60 (21.09.2026) befristet statt „PLUS ohne Laufzeitende“: ersetzt die lebenslange Stufe aus Handbuch B. Preis knapp unter dem PRO-Jahresabo (132 €). Umsatzverzicht im Blatt „PLUS-Wert“, Abschnitt S5.
A11: S6 | B11: Einfach so | C11: Unterstützung ohne Gegenleistung, freier Betrag; nur die Kampagnen-Updates. | D11: 20 | F11: 0.1 | G11: nein | H11: 0 | I11: =IF(AND(Rechner!$B$9="ja",G11="ja"),D11*Rechner!$B$8/(1+Rechner!$B$8),0) -> 0 | J11: =D11*N(INDEX(Plattformen!$D$6:$D$11,MATCH(Rechner!$B$7,Plattformen!$A$6:$A$11,0)))*(1+IF(Rechner!$B$9="ja",0,Rechner!$B$8))+IF(D11<N(INDEX(Plattformen!$G$6:$G$11,MATCH(Rechner!$B$7,Plattformen!$A$6:$A$11,0))),D11*N(INDEX(Plattformen!$H$6:$H$11,MATCH(Rechner!$B$7,Plattformen!$A$6:$A$11,0)))+N(INDEX(Plattformen!$I$6:$I$11,MATCH(Rechner!$B$7,Plattformen!$A$6:$A$11,0))),D11*N(INDEX(Plattformen!$E$6:$E$11,MATCH(Rechner!$B$7,Plattformen!$A$6:$A$11,0)))+N(INDEX(Plattformen!$F$6:$F$11,MATCH(Rechner!$B$7,Plattformen!$A$6:$A$11,0)))) -> 1.7 | K11: 0 | L11: =D11-H11-I11-J11 -> 18.3 | M11: =L11-K11 -> 18.3 | N11: =IF(D11=0,"",(H11+I11+J11)/D11) -> 0.085 | O11: =IF(D11=0,"",(H11+I11+J11+K11)/D11) -> 0.085 | P11: =IF(ISNUMBER(Rechner!$B$31),ROUNDUP(Rechner!$B$31*F11,0),"") -> 87 | Q11: =IF(P11="","—",IF(E11="","ohne Limit",IF(P11<=E11,"ja","nein"))) -> ohne Limit | R11: Preis = angenommener Durchschnitt (ANNAHME). Ohne Gegenleistung meist keine Umsatzsteuer (Startnext-Blog, 2021) — bei einer GmbH aber Betriebseinnahme.
B13: Gewichtet | C13: Durchschnitt je Unterstützung, gewichtet mit den Anteilen | D13: =SUMPRODUCT(D6:D11,F6:F11) -> 44.75 | F13: =SUM(F6:F11) -> 1 | I13: =SUMPRODUCT(F6:F11,I6:I11) -> 6.8256303 | J13: =SUMPRODUCT(F6:F11,J6:J11) -> 3.80375 | K13: =SUMPRODUCT(F6:F11,K6:K11) -> 9.9714118 | L13: =SUMPRODUCT(F6:F11,L6:L11) -> 34.12062 | M13: =SUMPRODUCT(F6:F11,M6:M11) -> 24.149208 | N13: =IF(D13=0,"",SUMPRODUCT(F6:F11,H6:H11+I6:I11+J6:J11)/D13) -> 0.23752805 | O13: =IF(D13=0,"",SUMPRODUCT(F6:F11,H6:H11+I6:I11+J6:J11+K6:K11)/D13) -> 0.46035289 | Q13: =IF(COUNTIF(Q6:Q11,"—")>0,"—",IF(COUNTIF(Q6:Q11,"nein")=0,"ja","nein — Limit prüfen")) -> ja
B14: Prüfung | C14: =IF(ROUND(F13,4)=1,"Die Anteile ergeben 100 %.","Die Anteile ergeben nicht 100 % — bitte korrigieren.") -> Die Anteile ergeben 100 %.
A16: Die Stufen setzen die Gegenleistungen aus Handbuch B um — Unterstützerabzeichen, Nennung in der App, Führung durch die Entwicklung — und den Vorverkauf aus dem Finanzmodell. Das „lebenslange PLUS“ aus Handbuch B entfällt nach Nr. 60 (21.09.2026): Alle Codes sind befristet. Preise, Limits und Anteile sind Vorschläge.
A17: Bewusst nicht enthalten: Plätze in der Testphase (Vergabe über Einladungscodes, Nr. 56), Verlosungen (Handbuch B meidet Gewinnspiele; Startnext schließt „Glückspiel, Lose und Wetten“ aus), physische Waren (Versand, Umsatzsteuer, Aufwand), Schutzfunktionen und Sichtbarkeit (nie Gegenleistung, Codesystem).
A18: Alle Gegenleistungen nur für Volljährige nutzbar: Die App ist ab 18. Einlösecodes statt Abgleich von E-Mail-Adressen — so bleibt die Unterstützung vom App-Konto getrennt, bis jemand selbst einlöst.

Sheet PLUS-Wert
A1: PLUS-Wert — was die PLUS-Stufen an späterem Erlös kosten
A2: Aufgabe A-21 · erstellt 16.09.2026, fortgeschrieben 21.09.2026 · Grundlage: Handbuch B (Kapitalfahrplan, Abopreise, Einmalkosten), finanzmodell.xlsx (Szenario realistisch), Plattformseiten abgerufen am 16.09.2026 · ENTWURF — die Tabelle rechnet, entscheiden tun die Gründer.
A3: LEGENDE: Gelb mit blauer Schrift = Eingabe (Voreinstellung mit Herkunft, änderbar). Alles andere rechnet. ANNAHME = kein Erfahrungswert, bewusst gesetzt.
A5: Laufzeit | B5: Monate | C5: PLUS gesamt (brutto) | D5: je Monat | E5: Anteil (Handbuch B) | F5: Ø Verweildauer (Monate) | G5: Erlös je Kunde netto (Handbuch B)
A6: 1 Monat | B6: 1 | C6: 9 | D6: =C6/B6 -> 9 | E6: 0.45 | F6: 3.3 | G6: 24.9
A7: 3 Monate | B7: 3 | C7: 23 | D7: =C7/B7 -> 7.6666667 | E7: 0.2 | F7: 10 | G7: 64.3
A8: 6 Monate | B8: 6 | C8: 40 | D8: =C8/B8 -> 6.6666667 | E8: 0.15 | F8: 16.7 | G8: 93.4
A9: 12 Monate | B9: 12 | C9: 70 | D9: =C9/B9 -> 5.8333333 | E9: 0.2 | F9: 25 | G9: 122.3
A10: gemischt | D10: =SUMPRODUCT(D6:D9,E6:E9) -> 7.75 | E10: =SUM(E6:E9) -> 1 | F10: 5.8 | G10: 42.8
A11: Quelle: Handbuch B, Abschnitt „Abonnements“ (Preisliste brutto; Abwanderung nach Laufzeit). Die gemischte Zeile gewichtet wie Handbuch B mit den Anteilen.
A13: Kette je Monat
A14: Umsatzsteuersatz | B14: =Rechner!B8 -> 0.19
A15: Provisionen gemischt (Stores und Web) — seit A-52: 60 % Web zu 1,80 % + 0,25 € je Zahlung, 40 % Stores zu 15 %; im Mittel 8,3 % (finanzmodell.xlsx, Abschnitt 2a). Handbuch B: 10,6 % | B15: 0.083
A16: Nettoerlös je PLUS-Monat im Jahresabo (ohne Umsatzsteuer, nach Provision) | B16: =D9/(1+B14)*(1-B15) -> 4.495098
A17: Nettoerlös je PLUS-Monat, gemischte Laufzeiten | B17: =D10/(1+B14)*(1-B15) -> 5.9720588
A19: Stufe S4 „Ein Jahr PLUS“
A20: Anteil, der das Jahresabo ohnehin gekauft hätte (ANNAHME) | B20: 0.5 | C20: Ohne Erfahrungswert. Bei 100 % holt die Stufe nur Erlös nach vorn, bei 0 % ist sie ganz zusätzlich.
A21: Monate | B21: =B9 -> 12
A22: Umsatzverzicht je Stück, erwartet | B22: =B20*B21*B16 -> 26.970588
A24: Stufe S5 „Ein Jahr PRO“ (seit Nr. 60 befristet)
A25: Anteil, der das PRO-Jahresabo ohnehin gekauft hätte (ANNAHME) | B25: 0.3 | C25: ANNAHME ohne Erfahrungswert: so hoch wie der Anteil PRO an allen Zahlern im Finanzmodell (30 %). Die teurere Stufe wählt man seltener ohnehin; bei 100 % holt die Stufe nur Erlös nach vorn, bei 0 % ist sie ganz zusätzlich.
A26: Monate | B26: 12 | C26: Laufzeit des Codes
A27: Nettoerlös je PRO-Monat im Jahresabo (132 € im Jahr, ohne Umsatzsteuer, nach Provision) | B27: =132/12/(1+B14)*(1-B15) -> 8.4764706 | C27: Handbuch B: PRO 132 € für 12 Monate
A28: Umsatzverzicht je Stück, erwartet | B28: =B25*B26*B27 -> 30.515294
A29: Erster Monat mit zahlenden Nutzern im Finanzmodell (Szenario realistisch) | B29: 14 | C29: finanzmodell.xlsx, Blatt „Annahmen“, „Monetarisierungsstart“ (pessimistisch 18, optimistisch 11). Vorher gibt es kein PLUS zu kaufen.
A30: Umsatzverzicht je Stück, ungünstigster Fall (jeder hätte das Jahresabo ohnehin gekauft) | B30: =B26*B27 -> 101.71765 | C30: Seit Nr. 60 begrenzt auf zwölf Monate — vorher bis zum Ende des Planungshorizonts
A31: Stück beim Wunschbetrag (Blatt „Stufen“) | B31: =IF(ISNUMBER(Stufen!P10),Stufen!P10,0) -> 131
A32: Umsatzverzicht bei dieser Stückzahl, erwartet | B32: =B31*B28 -> 3997.5035
A33: Umsatzverzicht bei dieser Stückzahl, ungünstigster Fall | B33: =B31*B30 -> 13325.012
A34: Aboerlöse des Finanzmodells über 36 Monate, Szenario realistisch | B34: 157053 | C34: finanzmodell.xlsx, Blatt „Realistisch“, Zeile „Abonnements“, Summe M1–M36, abgelesen am 21.09.2026 nach A-52
A35: Ungünstigster Fall im Verhältnis zu diesen Aboerlösen | B35: =IF(B34>0,B33/B34,"") -> 0.084844045
A37: Kontrollrechnung gegen Handbuch B
A38: Handbuch B: Erlös je Kunde im Jahresabo, nach Provision | B38: =G9*(1-B15) -> 112.1491
A39: Dieselbe Größe aus dieser Tabelle (Verweildauer × Nettoerlös je Monat) | B39: =F9*B16 -> 112.37745
A40: Abweichung | B40: =B39/B38-1 -> 0.0020361374 | C40: Rundungsdifferenz in Handbuch B; unter 1 % ist unerheblich.
A42: Betriebskosten je Konto entstehen unabhängig vom Abo und sind hier nicht gerechnet. Der Umsatzverzicht ist kein Bargeld — er fehlt später als Erlös.
A43: Die Abostufen sind erst nutzbar, wenn die Abos starten — im Finanzmodell Monat 11, 14 oder 18. Liegt die Kampagne in Monat 7, liegen dazwischen vier bis elf Monate. Codes sind befristet einlösbar (Nr. 60).

Sheet Plattformvergleich
A1: Plattformvergleich — dieselben Stufen, alle Plattformen
A2: Aufgabe A-21 · erstellt 16.09.2026, fortgeschrieben 21.09.2026 · Grundlage: Handbuch B (Kapitalfahrplan, Abopreise, Einmalkosten), finanzmodell.xlsx (Szenario realistisch), Plattformseiten abgerufen am 16.09.2026 · ENTWURF — die Tabelle rechnet, entscheiden tun die Gründer.
A3: LEGENDE: Gelb mit blauer Schrift = Eingabe (Voreinstellung mit Herkunft, änderbar). Alles andere rechnet. ANNAHME = kein Erfahrungswert, bewusst gesetzt.
B5: S1 | C5: S2 | D5: S3 | E5: S4 | F5: S5 | G5: S6
A6: Preis brutto | B6: =Stufen!D6 -> 10 | C6: =Stufen!D7 -> 25 | D6: =Stufen!D8 -> 45 | E6: =Stufen!D9 -> 60 | F6: =Stufen!D10 -> 120 | G6: =Stufen!D11 -> 20
A7: Anteil | B7: =Stufen!F6 -> 0.2 | C7: =Stufen!F7 -> 0.25 | D7: =Stufen!F8 -> 0.1 | E7: =Stufen!F9 -> 0.2 | F7: =Stufen!F10 -> 0.15 | G7: =Stufen!F11 -> 0.1
A8: Umsatzsteuer je Stück | B8: =Stufen!I6 -> 1.5966387 | C8: =Stufen!I7 -> 3.9915966 | D8: =Stufen!I8 -> 7.1848739 | E8: =Stufen!I9 -> 9.5798319 | F8: =Stufen!I10 -> 19.159664 | G8: =Stufen!I11 -> 0
A9: Direkte Kosten je Stück | B9: =Stufen!H6 -> 0 | C9: =Stufen!H7 -> 0 | D9: =Stufen!H8 -> 0 | E9: =Stufen!H9 -> 0 | F9: =Stufen!H10 -> 0 | G9: =Stufen!H11 -> 0
A10: Umsatzverzicht je Stück | B10: =Stufen!K6 -> 0 | C10: =Stufen!K7 -> 0 | D10: =Stufen!K8 -> 0 | E10: =Stufen!K9 -> 26.970588 | F10: =Stufen!K10 -> 30.515294 | G10: =Stufen!K11 -> 0
A12: Plattform | B12: Gebühr S1 | C12: Gebühr S2 | D12: Gebühr S3 | E12: Gebühr S4 | F12: Gebühr S5 | G12: Gebühr S6 | H12: Gebühren je Ø-Unterstützung | I12: Abzüge Kasse | J12: Abzüge wirtschaftlich | K12: Mindestbetrag wirtschaftlich | L12: Wunschbetrag wirtschaftlich | M12: Netto (Kasse) aus 10.000 € brutto | N12: Hinweis
A13: =Plattformen!A6 -> Startnext Basis | B13: =IF(Plattformen!$D$6="","",B$6*Plattformen!$D$6*(1+IF(Rechner!$B$9="ja",0,Rechner!$B$8))+IF(B$6<N(Plattformen!$G$6),B$6*Plattformen!$H$6+Plattformen!$I$6,B$6*Plattformen!$E$6+Plattformen!$F$6)) -> 0.85 | C13: =IF(Plattformen!$D$6="","",C$6*Plattformen!$D$6*(1+IF(Rechner!$B$9="ja",0,Rechner!$B$8))+IF(C$6<N(Plattformen!$G$6),C$6*Plattformen!$H$6+Plattformen!$I$6,C$6*Plattformen!$E$6+Plattformen!$F$6)) -> 2.125 | D13: =IF(Plattformen!$D$6="","",D$6*Plattformen!$D$6*(1+IF(Rechner!$B$9="ja",0,Rechner!$B$8))+IF(D$6<N(Plattformen!$G$6),D$6*Plattformen!$H$6+Plattformen!$I$6,D$6*Plattformen!$E$6+Plattformen!$F$6)) -> 3.825 | E13: =IF(Plattformen!$D$6="","",E$6*Plattformen!$D$6*(1+IF(Rechner!$B$9="ja",0,Rechner!$B$8))+IF(E$6<N(Plattformen!$G$6),E$6*Plattformen!$H$6+Plattformen!$I$6,E$6*Plattformen!$E$6+Plattformen!$F$6)) -> 5.1 | F13: =IF(Plattformen!$D$6="","",F$6*Plattformen!$D$6*(1+IF(Rechner!$B$9="ja",0,Rechner!$B$8))+IF(F$6<N(Plattformen!$G$6),F$6*Plattformen!$H$6+Plattformen!$I$6,F$6*Plattformen!$E$6+Plattformen!$F$6)) -> 10.2 | G13: =IF(Plattformen!$D$6="","",G$6*Plattformen!$D$6*(1+IF(Rechner!$B$9="ja",0,Rechner!$B$8))+IF(G$6<N(Plattformen!$G$6),G$6*Plattformen!$H$6+Plattformen!$I$6,G$6*Plattformen!$E$6+Plattformen!$F$6)) -> 1.7 | H13: =IF(B13="","",SUMPRODUCT($B$7:$G$7,B13:G13)) -> 3.80375 | I13: =IF(OR(H13="",Stufen!$D$13=0),"",(SUMPRODUCT($B$7:$G$7,$B$8:$G$8)+SUMPRODUCT($B$7:$G$7,$B$9:$G$9)+H13)/Stufen!$D$13) -> 0.23752805 | J13: =IF(I13="","",I13+SUMPRODUCT($B$7:$G$7,$B$10:$G$10)/Stufen!$D$13) -> 0.46035289 | K13: =IF(ROUND(Stufen!$F$13,4)<>1,"Stufen prüfen",IF(J13="","keine Angabe",ROUNDUP((Rechner!$B$16+Rechner!$B$10)/(1-J13)/100,0)*100)) -> 10800 | L13: =IF(ROUND(Stufen!$F$13,4)<>1,"Stufen prüfen",IF(J13="","keine Angabe",ROUNDUP((Rechner!$B$18+Rechner!$B$10)/(1-J13)/100,0)*100)) -> 38900 | M13: =IF(ROUND(Stufen!$F$13,4)<>1,"Stufen prüfen",IF(I13="","keine Angabe",10000*(1-I13))) -> 7624.7195
A14: =Plattformen!A7 -> Startnext Basis — nur PayPal (vorsichtig) | B14: =IF(Plattformen!$D$7="","",B$6*Plattformen!$D$7*(1+IF(Rechner!$B$9="ja",0,Rechner!$B$8))+IF(B$6<N(Plattformen!$G$7),B$6*Plattformen!$H$7+Plattformen!$I$7,B$6*Plattformen!$E$7+Plattformen!$F$7)) -> 1.3 | C14: =IF(Plattformen!$D$7="","",C$6*Plattformen!$D$7*(1+IF(Rechner!$B$9="ja",0,Rechner!$B$8))+IF(C$6<N(Plattformen!$G$7),C$6*Plattformen!$H$7+Plattformen!$I$7,C$6*Plattformen!$E$7+Plattformen!$F$7)) -> 2.575 | D14: =IF(Plattformen!$D$7="","",D$6*Plattformen!$D$7*(1+IF(Rechner!$B$9="ja",0,Rechner!$B$8))+IF(D$6<N(Plattformen!$G$7),D$6*Plattformen!$H$7+Plattformen!$I$7,D$6*Plattformen!$E$7+Plattformen!$F$7)) -> 4.275 | E14: =IF(Plattformen!$D$7="","",E$6*Plattformen!$D$7*(1+IF(Rechner!$B$9="ja",0,Rechner!$B$8))+IF(E$6<N(Plattformen!$G$7),E$6*Plattformen!$H$7+Plattformen!$I$7,E$6*Plattformen!$E$7+Plattformen!$F$7)) -> 5.55 | F14: =IF(Plattformen!$D$7="","",F$6*Plattformen!$D$7*(1+IF(Rechner!$B$9="ja",0,Rechner!$B$8))+IF(F$6<N(Plattformen!$G$7),F$6*Plattformen!$H$7+Plattformen!$I$7,F$6*Plattformen!$E$7+Plattformen!$F$7)) -> 10.65 | G14: =IF(Plattformen!$D$7="","",G$6*Plattformen!$D$7*(1+IF(Rechner!$B$9="ja",0,Rechner!$B$8))+IF(G$6<N(Plattformen!$G$7),G$6*Plattformen!$H$7+Plattformen!$I$7,G$6*Plattformen!$E$7+Plattformen!$F$7)) -> 2.15 | H14: =IF(B14="","",SUMPRODUCT($B$7:$G$7,B14:G14)) -> 4.25375 | I14: =IF(OR(H14="",Stufen!$D$13=0),"",(SUMPRODUCT($B$7:$G$7,$B$8:$G$8)+SUMPRODUCT($B$7:$G$7,$B$9:$G$9)+H14)/Stufen!$D$13) -> 0.24758392 | J14: =IF(I14="","",I14+SUMPRODUCT($B$7:$G$7,$B$10:$G$10)/Stufen!$D$13) -> 0.47040876 | K14: =IF(ROUND(Stufen!$F$13,4)<>1,"Stufen prüfen",IF(J14="","keine Angabe",ROUNDUP((Rechner!$B$16+Rechner!$B$10)/(1-J14)/100,0)*100)) -> 11000 | L14: =IF(ROUND(Stufen!$F$13,4)<>1,"Stufen prüfen",IF(J14="","keine Angabe",ROUNDUP((Rechner!$B$18+Rechner!$B$10)/(1-J14)/100,0)*100)) -> 39700 | M14: =IF(ROUND(Stufen!$F$13,4)<>1,"Stufen prüfen",IF(I14="","keine Angabe",10000*(1-I14))) -> 7524.1608 | N14: rechnet jeden Zahlweg wie PayPal
A15: =Plattformen!A8 -> Startnext Pro | B15: =IF(Plattformen!$D$8="","",B$6*Plattformen!$D$8*(1+IF(Rechner!$B$9="ja",0,Rechner!$B$8))+IF(B$6<N(Plattformen!$G$8),B$6*Plattformen!$H$8+Plattformen!$I$8,B$6*Plattformen!$E$8+Plattformen!$F$8)) -> 1.45 | C15: =IF(Plattformen!$D$8="","",C$6*Plattformen!$D$8*(1+IF(Rechner!$B$9="ja",0,Rechner!$B$8))+IF(C$6<N(Plattformen!$G$8),C$6*Plattformen!$H$8+Plattformen!$I$8,C$6*Plattformen!$E$8+Plattformen!$F$8)) -> 3.625 | D15: =IF(Plattformen!$D$8="","",D$6*Plattformen!$D$8*(1+IF(Rechner!$B$9="ja",0,Rechner!$B$8))+IF(D$6<N(Plattformen!$G$8),D$6*Plattformen!$H$8+Plattformen!$I$8,D$6*Plattformen!$E$8+Plattformen!$F$8)) -> 6.525 | E15: =IF(Plattformen!$D$8="","",E$6*Plattformen!$D$8*(1+IF(Rechner!$B$9="ja",0,Rechner!$B$8))+IF(E$6<N(Plattformen!$G$8),E$6*Plattformen!$H$8+Plattformen!$I$8,E$6*Plattformen!$E$8+Plattformen!$F$8)) -> 8.7 | F15: =IF(Plattformen!$D$8="","",F$6*Plattformen!$D$8*(1+IF(Rechner!$B$9="ja",0,Rechner!$B$8))+IF(F$6<N(Plattformen!$G$8),F$6*Plattformen!$H$8+Plattformen!$I$8,F$6*Plattformen!$E$8+Plattformen!$F$8)) -> 17.4 | G15: =IF(Plattformen!$D$8="","",G$6*Plattformen!$D$8*(1+IF(Rechner!$B$9="ja",0,Rechner!$B$8))+IF(G$6<N(Plattformen!$G$8),G$6*Plattformen!$H$8+Plattformen!$I$8,G$6*Plattformen!$E$8+Plattformen!$F$8)) -> 2.9 | H15: =IF(B15="","",SUMPRODUCT($B$7:$G$7,B15:G15)) -> 6.48875 | I15: =IF(OR(H15="",Stufen!$D$13=0),"",(SUMPRODUCT($B$7:$G$7,$B$8:$G$8)+SUMPRODUCT($B$7:$G$7,$B$9:$G$9)+H15)/Stufen!$D$13) -> 0.29752805 | J15: =IF(I15="","",I15+SUMPRODUCT($B$7:$G$7,$B$10:$G$10)/Stufen!$D$13) -> 0.52035289 | K15: =IF(ROUND(Stufen!$F$13,4)<>1,"Stufen prüfen",IF(J15="","keine Angabe",ROUNDUP((Rechner!$B$16+Rechner!$B$10)/(1-J15)/100,0)*100)) -> 12100 | L15: =IF(ROUND(Stufen!$F$13,4)<>1,"Stufen prüfen",IF(J15="","keine Angabe",ROUNDUP((Rechner!$B$18+Rechner!$B$10)/(1-J15)/100,0)*100)) -> 43800 | M15: =IF(ROUND(Stufen!$F$13,4)<>1,"Stufen prüfen",IF(I15="","keine Angabe",10000*(1-I15))) -> 7024.7195 | N15: Leistungsumfang des Plans erfragen
A16: =Plattformen!A9 -> Ulule | B16: =IF(Plattformen!$D$9="","",B$6*Plattformen!$D$9*(1+IF(Rechner!$B$9="ja",0,Rechner!$B$8))+IF(B$6<N(Plattformen!$G$9),B$6*Plattformen!$H$9+Plattformen!$I$9,B$6*Plattformen!$E$9+Plattformen!$F$9)) -> 0.667 | C16: =IF(Plattformen!$D$9="","",C$6*Plattformen!$D$9*(1+IF(Rechner!$B$9="ja",0,Rechner!$B$8))+IF(C$6<N(Plattformen!$G$9),C$6*Plattformen!$H$9+Plattformen!$I$9,C$6*Plattformen!$E$9+Plattformen!$F$9)) -> 1.6675 | D16: =IF(Plattformen!$D$9="","",D$6*Plattformen!$D$9*(1+IF(Rechner!$B$9="ja",0,Rechner!$B$8))+IF(D$6<N(Plattformen!$G$9),D$6*Plattformen!$H$9+Plattformen!$I$9,D$6*Plattformen!$E$9+Plattformen!$F$9)) -> 3.0015 | E16: =IF(Plattformen!$D$9="","",E$6*Plattformen!$D$9*(1+IF(Rechner!$B$9="ja",0,Rechner!$B$8))+IF(E$6<N(Plattformen!$G$9),E$6*Plattformen!$H$9+Plattformen!$I$9,E$6*Plattformen!$E$9+Plattformen!$F$9)) -> 4.002 | F16: =IF(Plattformen!$D$9="","",F$6*Plattformen!$D$9*(1+IF(Rechner!$B$9="ja",0,Rechner!$B$8))+IF(F$6<N(Plattformen!$G$9),F$6*Plattformen!$H$9+Plattformen!$I$9,F$6*Plattformen!$E$9+Plattformen!$F$9)) -> 8.004 | G16: =IF(Plattformen!$D$9="","",G$6*Plattformen!$D$9*(1+IF(Rechner!$B$9="ja",0,Rechner!$B$8))+IF(G$6<N(Plattformen!$G$9),G$6*Plattformen!$H$9+Plattformen!$I$9,G$6*Plattformen!$E$9+Plattformen!$F$9)) -> 1.334 | H16: =IF(B16="","",SUMPRODUCT($B$7:$G$7,B16:G16)) -> 2.984825 | I16: =IF(OR(H16="",Stufen!$D$13=0),"",(SUMPRODUCT($B$7:$G$7,$B$8:$G$8)+SUMPRODUCT($B$7:$G$7,$B$9:$G$9)+H16)/Stufen!$D$13) -> 0.21922805 | J16: =IF(I16="","",I16+SUMPRODUCT($B$7:$G$7,$B$10:$G$10)/Stufen!$D$13) -> 0.44205289 | K16: =IF(ROUND(Stufen!$F$13,4)<>1,"Stufen prüfen",IF(J16="","keine Angabe",ROUNDUP((Rechner!$B$16+Rechner!$B$10)/(1-J16)/100,0)*100)) -> 10400 | L16: =IF(ROUND(Stufen!$F$13,4)<>1,"Stufen prüfen",IF(J16="","keine Angabe",ROUNDUP((Rechner!$B$18+Rechner!$B$10)/(1-J16)/100,0)*100)) -> 37600 | M16: =IF(ROUND(Stufen!$F$13,4)<>1,"Stufen prüfen",IF(I16="","keine Angabe",10000*(1-I16))) -> 7807.7195 | N16: Unterstützer zahlen zusätzlich eine Servicegebühr
A17: =Plattformen!A10 -> Kickstarter | B17: =IF(Plattformen!$D$10="","",B$6*Plattformen!$D$10*(1+IF(Rechner!$B$9="ja",0,Rechner!$B$8))+IF(B$6<N(Plattformen!$G$10),B$6*Plattformen!$H$10+Plattformen!$I$10,B$6*Plattformen!$E$10+Plattformen!$F$10)) -> 1.1 | C17: =IF(Plattformen!$D$10="","",C$6*Plattformen!$D$10*(1+IF(Rechner!$B$9="ja",0,Rechner!$B$8))+IF(C$6<N(Plattformen!$G$10),C$6*Plattformen!$H$10+Plattformen!$I$10,C$6*Plattformen!$E$10+Plattformen!$F$10)) -> 2.3 | D17: =IF(Plattformen!$D$10="","",D$6*Plattformen!$D$10*(1+IF(Rechner!$B$9="ja",0,Rechner!$B$8))+IF(D$6<N(Plattformen!$G$10),D$6*Plattformen!$H$10+Plattformen!$I$10,D$6*Plattformen!$E$10+Plattformen!$F$10)) -> 3.9 | E17: =IF(Plattformen!$D$10="","",E$6*Plattformen!$D$10*(1+IF(Rechner!$B$9="ja",0,Rechner!$B$8))+IF(E$6<N(Plattformen!$G$10),E$6*Plattformen!$H$10+Plattformen!$I$10,E$6*Plattformen!$E$10+Plattformen!$F$10)) -> 5.1 | F17: =IF(Plattformen!$D$10="","",F$6*Plattformen!$D$10*(1+IF(Rechner!$B$9="ja",0,Rechner!$B$8))+IF(F$6<N(Plattformen!$G$10),F$6*Plattformen!$H$10+Plattformen!$I$10,F$6*Plattformen!$E$10+Plattformen!$F$10)) -> 9.9 | G17: =IF(Plattformen!$D$10="","",G$6*Plattformen!$D$10*(1+IF(Rechner!$B$9="ja",0,Rechner!$B$8))+IF(G$6<N(Plattformen!$G$10),G$6*Plattformen!$H$10+Plattformen!$I$10,G$6*Plattformen!$E$10+Plattformen!$F$10)) -> 1.9 | H17: =IF(B17="","",SUMPRODUCT($B$7:$G$7,B17:G17)) -> 3.88 | I17: =IF(OR(H17="",Stufen!$D$13=0),"",(SUMPRODUCT($B$7:$G$7,$B$8:$G$8)+SUMPRODUCT($B$7:$G$7,$B$9:$G$9)+H17)/Stufen!$D$13) -> 0.23923196 | J17: =IF(I17="","",I17+SUMPRODUCT($B$7:$G$7,$B$10:$G$10)/Stufen!$D$13) -> 0.4620568 | K17: =IF(ROUND(Stufen!$F$13,4)<>1,"Stufen prüfen",IF(J17="","keine Angabe",ROUNDUP((Rechner!$B$16+Rechner!$B$10)/(1-J17)/100,0)*100)) -> 10800 | L17: =IF(ROUND(Stufen!$F$13,4)<>1,"Stufen prüfen",IF(J17="","keine Angabe",ROUNDUP((Rechner!$B$18+Rechner!$B$10)/(1-J17)/100,0)*100)) -> 39000 | M17: =IF(ROUND(Stufen!$F$13,4)<>1,"Stufen prüfen",IF(I17="","keine Angabe",10000*(1-I17))) -> 7607.6804 | N17: US-Unternehmen (Nr. 58)
A18: =Plattformen!A11 -> wemakeit | B18: =IF(Plattformen!$D$11="","",B$6*Plattformen!$D$11*(1+IF(Rechner!$B$9="ja",0,Rechner!$B$8))+IF(B$6<N(Plattformen!$G$11),B$6*Plattformen!$H$11+Plattformen!$I$11,B$6*Plattformen!$E$11+Plattformen!$F$11)) | C18: =IF(Plattformen!$D$11="","",C$6*Plattformen!$D$11*(1+IF(Rechner!$B$9="ja",0,Rechner!$B$8))+IF(C$6<N(Plattformen!$G$11),C$6*Plattformen!$H$11+Plattformen!$I$11,C$6*Plattformen!$E$11+Plattformen!$F$11)) | D18: =IF(Plattformen!$D$11="","",D$6*Plattformen!$D$11*(1+IF(Rechner!$B$9="ja",0,Rechner!$B$8))+IF(D$6<N(Plattformen!$G$11),D$6*Plattformen!$H$11+Plattformen!$I$11,D$6*Plattformen!$E$11+Plattformen!$F$11)) | E18: =IF(Plattformen!$D$11="","",E$6*Plattformen!$D$11*(1+IF(Rechner!$B$9="ja",0,Rechner!$B$8))+IF(E$6<N(Plattformen!$G$11),E$6*Plattformen!$H$11+Plattformen!$I$11,E$6*Plattformen!$E$11+Plattformen!$F$11)) | F18: =IF(Plattformen!$D$11="","",F$6*Plattformen!$D$11*(1+IF(Rechner!$B$9="ja",0,Rechner!$B$8))+IF(F$6<N(Plattformen!$G$11),F$6*Plattformen!$H$11+Plattformen!$I$11,F$6*Plattformen!$E$11+Plattformen!$F$11)) | G18: =IF(Plattformen!$D$11="","",G$6*Plattformen!$D$11*(1+IF(Rechner!$B$9="ja",0,Rechner!$B$8))+IF(G$6<N(Plattformen!$G$11),G$6*Plattformen!$H$11+Plattformen!$I$11,G$6*Plattformen!$E$11+Plattformen!$F$11)) | H18: =IF(B18="","",SUMPRODUCT($B$7:$G$7,B18:G18)) | I18: =IF(OR(H18="",Stufen!$D$13=0),"",(SUMPRODUCT($B$7:$G$7,$B$8:$G$8)+SUMPRODUCT($B$7:$G$7,$B$9:$G$9)+H18)/Stufen!$D$13) | J18: =IF(I18="","",I18+SUMPRODUCT($B$7:$G$7,$B$10:$G$10)/Stufen!$D$13) | K18: =IF(ROUND(Stufen!$F$13,4)<>1,"Stufen prüfen",IF(J18="","keine Angabe",ROUNDUP((Rechner!$B$16+Rechner!$B$10)/(1-J18)/100,0)*100)) -> keine Angabe | L18: =IF(ROUND(Stufen!$F$13,4)<>1,"Stufen prüfen",IF(J18="","keine Angabe",ROUNDUP((Rechner!$B$18+Rechner!$B$10)/(1-J18)/100,0)*100)) -> keine Angabe | M18: =IF(ROUND(Stufen!$F$13,4)<>1,"Stufen prüfen",IF(I18="","keine Angabe",10000*(1-I18))) -> keine Angabe | N18: Gebühren nicht belegt
A20: Niedrigster Mindestbetrag unter den belegten Plattformen | B20: =IF(COUNT(K13:K18)=0,"—",INDEX(A13:A18,MATCH(MIN(K13:K18),K13:K18,0))) -> Ulule
A21: Gegenprobe mit dem Blatt „Rechner“ | B21: =IF(Rechner!$B$11<>"ja","gewählte Plattform ohne belegte Gebühren",IF(NOT(ISNUMBER(Rechner!$B$26)),"—",IF(INDEX(K13:K18,MATCH(Rechner!$B$7,A13:A18,0))=Rechner!$B$26,"stimmt überein","Abweichung — prüfen"))) -> stimmt überein
A23: Der niedrigste Betrag ist kein Urteil über die Plattform: Zulässigkeit, Sitz, Sichtbarkeit der Unterstützer und Reichweite zählen mehr als ein Prozentpunkt (Konzept, Abschnitt 3).

Sheet Warteliste
A1: Warteliste — welcher Anteil müsste unterstützen?
A2: Aufgabe A-21 · erstellt 16.09.2026, fortgeschrieben 21.09.2026 · Grundlage: Handbuch B (Kapitalfahrplan, Abopreise, Einmalkosten), finanzmodell.xlsx (Szenario realistisch), Plattformseiten abgerufen am 16.09.2026 · ENTWURF — die Tabelle rechnet, entscheiden tun die Gründer.
A3: LEGENDE: Gelb mit blauer Schrift = Eingabe (Voreinstellung mit Herkunft, änderbar). Alles andere rechnet. ANNAHME = kein Erfahrungswert, bewusst gesetzt.
A5: Größe der Warteliste | B5: Herkunft | C5: Anteil für den Mindestbetrag | D5: Anteil für den Wunschbetrag | E5: Unterstützer bei 3 von 100 | F5: Summe daraus (brutto) | G5: Anteil am Mindestbetrag
A6: 1000 | B6: Handbuch B: Kampagne erst, „sobald die Warteliste über 1.000 Personen hat“ | C6: =IF(ISNUMBER(Rechner!$B$30),Rechner!$B$30/A6,"—") -> 0.242 | D6: =IF(ISNUMBER(Rechner!$B$31),Rechner!$B$31/A6,"—") -> 0.87 | E6: =ROUND(A6*Rechner!$B$44/100,0) -> 30 | F6: =E6*Rechner!$B$21 -> 1342.5 | G6: =IF(ISNUMBER(Rechner!$B$26),F6/Rechner!$B$26,"—") -> 0.12430556
A7: 1247 | B7: Tor-1-Analyse (A-23), Erwartung am Messtag, pessimistisch | C7: =IF(ISNUMBER(Rechner!$B$30),Rechner!$B$30/A7,"—") -> 0.19406576 | D7: =IF(ISNUMBER(Rechner!$B$31),Rechner!$B$31/A7,"—") -> 0.69767442 | E7: =ROUND(A7*Rechner!$B$44/100,0) -> 37 | F7: =E7*Rechner!$B$21 -> 1655.75 | G7: =IF(ISNUMBER(Rechner!$B$26),F7/Rechner!$B$26,"—") -> 0.15331019
A8: 1500 | B8: Tor 1, Handbuch A: „Weiter nur bei über 1.500 Anmeldungen“ | C8: =IF(ISNUMBER(Rechner!$B$30),Rechner!$B$30/A8,"—") -> 0.16133333 | D8: =IF(ISNUMBER(Rechner!$B$31),Rechner!$B$31/A8,"—") -> 0.58 | E8: =ROUND(A8*Rechner!$B$44/100,0) -> 45 | F8: =E8*Rechner!$B$21 -> 2013.75 | G8: =IF(ISNUMBER(Rechner!$B$26),F8/Rechner!$B$26,"—") -> 0.18645833
A9: 2437 | B9: Tor-1-Analyse (A-23), Erwartung am Messtag, mittel | C9: =IF(ISNUMBER(Rechner!$B$30),Rechner!$B$30/A9,"—") -> 0.099302421 | D9: =IF(ISNUMBER(Rechner!$B$31),Rechner!$B$31/A9,"—") -> 0.35699631 | E9: =ROUND(A9*Rechner!$B$44/100,0) -> 73 | F9: =E9*Rechner!$B$21 -> 3266.75 | G9: =IF(ISNUMBER(Rechner!$B$26),F9/Rechner!$B$26,"—") -> 0.30247685
A10: 3940 | B10: Tor-1-Analyse (A-23), Erwartung am Messtag, optimistisch | C10: =IF(ISNUMBER(Rechner!$B$30),Rechner!$B$30/A10,"—") -> 0.06142132 | D10: =IF(ISNUMBER(Rechner!$B$31),Rechner!$B$31/A10,"—") -> 0.22081218 | E10: =ROUND(A10*Rechner!$B$44/100,0) -> 118 | F10: =E10*Rechner!$B$21 -> 5280.5 | G10: =IF(ISNUMBER(Rechner!$B$26),F10/Rechner!$B$26,"—") -> 0.48893519
A12: Die 3 von 100 sind eine Faustregel für Besuche der Projektseite, nicht für Mails an eine Liste. Die Spalten E bis G zeigen eine Größenordnung, keine Prognose.
A14: Darf die Warteliste zur Kampagne angeschrieben werden? (Entscheidung Nr. 59) | C14: ja
A15: =IF(C14="ja","Die Liste zählt als Kanal — im Rahmen der Einwilligung, die sie abdeckt. Nr. 59 ist am 19.09.2026 so entschieden; der Einwilligungstext nennt die Finanzierungskampagne seit A-57 ausdrücklich (Anwaltsfragen K8, R6, U1 offen).",IF(C14="nein","Die Liste fällt als Kanal aus. Die Summe muss über Kanal, Partnerorte und Presse kommen.","Offen: Solange Nr. 59 nicht entschieden ist, zählt die Liste nicht als Kanal.")) -> Die Liste zählt als Kanal — im Rahmen der Einwilligung, die sie abdeckt. Nr. 59 ist am 19.09.2026 so entschieden; der Einwilligungstext nennt die Finanzierungskampagne seit A-57 ausdrücklich (Anwaltsfragen K8, R6, U1 offen).

Sheet Plattformen
A1: Plattformen — Gebühren und Regeln (Stand 16.09.2026)
A2: Aufgabe A-21 · erstellt 16.09.2026, fortgeschrieben 21.09.2026 · Grundlage: Handbuch B (Kapitalfahrplan, Abopreise, Einmalkosten), finanzmodell.xlsx (Szenario realistisch), Plattformseiten abgerufen am 16.09.2026 · ENTWURF — die Tabelle rechnet, entscheiden tun die Gründer.
A3: LEGENDE: Gelb mit blauer Schrift = Eingabe (Voreinstellung mit Herkunft, änderbar). Alles andere rechnet. ANNAHME = kein Erfahrungswert, bewusst gesetzt.
A5: Plattform | B5: Sitz | C5: Modell | D5: Provision (netto) | E5: Zahlung % | F5: Zahlung fix je Unterstützung | G5: Schwelle (€) | H5: Zahlung % unter der Schwelle | I5: Zahlung fix unter der Schwelle | J5: Regeln mit Bezug zu Cruizy | K5: Quelle | L5: abgerufen
A6: Startnext Basis | B6: Dresden, Deutschland (Startnext GmbH) | C6: Mindestbetrag (alles oder nichts) oder flexibel („jeder Euro zählt“) | D6: 0.05 | E6: 0.035 | F6: 0 | G6: 0 | H6: 0.035 | I6: 0 | J6: Ausgeschlossen u. a. „Pornografie, Sexualservices oder Escort-Dienstleistungen“ sowie „Fehlende Kennzeichnung von KI generierten Inhalten und Bildern“; Starter mindestens 18 Jahre. Ob eine Cruising-App zugelassen wird, vor der Planung schriftlich bei der Plattform klären. Vertrag über die Gegenleistung schließen Unterstützer und Starter; der Starter informiert über Widerrufsrechte (Nutzungsbedingungen, Stand August 2026). | K6: startnext.com/hilfe/gebuehren.html (Stand 31.3.26): Basis „5% neu“, Pro „11%“, Premium „14%“; Transaktionskosten „ca. 3,5% netto“, PayPal „3,5% + 45 Cent netto“; Gebühren „zzgl. MwSt.“ · startnext.com/hilfe/richtlinien.html · startnext.com/info/agb/anb.html | L6: 16.09.2026
A7: Startnext Basis — nur PayPal (vorsichtig) | B7: Dresden, Deutschland (Startnext GmbH) | C7: Mindestbetrag (alles oder nichts) oder flexibel („jeder Euro zählt“) | D7: 0.05 | E7: 0.035 | F7: 0.45 | G7: 0 | H7: 0.035 | I7: 0.45 | J7: Wie Startnext Basis, aber jede Unterstützung mit dem teuersten Zahlweg gerechnet (Karte: 2 % + 0,25 €, Lastschrift: 0,5 % + 0,35 €). | K7: startnext.com/hilfe/gebuehren.html (Stand 31.3.26) | L7: 16.09.2026
A8: Startnext Pro | B8: Dresden, Deutschland (Startnext GmbH) | C8: Mindestbetrag (alles oder nichts) oder flexibel („jeder Euro zählt“) | D8: 0.11 | E8: 0.035 | F8: 0 | G8: 0 | H8: 0.035 | I8: 0 | J8: Was Pro und Premium zusätzlich leisten, nennt die Gebührenseite nicht („Der Plan legt den Funktionsumfang und die Dienstleistungen fest“). Vor einer Wahl erfragen. | K8: startnext.com/hilfe/gebuehren.html (Stand 31.3.26) | L8: 16.09.2026
A9: Ulule | B9: Paris, Frankreich (Ulule) | C9: alles oder nichts (Belohnungsmodell) | D9: 0.0667 | E9: 0 | F9: 0 | G9: 0 | H9: 0 | I9: 0 | J9: Provision für Kartenzahlungen 6,67 % ohne USt; sie „includes all services and features of the platform“. Seit 14.04.2025 zahlen die Unterstützer zusätzlich eine eigene Servicegebühr (0,10 € + 2,2 %) — sie mindert den Erlös nicht, verteuert aber jede Unterstützung. | K9: support.ulule.com („What is Ulule’s commission?“) · outils.ulule.com (aktualisiert 1.7.2026) · Sitz: annuaire-entreprises.data.gouv.fr | L9: 16.09.2026
A10: Kickstarter | B10: Brooklyn, New York, USA (Kickstarter PBC) | C10: alles oder nichts | D10: 0.05 | E10: 0.03 | F10: 0.3 | G10: 10 | H10: 0.05 | I10: 0.08 | J10: US-Unternehmen. Handbuch A schließt US-Auftragsverarbeiter aus (Nr. 58); die Plattform wäre eigener Verantwortlicher, das Markenversprechen litte trotzdem. Deutschland ist als Starterland zugelassen. Verbotsliste nennt u. a. Dienstleister, Marktplätze, Gewinnspiele und pornografische Inhalte. | K10: kickstarter.com/help/fees?country=DE · help.kickstarter.com (Länderliste) · kickstarter.com/rules/prohibited · Sitz: Wikipedia | L10: 16.09.2026
A11: wemakeit | B11: Zürich, Schweiz | C11: nicht verifiziert | J11: Die Gebührenseiten der Plattform waren am 16.09.2026 nicht abrufbar (Fehler 403). Ein Plattformprofil von 2019 nennt 6 % plus 4 % — veraltet, hier nicht verwendet. | K11: crowdfunding.de/plattformen/wemakeit (Stand 2019) · wemakeit.com (nicht abrufbar) | L11: 16.09.2026
A13: Nicht mehr verfügbar: VisionBakery hat die Plattform am 28.02.2020 geschlossen (Fundraiser-Magazin, 21.02.2020). Ältere Vergleichslisten führen sie noch.
A14: Alle Provisionen netto. Bei Regelbesteuerung ist die Umsatzsteuer auf die Provision als Vorsteuer abziehbar; ohne Vorsteuerabzug (Kleinunternehmer) rechnet die Tabelle sie als Kosten. Transaktionskosten enthalten laut Startnext keine MwSt.
A15: Schwelle: Unterstützungen unter diesem Betrag werden mit den Werten „unter der Schwelle“ gerechnet (Kickstarter: unter 10 €). Leere gelbe Felder = keine belegte Angabe.
A16: Vor dem Start neu prüfen: Gebühren ändern sich — Startnext kennzeichnet den Basis-Satz als „neu“, Ulule hat 2025 eine Unterstützergebühr eingeführt.

Sheet Quellen
A1: Quellen — alle am 16.09.2026 abgerufen
A2: Aufgabe A-21 · erstellt 16.09.2026, fortgeschrieben 21.09.2026 · Grundlage: Handbuch B (Kapitalfahrplan, Abopreise, Einmalkosten), finanzmodell.xlsx (Szenario realistisch), Plattformseiten abgerufen am 16.09.2026 · ENTWURF — die Tabelle rechnet, entscheiden tun die Gründer.
A4: # | B4: Fundstelle | C4: Was daraus stammt | D4: Stand laut Quelle
A5: 1 | B5: https://www.startnext.com/hilfe/gebuehren.html | C5: Provision Basis 5 %, Pro 11 %, Premium 14 %; Transaktionskosten; „zzgl. MwSt.“; „Kosten nur bei Erfolg“ | D5: 31.03.2026
A6: 2 | B6: https://www.startnext.com/hilfe/richtlinien.html | C6: Ausschlüsse (u. a. Sexualservices, KI-Kennzeichnung, Glücksspiel und Lose), Mindestalter 18, Sitzländer | D6: ohne Datum
A7: 3 | B7: https://www.startnext.com/info/agb/anb.html | C7: Vertragspartner Unterstützer und Starter; Hinweispflicht zu Widerrufsrechten; Datenübermittlung ab Mindestbetrag | D7: August 2026
A8: 4 | B8: https://www.startnext.com/hilfe/handbuch/finanzierungsziel.html | C8: Mindestbetrag (alles oder nichts) und flexible Kampagne; Bestandteile der Zielsumme | D8: ohne Datum
A9: 5 | B9: https://www.startnext.com/hilfe/handbuch/kommunikation.html | C9: 20–40 % in 72 Stunden; 1 € je Besuch; 3 von 100; Ø 35 €; Start am Donnerstag; sieben Kontaktversuche | D9: ohne Datum
A10: 6 | B10: https://www.startnext.com/hilfe/handbuch/dankeschoens.html | C10: Warenkorb 35–75 €; Versandkosten gehören in den Preis; Limits; Unterstützerlisten mit Namen, Adressen, E-Mail | D10: ohne Datum
A11: 7 | B11: https://www.startnext.com/info/impressum.html | C11: Startnext GmbH, Dresden | D11: —
A12: 8 | B12: https://support.ulule.com/hc/en-us/articles/211812409-What-is-Ulule-s-commission | C12: Provision 6,67 % ohne USt (Karte), enthält alle Leistungen; nur bei Erfolg | D12: ohne Datum
A13: 9 | B13: https://outils.ulule.com/articles/frais-ulule-commission-service-contributeurs | C13: Servicegebühr der Unterstützer seit 14.04.2025 (0,10 € + 2,2 %) | D13: 01.07.2026
A14: 10 | B14: https://annuaire-entreprises.data.gouv.fr/entreprise/ulule-794710830 | C14: Sitz Paris | D14: —
A15: 11 | B15: https://www.kickstarter.com/help/fees?country=DE | C15: 5 % Plattform; 3 % + 0,30 € je Unterstützung; unter 10 €: 5 % + 0,08 €; nur bei Erfolg | D15: ohne Datum
A16: 12 | B16: https://help.kickstarter.com/hc/en-us/articles/115005128014 | C16: Deutschland als Starterland zugelassen | D16: ohne Datum
... A29: 25 | B29: 01-steuerung/tor-1-zeitachse-analyse.md | C29: Erwartungswerte der Warteliste am Messtag (1.247 / 2.437 / 3.940); zwei Uhren | D29: 27.07.2026
