Workbook

Sheet Anleitung
A1: Terminservice „Heute ohne App“ — Arbeitstabelle
A2: ENTWURF · Aufgabe A-16 · erstellt 15.09.2026 · Konzept: terminservice-konzept.md (gleicher Ordner) · Nichts wird ohne Freigabe beider Gründer veröffentlicht.
A3: LEGENDE: Gelbe Zellen sind zum Ausfüllen. Blaue Zahlen sind Planwerte und dürfen überschrieben werden. Alles andere rechnet. Graue Zeilen mit „BEISPIEL“ vor Gebrauch löschen.
A5: Die Blätter
A6: Blatt | B6: Wofür | C6: Wann
A7: Freigaben | B7: Wer genannt werden darf. Ohne Eintrag „freigegeben“ wird kein Termin veröffentlicht. Vorbefüllt mit den 33 benannten Orten der Ortsliste Köln (Stand 24.07.2026). | C7: bei jedem Gespräch mit einem Ort
A8: Termine | B8: Sammeln, prüfen, auswählen. Die Spalte „Veröffentlichungsfähig?“ sagt, ob alle Regeln erfüllt sind — und wenn nicht, warum. | C8: Montag bis Mittwoch
A9: Aufwand | B9: Minuten je Arbeitsschritt und Formatoption. Prüft das Abnahmekriterium: unter drei Stunden je Woche für Gründer 2. | C9: vor dem Start, dann nach Woche 3
A10: Messung | B10: Kennzahlen je Woche, Soll-Werte der Gründer und das Feld für die Entscheidung nach Woche 13. | C10: jeden Montag
A11: Kalender | B11: Die 13 Ausgaben mit Datum und die Anlässe, die in den Zeitraum fallen. Rechnet vom Startdatum im Blatt „Messung“. | C11: sobald T0 feststeht (Nr. 45)
A13: Fünf Regeln, die jede Woche gelten
A14: Regel | B14: Inhalt | C14: Konzept
A15: Freigabe vor Nennung | B15: Ein Veranstalter wird erst genannt, wenn seine Freigabe in Textform vorliegt. Das gilt auch für große Veranstalter. | C15: Abschnitt 4, Q2
A16: An der Quelle bestätigen | B16: Jede Angabe wird beim Veranstalter selbst geprüft, nie aus einem Sammelkalender übernommen. | C16: Abschnitt 4, Q3 und Q4
A17: Eigene Worte, eigene Gestaltung | B17: Keine fremden Texte, keine Flyer, Logos oder Fotos — auch nicht über die Teilen-Funktion. | C17: Abschnitt 4, Q5 und Q6
A18: Ampel rot nie öffentlich | B18: Termine, deren Kern sexuelle Handlungen sind, erscheinen nicht im öffentlichen Kanal. Orte im öffentlichen Raum zum Cruisen erscheinen nirgends. | C18: Abschnitt 5 und Nr. 55
A19: Gegenleistung heißt Kennzeichnung | B19: Wird eine Gegenleistung vereinbart, etwa Hervorhebung gegen Erwähnung, wird die Nennung als Werbung gekennzeichnet (§ 5a Abs. 4 UWG). | C19: Abschnitt 4, Q9
A21: Wochenablauf
A22: Tag · Schritt | B22: Was | C22: Minuten (gewählte Option)
A23: Mo · termine@ sichten | B23: Neue Veranstalter-Mails lesen, Termine ins Blatt „Termine“ eintragen, erledigte Mails markieren | C23: =INDEX(Aufwand!$D$6:$H$6,1,MATCH(Aufwand!$C$22,Aufwand!$D$5:$H$5,0)) -> 15
A24: Di · Terminkanäle durchgehen | B24: Öffentliche Kanäle der freigegebenen Veranstalter prüfen; Sammelkalender nur als Hinweis; Neue ohne Freigabe nur ins Blatt „Freigaben“ | C24: =INDEX(Aufwand!$D$7:$H$7,1,MATCH(Aufwand!$C$22,Aufwand!$D$5:$H$5,0)) -> 20
A25: Mi · Prüfen, auswählen, texten | B25: Jede Angabe an der Veranstalterquelle bestätigen, Ampel prüfen, höchstens zehn Termine wählen, Kurzinfos in eigenen Worten | C25: =INDEX(Aufwand!$D$8:$H$8,1,MATCH(Aufwand!$C$22,Aufwand!$D$5:$H$5,0)) -> 25
A26: Do · Wochenset gestalten | B26: Titelframe, Terminframes und Schlussframe aus der Vorlage befüllen | C26: =INDEX(Aufwand!$D$9:$H$9,1,MATCH(Aufwand!$C$22,Aufwand!$D$5:$H$5,0)) -> 35
A27: Do · Tagesframes vorplanen | B27: Je einen Frame „Heute in Köln“ für Freitag bis Mittwoch anlegen und zeitlich planen | C27: =INDEX(Aufwand!$D$10:$H$10,1,MATCH(Aufwand!$C$22,Aufwand!$D$5:$H$5,0)) -> 15
A28: Do · Live veröffentlichen | B28: Wochenset posten, Erwähnungen und Frage-Sticker setzen, Highlight „Diese Woche“ austauschen | C28: =INDEX(Aufwand!$D$11:$H$11,1,MATCH(Aufwand!$C$22,Aufwand!$D$5:$H$5,0)) -> 10
A29: tägl. · Änderungen prüfen | B29: Absagen der Tagesauswahl beim Veranstalter prüfen, bei Bedarf Korrektur-Frame (6 × 3 Min.; schlank: nur Fr–So, 3 × 3 Min.) | C29: =INDEX(Aufwand!$D$12:$H$12,1,MATCH(Aufwand!$C$22,Aufwand!$D$5:$H$5,0)) -> 18
A30: Do · Mail schreiben | B30: Mail aus dem Gerüst befüllen; bei „beides“ die Kurzinfos der Stories übernehmen | C30: =INDEX(Aufwand!$D$13:$H$13,1,MATCH(Aufwand!$C$22,Aufwand!$D$5:$H$5,0)) -> 0
A31: Do · Mail prüfen und planen | B31: Testversand an die eigene Adresse, Mobil- und Dunkelansicht, Links, Versand für Donnerstag planen | C31: =INDEX(Aufwand!$D$14:$H$14,1,MATCH(Aufwand!$C$22,Aufwand!$D$5:$H$5,0)) -> 0
A32: lfd. · Antworten | B32: Story-Antworten und Antwort-Mails beantworten (bei „Modul“ nur Stories — die Mail gehört zu A-17) | C32: =INDEX(Aufwand!$D$15:$H$15,1,MATCH(Aufwand!$C$22,Aufwand!$D$5:$H$5,0)) -> 15
A33: Mo · Messen | B33: Kennzahlen der Vorwoche und Ist-Minuten ins Blatt „Messung“ eintragen | C33: =INDEX(Aufwand!$D$16:$H$16,1,MATCH(Aufwand!$C$22,Aufwand!$D$5:$H$5,0)) -> 10
A34: Summe | B34: Gewählte Option steht im Blatt „Aufwand“, Zelle C22. | C34: =SUM(C23:C33) -> 163

Sheet Freigaben
A1: Freigaben — wer genannt werden darf
A2: ENTWURF · Aufgabe A-16 · erstellt 15.09.2026 · Konzept: terminservice-konzept.md (gleicher Ordner) · Nichts wird ohne Freigabe beider Gründer veröffentlicht.
A3: Vorbefüllt aus 60-orte-b2b/ortsliste-koeln.xlsx (Stand 24.07.2026). Die Ampel ist ein Vorschlag nach der Art des Ortes und wird im Gespräch geprüft. Gegenleistung „ja“ bedeutet: jede Nennung als Werbung kennzeichnen.
A4: Nr | B4: Veranstalter oder Ort | C4: Nr. in Ortsliste | D4: Art (laut Ortsliste) | E4: Recherche-Status (Ortsliste) | F4: Öffentlicher Terminkanal (Website, Profil, Newsletter) | G4: Freigabe erteilt am | H4: Form der Freigabe | I4: Wer hat gefragt | J4: Gegenleistung vereinbart? | K4: Beispielmail aufbewahren erlaubt? | L4: Widerrufen am | M4: Status | N4: Ampel (Vorschlag) | O4: Kennzeichnung nötig? | P4: Notiz
A5: BSP | B5: Beispielort (fiktiv) — BEISPIEL, vor Gebrauch löschen | C5: — | D5: Bar | E5: — | F5: www.beispiel.invalid/termine | G5: 47016 | H5: Gespräch + Nachricht | I5: Gründer 2 | J5: nein | K5: nein | M5: =IF(B5="","",IF(L5<>"","widerrufen",IF(G5<>"","freigegeben","offen"))) -> freigegeben | N5: grün | O5: =IF(B5="","",IF(J5="ja","ja — als Werbung kennzeichnen",IF(J5="nein","nein","noch nicht geklärt"))) -> nein | P5: Beispiel zur Formelprüfung
A6: 1 | B6: ExCorner | C6: 1 | D6: Bar/Tanzbar | E6: per Websuche bestätigt 07/2026 | M6: =IF(B6="","",IF(L6<>"","widerrufen",IF(G6<>"","freigegeben","offen"))) -> offen | N6: grün | O6: =IF(B6="","",IF(J6="ja","ja — als Werbung kennzeichnen",IF(J6="nein","nein","noch nicht geklärt"))) -> noch nicht geklärt
A7: 2 | B7: Schampanja | C7: 2 | D7: Kneipe (Institution, 30+ Jahre) | E7: per Websuche bestätigt 07/2026 | M7: =IF(B7="","",IF(L7<>"","widerrufen",IF(G7<>"","freigegeben","offen"))) -> offen | N7: grün | O7: =IF(B7="","",IF(J7="ja","ja — als Werbung kennzeichnen",IF(J7="nein","nein","noch nicht geklärt"))) -> noch nicht geklärt
A8: 3 | B8: Die Mumu | C8: 3 | D8: Bar (Karaoke, schrill) | E8: per Websuche bestätigt 07/2026 | M8: =IF(B8="","",IF(L8<>"","widerrufen",IF(G8<>"","freigegeben","offen"))) -> offen | N8: grün | O8: =IF(B8="","",IF(J8="ja","ja — als Werbung kennzeichnen",IF(J8="nein","nein","noch nicht geklärt"))) -> noch nicht geklärt
A9: 4 | B9: Iron Cocktail Lounge | C9: 4 | D9: Cocktailbar | E9: per Websuche bestätigt 07/2026 | M9: =IF(B9="","",IF(L9<>"","widerrufen",IF(G9<>"","freigegeben","offen"))) -> offen | N9: grün | O9: =IF(B9="","",IF(J9="ja","ja — als Werbung kennzeichnen",IF(J9="nein","nein","noch nicht geklärt"))) -> noch nicht geklärt
A10: 5 | B10: Blue Lounge | C10: 5 | D10: Bar (gemischt/lesbisch) | E10: Vorwissen — vor Kontakt verifizieren | M10: =IF(B10="","",IF(L10<>"","widerrufen",IF(G10<>"","freigegeben","offen"))) -> offen | N10: grün | O10: =IF(B10="","",IF(J10="ja","ja — als Werbung kennzeichnen",IF(J10="nein","nein","noch nicht geklärt"))) -> noch nicht geklärt
A11: 6 | B11: Stiefelknecht | C11: 6 | D11: Leder-/Cruising-Bar | E11: Vorwissen — vor Kontakt verifizieren | M11: =IF(B11="","",IF(L11<>"","widerrufen",IF(G11<>"","freigegeben","offen"))) -> offen | N11: gelb | O11: =IF(B11="","",IF(J11="ja","ja — als Werbung kennzeichnen",IF(J11="nein","nein","noch nicht geklärt"))) -> noch nicht geklärt
A12: 7 | B12: Vampire | C12: 7 | D12: Bar (lesbisch/queer) | E12: Vorwissen — vor Kontakt verifizieren | M12: =IF(B12="","",IF(L12<>"","widerrufen",IF(G12<>"","freigegeben","offen"))) -> offen | N12: grün | O12: =IF(B12="","",IF(J12="ja","ja — als Werbung kennzeichnen",IF(J12="nein","nein","noch nicht geklärt"))) -> noch nicht geklärt
A13: 8 | B13: Baustelle 4U | C13: 8 | D13: Bar | E13: per Websuche bestätigt 07/2026 | M13: =IF(B13="","",IF(L13<>"","widerrufen",IF(G13<>"","freigegeben","offen"))) -> offen | N13: grün | O13: =IF(B13="","",IF(J13="ja","ja — als Werbung kennzeichnen",IF(J13="nein","nein","noch nicht geklärt"))) -> noch nicht geklärt
A14: 9 | B14: Barcelon | C14: 9 | D14: Café-Bar | E14: Vorwissen — vor Kontakt verifizieren | M14: =IF(B14="","",IF(L14<>"","widerrufen",IF(G14<>"","freigegeben","offen"))) -> offen | N14: grün | O14: =IF(B14="","",IF(J14="ja","ja — als Werbung kennzeichnen",IF(J14="nein","nein","noch nicht geklärt"))) -> noch nicht geklärt
A15: 10 | B15: Zum Pitter | C15: 10 | D15: Traditionskneipe | E15: Vorwissen — vor Kontakt verifizieren | M15: =IF(B15="","",IF(L15<>"","widerrufen",IF(G15<>"","freigegeben","offen"))) -> offen | N15: grün | O15: =IF(B15="","",IF(J15="ja","ja — als Werbung kennzeichnen",IF(J15="nein","nein","noch nicht geklärt"))) -> noch nicht geklärt
A16: 11 | B16: Comeback | C16: 11 | D16: Kneipe | E16: Vorwissen — vor Kontakt verifizieren | M16: =IF(B16="","",IF(L16<>"","widerrufen",IF(G16<>"","freigegeben","offen"))) -> offen | N16: grün | O16: =IF(B16="","",IF(J16="ja","ja — als Werbung kennzeichnen",IF(J16="nein","nein","noch nicht geklärt"))) -> noch nicht geklärt | P16: evtl. geschlossen laut Ortsliste — prüfen
A17: 12 | B17: Exile on Mainstreet | C17: 12 | D17: Bar | E17: Vorwissen — vor Kontakt verifizieren | M17: =IF(B17="","",IF(L17<>"","widerrufen",IF(G17<>"","freigegeben","offen"))) -> offen | N17: grün | O17: =IF(B17="","",IF(J17="ja","ja — als Werbung kennzeichnen",IF(J17="nein","nein","noch nicht geklärt"))) -> noch nicht geklärt
A18: 13 | B18: Hotel Timp | C18: 13 | D18: Travestie-Bar/Hotel | E18: Vorwissen — vor Kontakt verifizieren | M18: =IF(B18="","",IF(L18<>"","widerrufen",IF(G18<>"","freigegeben","offen"))) -> offen | N18: grün | O18: =IF(B18="","",IF(J18="ja","ja — als Werbung kennzeichnen",IF(J18="nein","nein","noch nicht geklärt"))) -> noch nicht geklärt
A19: 14 | B19: Badehaus Babylon | C19: 14 | D19: Sauna | E19: per Websuche bestätigt 07/2026 | M19: =IF(B19="","",IF(L19<>"","widerrufen",IF(G19<>"","freigegeben","offen"))) -> offen | N19: gelb | O19: =IF(B19="","",IF(J19="ja","ja — als Werbung kennzeichnen",IF(J19="nein","nein","noch nicht geklärt"))) -> noch nicht geklärt
A20: 15 | B20: Phoenix Sauna Köln | C20: 15 | D20: Sauna | E20: per Websuche bestätigt 07/2026 | M20: =IF(B20="","",IF(L20<>"","widerrufen",IF(G20<>"","freigegeben","offen"))) -> offen | N20: gelb | O20: =IF(B20="","",IF(J20="ja","ja — als Werbung kennzeichnen",IF(J20="nein","nein","noch nicht geklärt"))) -> noch nicht geklärt
A21: 16 | B21: Station 2B | C21: 16 | D21: Cruising-Club | E21: per Websuche bestätigt 07/2026 | M21: =IF(B21="","",IF(L21<>"","widerrufen",IF(G21<>"","freigegeben","offen"))) -> offen | N21: gelb | O21: =IF(B21="","",IF(J21="ja","ja — als Werbung kennzeichnen",IF(J21="nein","nein","noch nicht geklärt"))) -> noch nicht geklärt
A22: 17 | B22: Chains | C22: 17 | D22: Fetisch-/Cruising-Bar | E22: Vorwissen — vor Kontakt verifizieren | M22: =IF(B22="","",IF(L22<>"","widerrufen",IF(G22<>"","freigegeben","offen"))) -> offen | N22: gelb | O22: =IF(B22="","",IF(J22="ja","ja — als Werbung kennzeichnen",IF(J22="nein","nein","noch nicht geklärt"))) -> noch nicht geklärt
A23: 18 | B23: Hustler | C23: 18 | D23: Cruising-Bar | E23: Existenz unklar — prüfen oder streichen | M23: =IF(B23="","",IF(L23<>"","widerrufen",IF(G23<>"","freigegeben","offen"))) -> offen | N23: gelb | O23: =IF(B23="","",IF(J23="ja","ja — als Werbung kennzeichnen",IF(J23="nein","nein","noch nicht geklärt"))) -> noch nicht geklärt | P23: Existenz unklar laut Ortsliste — vor Kontakt prüfen
A24: 19 | B24: Gloria Theater | C24: 19 | D24: Club/Kulturhaus (queer-affin) | E24: Vorwissen — vor Kontakt verifizieren | M24: =IF(B24="","",IF(L24<>"","widerrufen",IF(G24<>"","freigegeben","offen"))) -> offen | N24: grün | O24: =IF(B24="","",IF(J24="ja","ja — als Werbung kennzeichnen",IF(J24="nein","nein","noch nicht geklärt"))) -> noch nicht geklärt
A25: 20 | B25: Garry Klein | C25: 20 | D25: Queere Techno-Partyreihe | E25: Vorwissen — vor Kontakt verifizieren | M25: =IF(B25="","",IF(L25<>"","widerrufen",IF(G25<>"","freigegeben","offen"))) -> offen | N25: grün | O25: =IF(B25="","",IF(J25="ja","ja — als Werbung kennzeichnen",IF(J25="nein","nein","noch nicht geklärt"))) -> noch nicht geklärt
A26: 21 | B26: Revolver Party | C26: 21 | D26: Queere Partyreihe | E26: Vorwissen — vor Kontakt verifizieren | M26: =IF(B26="","",IF(L26<>"","widerrufen",IF(G26<>"","freigegeben","offen"))) -> offen | N26: grün | O26: =IF(B26="","",IF(J26="ja","ja — als Werbung kennzeichnen",IF(J26="nein","nein","noch nicht geklärt"))) -> noch nicht geklärt
A27: 22 | B27: Queerfilmnacht Köln | C27: 22 | D27: Filmreihe | E27: Vorwissen — vor Kontakt verifizieren | M27: =IF(B27="","",IF(L27<>"","widerrufen",IF(G27<>"","freigegeben","offen"))) -> offen | N27: grün | O27: =IF(B27="","",IF(J27="ja","ja — als Werbung kennzeichnen",IF(J27="nein","nein","noch nicht geklärt"))) -> noch nicht geklärt
A28: 23 | B28: anyway e.V. | C28: 23 | D28: Queeres Jugendzentrum + Café | E28: per Websuche bestätigt 07/2026 | M28: =IF(B28="","",IF(L28<>"","widerrufen",IF(G28<>"","freigegeben","offen"))) -> offen | N28: grün | O28: =IF(B28="","",IF(J28="ja","ja — als Werbung kennzeichnen",IF(J28="nein","nein","noch nicht geklärt"))) -> noch nicht geklärt
A29: 24 | B29: rubicon e.V. | C29: 24 | D29: Queere Beratungsstelle | E29: per Websuche bestätigt 07/2026 | M29: =IF(B29="","",IF(L29<>"","widerrufen",IF(G29<>"","freigegeben","offen"))) -> offen | N29: grün | O29: =IF(B29="","",IF(J29="ja","ja — als Werbung kennzeichnen",IF(J29="nein","nein","noch nicht geklärt"))) -> noch nicht geklärt
A30: 25 | B30: Aidshilfe Köln | C30: 25 | D30: Gesundheit/Beratung | E30: Vorwissen — vor Kontakt verifizieren | M30: =IF(B30="","",IF(L30<>"","widerrufen",IF(G30<>"","freigegeben","offen"))) -> offen | N30: grün | O30: =IF(B30="","",IF(J30="ja","ja — als Werbung kennzeichnen",IF(J30="nein","nein","noch nicht geklärt"))) -> noch nicht geklärt
A31: 26 | B31: Checkpoint Köln | C31: 26 | D31: Test-/Gesundheitsangebot | E31: Vorwissen — vor Kontakt verifizieren | M31: =IF(B31="","",IF(L31<>"","widerrufen",IF(G31<>"","freigegeben","offen"))) -> offen | N31: grün | O31: =IF(B31="","",IF(J31="ja","ja — als Werbung kennzeichnen",IF(J31="nein","nein","noch nicht geklärt"))) -> noch nicht geklärt
A32: 27 | B32: SC Janus e.V. | C32: 27 | D32: Queerer Sportverein (Europas größter) | E32: per Websuche bestätigt 07/2026 | M32: =IF(B32="","",IF(L32<>"","widerrufen",IF(G32<>"","freigegeben","offen"))) -> offen | N32: grün | O32: =IF(B32="","",IF(J32="ja","ja — als Werbung kennzeichnen",IF(J32="nein","nein","noch nicht geklärt"))) -> noch nicht geklärt
A33: 28 | B33: Centrum Schwule Geschichte | C33: 28 | D33: Archiv/Verein | E33: Vorwissen — vor Kontakt verifizieren | M33: =IF(B33="","",IF(L33<>"","widerrufen",IF(G33<>"","freigegeben","offen"))) -> offen | N33: grün | O33: =IF(B33="","",IF(J33="ja","ja — als Werbung kennzeichnen",IF(J33="nein","nein","noch nicht geklärt"))) -> noch nicht geklärt
A34: 29 | B34: ColognePride / KLuST e.V. | C34: 29 | D34: CSD-Veranstalter (19.06.–05.07.2026) | E34: per Websuche bestätigt 07/2026 | M34: =IF(B34="","",IF(L34<>"","widerrufen",IF(G34<>"","freigegeben","offen"))) -> offen | N34: grün | O34: =IF(B34="","",IF(J34="ja","ja — als Werbung kennzeichnen",IF(J34="nein","nein","noch nicht geklärt"))) -> noch nicht geklärt
A35: 30 | B35: QueerGoingOut | C35: 30 | D35: Terminkalender Köln (Medium) | E35: per Websuche bestätigt 07/2026 | M35: =IF(B35="","",IF(L35<>"","widerrufen",IF(G35<>"","freigegeben","offen"))) -> offen | N35: grün | O35: =IF(B35="","",IF(J35="ja","ja — als Werbung kennzeichnen",IF(J35="nein","nein","noch nicht geklärt"))) -> noch nicht geklärt
... A38: 33 | B38: Zauberflöten Köln | C38: 33 | D38: Schwuler Chor | E38: Vorwissen — vor Kontakt verifizieren | M38: =IF(B38="","",IF(L38<>"","widerrufen",IF(G38<>"","freigegeben","offen"))) -> offen | N38: grün | O38: =IF(B38="","",IF(J38="ja","ja — als Werbung kennzeichnen",IF(J38="nein","nein","noch nicht geklärt"))) -> noch nicht geklärt
A39: 34 | M39: =IF(B39="","",IF(L39<>"","widerrufen",IF(G39<>"","freigegeben","offen"))) | O39: =IF(B39="","",IF(J39="ja","ja — als Werbung kennzeichnen",IF(J39="nein","nein","noch nicht geklärt")))
A40: 35 | M40: =IF(B40="","",IF(L40<>"","widerrufen",IF(G40<>"","freigegeben","offen"))) | O40: =IF(B40="","",IF(J40="ja","ja — als Werbung kennzeichnen",IF(J40="nein","nein","noch nicht geklärt")))
A41: 36 | M41: =IF(B41="","",IF(L41<>"","widerrufen",IF(G41<>"","freigegeben","offen"))) | O41: =IF(B41="","",IF(J41="ja","ja — als Werbung kennzeichnen",IF(J41="nein","nein","noch nicht geklärt")))
A42: 37 | M42: =IF(B42="","",IF(L42<>"","widerrufen",IF(G42<>"","freigegeben","offen"))) | O42: =IF(B42="","",IF(J42="ja","ja — als Werbung kennzeichnen",IF(J42="nein","nein","noch nicht geklärt")))
...

Sheet Termine
A1: Termine — sammeln, prüfen, auswählen
A2: ENTWURF · Aufgabe A-16 · erstellt 15.09.2026 · Konzept: terminservice-konzept.md (gleicher Ordner) · Nichts wird ohne Freigabe beider Gründer veröffentlicht.
A3: Veranstalter genau so schreiben wie im Blatt „Freigaben“ (Spalte B), sonst findet die Prüfung keine Freigabe. Kurzinfo höchstens 60 Zeichen, eigene Worte. „Veröffentlichungsfähig?“ prüft Freigabe, Bestätigung an der Quelle, Ampel und Länge.
A4: Woche (1–13) | B4: Datum | C4: Tag | D4: Beginn | E4: Ende | F4: Titel (wie angekündigt) | G4: Kurzinfo in eigenen Worten | H4: Zeichen | I4: Veranstalter oder Ort (wie in „Freigaben“) | J4: Freigabe? | K4: Ampel | L4: Quelle beim Veranstalter (Link) | M4: An der Quelle bestätigt am | N4: Gefunden über | O4: ab 18 | P4: Eintritt (nur wenn angegeben) | Q4: Zugang (nur wenn angegeben) | R4: Kanal | S4: Status | T4: Veröffentlichungsfähig? | U4: Grund, falls nein | V4: Notiz
A5: 1 | B5: 47031 | C5: =IF(B5="","",CHOOSE(WEEKDAY(B5,2),"Mo","Di","Mi","Do","Fr","Sa","So")) -> Do | D5: 0.83333333 | E5: 0.95833333 | F5: Beispielabend — BEISPIEL, vor Gebrauch löschen | G5: Quiz mit Musik, ohne Anmeldung | H5: =IF(G5="","",LEN(G5)) -> 30 | I5: Beispielort (fiktiv) — BEISPIEL, vor Gebrauch löschen | J5: =IF(I5="","",IF(COUNTIFS(Freigaben!$B$5:$B$58,I5,Freigaben!$M$5:$M$58,"freigegeben")>0,"ja","nein")) -> ja | K5: =IF(I5="","",IFERROR(IF(INDEX(Freigaben!$N$5:$N$58,MATCH(I5,Freigaben!$B$5:$B$58,0))="","ohne Ampel",INDEX(Freigaben!$N$5:$N$58,MATCH(I5,Freigaben!$B$5:$B$58,0))),"nicht in Freigaben")) -> grün | L5: www.beispiel.invalid/termine | M5: 47030 | N5: Terminkanal des Veranstalters | O5: nein | P5: frei | R5: beides | S5: ausgewählt | T5: =IF(F5="","",IF(AND(J5="ja",M5<>"",OR(K5="grün",K5="gelb"),LEN(G5)<=60),"ja","nein")) -> ja | U5: =IF(T5<>"nein","",IF(J5<>"ja","keine Freigabe",IF(M5="","nicht an der Quelle bestätigt",IF(K5="rot","Ampel rot — nicht öffentlich",IF(OR(K5="ohne Ampel",K5="nicht in Freigaben"),"Ampel fehlt",IF(LEN(G5)>60,"Kurzinfo zu lang","")))))) | V5: Beispiel zur Formelprüfung
C6: =IF(B6="","",CHOOSE(WEEKDAY(B6,2),"Mo","Di","Mi","Do","Fr","Sa","So")) | H6: =IF(G6="","",LEN(G6)) | J6: =IF(I6="","",IF(COUNTIFS(Freigaben!$B$5:$B$58,I6,Freigaben!$M$5:$M$58,"freigegeben")>0,"ja","nein")) | K6: =IF(I6="","",IFERROR(IF(INDEX(Freigaben!$N$5:$N$58,MATCH(I6,Freigaben!$B$5:$B$58,0))="","ohne Ampel",INDEX(Freigaben!$N$5:$N$58,MATCH(I6,Freigaben!$B$5:$B$58,0))),"nicht in Freigaben")) | T6: =IF(F6="","",IF(AND(J6="ja",M6<>"",OR(K6="grün",K6="gelb"),LEN(G6)<=60),"ja","nein")) | U6: =IF(T6<>"nein","",IF(J6<>"ja","keine Freigabe",IF(M6="","nicht an der Quelle bestätigt",IF(K6="rot","Ampel rot — nicht öffentlich",IF(OR(K6="ohne Ampel",K6="nicht in Freigaben"),"Ampel fehlt",IF(LEN(G6)>60,"Kurzinfo zu lang",""))))))
C7: =IF(B7="","",CHOOSE(WEEKDAY(B7,2),"Mo","Di","Mi","Do","Fr","Sa","So")) | H7: =IF(G7="","",LEN(G7)) | J7: =IF(I7="","",IF(COUNTIFS(Freigaben!$B$5:$B$58,I7,Freigaben!$M$5:$M$58,"freigegeben")>0,"ja","nein")) | K7: =IF(I7="","",IFERROR(IF(INDEX(Freigaben!$N$5:$N$58,MATCH(I7,Freigaben!$B$5:$B$58,0))="","ohne Ampel",INDEX(Freigaben!$N$5:$N$58,MATCH(I7,Freigaben!$B$5:$B$58,0))),"nicht in Freigaben")) | T7: =IF(F7="","",IF(AND(J7="ja",M7<>"",OR(K7="grün",K7="gelb"),LEN(G7)<=60),"ja","nein")) | U7: =IF(T7<>"nein","",IF(J7<>"ja","keine Freigabe",IF(M7="","nicht an der Quelle bestätigt",IF(K7="rot","Ampel rot — nicht öffentlich",IF(OR(K7="ohne Ampel",K7="nicht in Freigaben"),"Ampel fehlt",IF(LEN(G7)>60,"Kurzinfo zu lang",""))))))
C8: =IF(B8="","",CHOOSE(WEEKDAY(B8,2),"Mo","Di","Mi","Do","Fr","Sa","So")) | H8: =IF(G8="","",LEN(G8)) | J8: =IF(I8="","",IF(COUNTIFS(Freigaben!$B$5:$B$58,I8,Freigaben!$M$5:$M$58,"freigegeben")>0,"ja","nein")) | K8: =IF(I8="","",IFERROR(IF(INDEX(Freigaben!$N$5:$N$58,MATCH(I8,Freigaben!$B$5:$B$58,0))="","ohne Ampel",INDEX(Freigaben!$N$5:$N$58,MATCH(I8,Freigaben!$B$5:$B$58,0))),"nicht in Freigaben")) | T8: =IF(F8="","",IF(AND(J8="ja",M8<>"",OR(K8="grün",K8="gelb"),LEN(G8)<=60),"ja","nein")) | U8: =IF(T8<>"nein","",IF(J8<>"ja","keine Freigabe",IF(M8="","nicht an der Quelle bestätigt",IF(K8="rot","Ampel rot — nicht öffentlich",IF(OR(K8="ohne Ampel",K8="nicht in Freigaben"),"Ampel fehlt",IF(LEN(G8)>60,"Kurzinfo zu lang",""))))))
C9: =IF(B9="","",CHOOSE(WEEKDAY(B9,2),"Mo","Di","Mi","Do","Fr","Sa","So")) | H9: =IF(G9="","",LEN(G9)) | J9: =IF(I9="","",IF(COUNTIFS(Freigaben!$B$5:$B$58,I9,Freigaben!$M$5:$M$58,"freigegeben")>0,"ja","nein")) | K9: =IF(I9="","",IFERROR(IF(INDEX(Freigaben!$N$5:$N$58,MATCH(I9,Freigaben!$B$5:$B$58,0))="","ohne Ampel",INDEX(Freigaben!$N$5:$N$58,MATCH(I9,Freigaben!$B$5:$B$58,0))),"nicht in Freigaben")) | T9: =IF(F9="","",IF(AND(J9="ja",M9<>"",OR(K9="grün",K9="gelb"),LEN(G9)<=60),"ja","nein")) | U9: =IF(T9<>"nein","",IF(J9<>"ja","keine Freigabe",IF(M9="","nicht an der Quelle bestätigt",IF(K9="rot","Ampel rot — nicht öffentlich",IF(OR(K9="ohne Ampel",K9="nicht in Freigaben"),"Ampel fehlt",IF(LEN(G9)>60,"Kurzinfo zu lang",""))))))
C10: =IF(B10="","",CHOOSE(WEEKDAY(B10,2),"Mo","Di","Mi","Do","Fr","Sa","So")) | H10: =IF(G10="","",LEN(G10)) | J10: =IF(I10="","",IF(COUNTIFS(Freigaben!$B$5:$B$58,I10,Freigaben!$M$5:$M$58,"freigegeben")>0,"ja","nein")) | K10: =IF(I10="","",IFERROR(IF(INDEX(Freigaben!$N$5:$N$58,MATCH(I10,Freigaben!$B$5:$B$58,0))="","ohne Ampel",INDEX(Freigaben!$N$5:$N$58,MATCH(I10,Freigaben!$B$5:$B$58,0))),"nicht in Freigaben")) | T10: =IF(F10="","",IF(AND(J10="ja",M10<>"",OR(K10="grün",K10="gelb"),LEN(G10)<=60),"ja","nein")) | U10: =IF(T10<>"nein","",IF(J10<>"ja","keine Freigabe",IF(M10="","nicht an der Quelle bestätigt",IF(K10="rot","Ampel rot — nicht öffentlich",IF(OR(K10="ohne Ampel",K10="nicht in Freigaben"),"Ampel fehlt",IF(LEN(G10)>60,"Kurzinfo zu lang",""))))))
C11: =IF(B11="","",CHOOSE(WEEKDAY(B11,2),"Mo","Di","Mi","Do","Fr","Sa","So")) | H11: =IF(G11="","",LEN(G11)) | J11: =IF(I11="","",IF(COUNTIFS(Freigaben!$B$5:$B$58,I11,Freigaben!$M$5:$M$58,"freigegeben")>0,"ja","nein")) | K11: =IF(I11="","",IFERROR(IF(INDEX(Freigaben!$N$5:$N$58,MATCH(I11,Freigaben!$B$5:$B$58,0))="","ohne Ampel",INDEX(Freigaben!$N$5:$N$58,MATCH(I11,Freigaben!$B$5:$B$58,0))),"nicht in Freigaben")) | T11: =IF(F11="","",IF(AND(J11="ja",M11<>"",OR(K11="grün",K11="gelb"),LEN(G11)<=60),"ja","nein")) | U11: =IF(T11<>"nein","",IF(J11<>"ja","keine Freigabe",IF(M11="","nicht an der Quelle bestätigt",IF(K11="rot","Ampel rot — nicht öffentlich",IF(OR(K11="ohne Ampel",K11="nicht in Freigaben"),"Ampel fehlt",IF(LEN(G11)>60,"Kurzinfo zu lang",""))))))
C12: =IF(B12="","",CHOOSE(WEEKDAY(B12,2),"Mo","Di","Mi","Do","Fr","Sa","So")) | H12: =IF(G12="","",LEN(G12)) | J12: =IF(I12="","",IF(COUNTIFS(Freigaben!$B$5:$B$58,I12,Freigaben!$M$5:$M$58,"freigegeben")>0,"ja","nein")) | K12: =IF(I12="","",IFERROR(IF(INDEX(Freigaben!$N$5:$N$58,MATCH(I12,Freigaben!$B$5:$B$58,0))="","ohne Ampel",INDEX(Freigaben!$N$5:$N$58,MATCH(I12,Freigaben!$B$5:$B$58,0))),"nicht in Freigaben")) | T12: =IF(F12="","",IF(AND(J12="ja",M12<>"",OR(K12="grün",K12="gelb"),LEN(G12)<=60),"ja","nein")) | U12: =IF(T12<>"nein","",IF(J12<>"ja","keine Freigabe",IF(M12="","nicht an der Quelle bestätigt",IF(K12="rot","Ampel rot — nicht öffentlich",IF(OR(K12="ohne Ampel",K12="nicht in Freigaben"),"Ampel fehlt",IF(LEN(G12)>60,"Kurzinfo zu lang",""))))))
C13: =IF(B13="","",CHOOSE(WEEKDAY(B13,2),"Mo","Di","Mi","Do","Fr","Sa","So")) | H13: =IF(G13="","",LEN(G13)) | J13: =IF(I13="","",IF(COUNTIFS(Freigaben!$B$5:$B$58,I13,Freigaben!$M$5:$M$58,"freigegeben")>0,"ja","nein")) | K13: =IF(I13="","",IFERROR(IF(INDEX(Freigaben!$N$5:$N$58,MATCH(I13,Freigaben!$B$5:$B$58,0))="","ohne Ampel",INDEX(Freigaben!$N$5:$N$58,MATCH(I13,Freigaben!$B$5:$B$58,0))),"nicht in Freigaben")) | T13: =IF(F13="","",IF(AND(J13="ja",M13<>"",OR(K13="grün",K13="gelb"),LEN(G13)<=60),"ja","nein")) | U13: =IF(T13<>"nein","",IF(J13<>"ja","keine Freigabe",IF(M13="","nicht an der Quelle bestätigt",IF(K13="rot","Ampel rot — nicht öffentlich",IF(OR(K13="ohne Ampel",K13="nicht in Freigaben"),"Ampel fehlt",IF(LEN(G13)>60,"Kurzinfo zu lang",""))))))
C14: =IF(B14="","",CHOOSE(WEEKDAY(B14,2),"Mo","Di","Mi","Do","Fr","Sa","So")) | H14: =IF(G14="","",LEN(G14)) | J14: =IF(I14="","",IF(COUNTIFS(Freigaben!$B$5:$B$58,I14,Freigaben!$M$5:$M$58,"freigegeben")>0,"ja","nein")) | K14: =IF(I14="","",IFERROR(IF(INDEX(Freigaben!$N$5:$N$58,MATCH(I14,Freigaben!$B$5:$B$58,0))="","ohne Ampel",INDEX(Freigaben!$N$5:$N$58,MATCH(I14,Freigaben!$B$5:$B$58,0))),"nicht in Freigaben")) | T14: =IF(F14="","",IF(AND(J14="ja",M14<>"",OR(K14="grün",K14="gelb"),LEN(G14)<=60),"ja","nein")) | U14: =IF(T14<>"nein","",IF(J14<>"ja","keine Freigabe",IF(M14="","nicht an der Quelle bestätigt",IF(K14="rot","Ampel rot — nicht öffentlich",IF(OR(K14="ohne Ampel",K14="nicht in Freigaben"),"Ampel fehlt",IF(LEN(G14)>60,"Kurzinfo zu lang",""))))))
C15: =IF(B15="","",CHOOSE(WEEKDAY(B15,2),"Mo","Di","Mi","Do","Fr","Sa","So")) | H15: =IF(G15="","",LEN(G15)) | J15: =IF(I15="","",IF(COUNTIFS(Freigaben!$B$5:$B$58,I15,Freigaben!$M$5:$M$58,"freigegeben")>0,"ja","nein")) | K15: =IF(I15="","",IFERROR(IF(INDEX(Freigaben!$N$5:$N$58,MATCH(I15,Freigaben!$B$5:$B$58,0))="","ohne Ampel",INDEX(Freigaben!$N$5:$N$58,MATCH(I15,Freigaben!$B$5:$B$58,0))),"nicht in Freigaben")) | T15: =IF(F15="","",IF(AND(J15="ja",M15<>"",OR(K15="grün",K15="gelb"),LEN(G15)<=60),"ja","nein")) | U15: =IF(T15<>"nein","",IF(J15<>"ja","keine Freigabe",IF(M15="","nicht an der Quelle bestätigt",IF(K15="rot","Ampel rot — nicht öffentlich",IF(OR(K15="ohne Ampel",K15="nicht in Freigaben"),"Ampel fehlt",IF(LEN(G15)>60,"Kurzinfo zu lang",""))))))
C16: =IF(B16="","",CHOOSE(WEEKDAY(B16,2),"Mo","Di","Mi","Do","Fr","Sa","So")) | H16: =IF(G16="","",LEN(G16)) | J16: =IF(I16="","",IF(COUNTIFS(Freigaben!$B$5:$B$58,I16,Freigaben!$M$5:$M$58,"freigegeben")>0,"ja","nein")) | K16: =IF(I16="","",IFERROR(IF(INDEX(Freigaben!$N$5:$N$58,MATCH(I16,Freigaben!$B$5:$B$58,0))="","ohne Ampel",INDEX(Freigaben!$N$5:$N$58,MATCH(I16,Freigaben!$B$5:$B$58,0))),"nicht in Freigaben")) | T16: =IF(F16="","",IF(AND(J16="ja",M16<>"",OR(K16="grün",K16="gelb"),LEN(G16)<=60),"ja","nein")) | U16: =IF(T16<>"nein","",IF(J16<>"ja","keine Freigabe",IF(M16="","nicht an der Quelle bestätigt",IF(K16="rot","Ampel rot — nicht öffentlich",IF(OR(K16="ohne Ampel",K16="nicht in Freigaben"),"Ampel fehlt",IF(LEN(G16)>60,"Kurzinfo zu lang",""))))))
C17: =IF(B17="","",CHOOSE(WEEKDAY(B17,2),"Mo","Di","Mi","Do","Fr","Sa","So")) | H17: =IF(G17="","",LEN(G17)) | J17: =IF(I17="","",IF(COUNTIFS(Freigaben!$B$5:$B$58,I17,Freigaben!$M$5:$M$58,"freigegeben")>0,"ja","nein")) | K17: =IF(I17="","",IFERROR(IF(INDEX(Freigaben!$N$5:$N$58,MATCH(I17,Freigaben!$B$5:$B$58,0))="","ohne Ampel",INDEX(Freigaben!$N$5:$N$58,MATCH(I17,Freigaben!$B$5:$B$58,0))),"nicht in Freigaben")) | T17: =IF(F17="","",IF(AND(J17="ja",M17<>"",OR(K17="grün",K17="gelb"),LEN(G17)<=60),"ja","nein")) | U17: =IF(T17<>"nein","",IF(J17<>"ja","keine Freigabe",IF(M17="","nicht an der Quelle bestätigt",IF(K17="rot","Ampel rot — nicht öffentlich",IF(OR(K17="ohne Ampel",K17="nicht in Freigaben"),"Ampel fehlt",IF(LEN(G17)>60,"Kurzinfo zu lang",""))))))
... C204: =IF(B204="","",CHOOSE(WEEKDAY(B204,2),"Mo","Di","Mi","Do","Fr","Sa","So")) | H204: =IF(G204="","",LEN(G204)) | J204: =IF(I204="","",IF(COUNTIFS(Freigaben!$B$5:$B$58,I204,Freigaben!$M$5:$M$58,"freigegeben")>0,"ja","nein")) | K204: =IF(I204="","",IFERROR(IF(INDEX(Freigaben!$N$5:$N$58,MATCH(I204,Freigaben!$B$5:$B$58,0))="","ohne Ampel",INDEX(Freigaben!$N$5:$N$58,MATCH(I204,Freigaben!$B$5:$B$58,0))),"nicht in Freigaben")) | T204: =IF(F204="","",IF(AND(J204="ja",M204<>"",OR(K204="grün",K204="gelb"),LEN(G204)<=60),"ja","nein")) | U204: =IF(T204<>"nein","",IF(J204<>"ja","keine Freigabe",IF(M204="","nicht an der Quelle bestätigt",IF(K204="rot","Ampel rot — nicht öffentlich",IF(OR(K204="ohne Ampel",K204="nicht in Freigaben"),"Ampel fehlt",IF(LEN(G204)>60,"Kurzinfo zu lang",""))))))

Sheet Aufwand
A1: Aufwand — hält das Abnahmekriterium?
A2: ENTWURF · Aufgabe A-16 · erstellt 15.09.2026 · Konzept: terminservice-konzept.md (gleicher Ordner) · Nichts wird ohne Freigabe beider Gründer veröffentlicht.
A3: Abnahmekriterium A-16: Gründer 2 produziert in unter drei Stunden je Woche (unter 180 Minuten). Planwerte in Blau, nach Woche 3 mit den Ist-Minuten aus „Messung“ vergleichen.
D4: A · Story-Serie | E4: B · Wochenmail | F4: C · beides, vollständig | G4: C · beides, schlank | H4: C · beides, Mail als Modul
A5: Schritt | B5: Tag | C5: Was | D5: A | E5: B | F5: CV | G5: CS | H5: CM
A6: S1 | B6: Mo | C6: termine@ sichten: Neue Veranstalter-Mails lesen, Termine ins Blatt „Termine“ eintragen, erledigte Mails markieren | D6: 15 | E6: 15 | F6: 15 | G6: 15 | H6: 15
A7: S2 | B7: Di | C7: Terminkanäle durchgehen: Öffentliche Kanäle der freigegebenen Veranstalter prüfen; Sammelkalender nur als Hinweis; Neue ohne Freigabe nur ins Blatt „Freigaben“ | D7: 20 | E7: 20 | F7: 20 | G7: 20 | H7: 20
A8: S3 | B8: Mi | C8: Prüfen, auswählen, texten: Jede Angabe an der Veranstalterquelle bestätigen, Ampel prüfen, höchstens zehn Termine wählen, Kurzinfos in eigenen Worten | D8: 25 | E8: 25 | F8: 25 | G8: 25 | H8: 25
A9: S4 | B9: Do | C9: Wochenset gestalten: Titelframe, Terminframes und Schlussframe aus der Vorlage befüllen | D9: 35 | E9: 0 | F9: 35 | G9: 35 | H9: 35
A10: S5 | B10: Do | C10: Tagesframes vorplanen: Je einen Frame „Heute in Köln“ für Freitag bis Mittwoch anlegen und zeitlich planen | D10: 15 | E10: 0 | F10: 15 | G10: 0 | H10: 0
A11: S6 | B11: Do | C11: Live veröffentlichen: Wochenset posten, Erwähnungen und Frage-Sticker setzen, Highlight „Diese Woche“ austauschen | D11: 10 | E11: 0 | F11: 10 | G11: 10 | H11: 10
A12: S7 | B12: tägl. | C12: Änderungen prüfen: Absagen der Tagesauswahl beim Veranstalter prüfen, bei Bedarf Korrektur-Frame (6 × 3 Min.; schlank: nur Fr–So, 3 × 3 Min.) | D12: 18 | E12: 0 | F12: 18 | G12: 9 | H12: 9
A13: S8 | B13: Do | C13: Mail schreiben: Mail aus dem Gerüst befüllen; bei „beides“ die Kurzinfos der Stories übernehmen | D13: 0 | E13: 25 | F13: 15 | G13: 15 | H13: 15
A14: S9 | B14: Do | C14: Mail prüfen und planen: Testversand an die eigene Adresse, Mobil- und Dunkelansicht, Links, Versand für Donnerstag planen | D14: 0 | E14: 15 | F14: 10 | G14: 10 | H14: 0
A15: S10 | B15: lfd. | C15: Antworten: Story-Antworten und Antwort-Mails beantworten (bei „Modul“ nur Stories — die Mail gehört zu A-17) | D15: 15 | E15: 10 | F15: 20 | G15: 20 | H15: 15
A16: S11 | B16: Mo | C16: Messen: Kennzahlen der Vorwoche und Ist-Minuten ins Blatt „Messung“ eintragen | D16: 10 | E16: 5 | F16: 15 | G16: 15 | H16: 10
C17: Summe je Woche (Minuten) | D17: =SUM(D6:D16) -> 163 | E17: =SUM(E6:E16) -> 115 | F17: =SUM(F6:F16) -> 198 | G17: =SUM(G6:G16) -> 174 | H17: =SUM(H6:H16) -> 154
C18: in Stunden und Minuten | D18: =D17/1440 -> 0.11319444 | E18: =E17/1440 -> 0.079861111 | F18: =F17/1440 -> 0.1375 | G18: =G17/1440 -> 0.12083333 | H18: =H17/1440 -> 0.10694444
C19: Abnahme: unter 180 Minuten | D19: =IF(D17<180,"erfüllt","verfehlt") -> erfüllt | E19: =IF(E17<180,"erfüllt","verfehlt") -> erfüllt | F19: =IF(F17<180,"erfüllt","verfehlt") -> verfehlt | G19: =IF(G17<180,"erfüllt","verfehlt") -> erfüllt | H19: =IF(H17<180,"erfüllt","verfehlt") -> erfüllt
C20: Puffer bis 180 Minuten | D20: =180-D17 -> 17 | E20: =180-E17 -> 65 | F20: =180-F17 -> -18 | G20: =180-G17 -> 6 | H20: =180-H17 -> 26
A22: Wahl | B22: Option | C22: A | D22: gewählte Option (Kürzel aus Zeile 5) — Entscheidung Nr. 52, bis dahin Vorschlag A
C23: Planwert der gewählten Option (Minuten) | D23: =INDEX(D17:H17,1,MATCH(C22,D5:H5,0)) -> 163
C24: Ist-Minuten im Schnitt (aus „Messung“, sobald eingetragen) | D24: =IF(COUNT(Messung!T6:T18)=0,"noch keine",AVERAGE(Messung!T6:T18)) -> noch keine
C25: Ist unter 180 Minuten? | D25: =IF(COUNT(Messung!T6:T18)=0,"—",IF(D24<180,"erfüllt","verfehlt")) -> —
C27: Variante A+ — Wochenübersicht zusätzlich als Carousel, damit „Gespeichert“ messbar wird (+20 Min.) | D27: 20
C28: A+ voll gezählt (Minuten) | D28: =D17+D27 -> 183
C29: A+ voll gezählt unter 180 Minuten? | D29: =IF(D28<180,"erfüllt","verfehlt") -> verfehlt
C30: A+, wenn der Carousel einen der sieben Wochenbeiträge aus A-05 ersetzt (Zeit aus dem A-05-Budget) | D30: =D17 -> 163
C32: Vier-Augen-Freigabe durch den anderen Gründer (nicht im Budget von Gründer 2) | D32: 10
A34: Wenn es länger dauert
C35: 1. Tägliche Frames auf Freitag bis Sonntag beschränken (Option schlank).
C36: 2. Höchstens sechs statt zehn Termine je Ausgabe.
C37: 3. Sammelkalender nur noch alle zwei Wochen durchsehen.
C38: 4. Mail auf das Modul in der Wochenmail aus A-17 umstellen (nur nach Nr. 53).
C39: Nie kürzen: die Bestätigung an der Quelle, die Freigabeprüfung, die Vier-Augen-Freigabe.

Sheet Messung
A1: Messung — jede Woche, ohne Tracking
A2: ENTWURF · Aufgabe A-16 · erstellt 15.09.2026 · Konzept: terminservice-konzept.md (gleicher Ordner) · Nichts wird ohne Freigabe beider Gründer veröffentlicht.
A3: Erste Ausgabe (Donnerstag): | D3: 47031 | E3: Annahme für Szenario „T0 Anfang Juli 2028“ (Nr. 45 offen). Szenario „T0 September 2028“: 07.12.2028.
A5: Woche | B5: Ausgabe am | C5: Termine veröffentlicht | D5: Freigegebene Veranstalter (Stand) | E5: Story: Aufrufe Titelframe | F5: Story: Aufrufe Schlussframe | G5: Durchhaltequote | H5: Story: Antworten | I5: Story: Geteilt | J5: Story: Sticker-Tipps | K5: Profilaufrufe | L5: Neue Follower | M5: Carousel: Gespeichert | N5: Carousel: Geteilt | O5: Mail: Empfänger | P5: Mail: Antworten | Q5: Mail: Anmeldungen über Weiterleitung | R5: Mail: Abmeldungen | S5: termine@: neue Einreichungen | T5: Ist-Minuten Gründer 2 | U5: Notiz
A6: 1 | B6: =IF($D$3="","",$D$3+7*(A6-1)) -> 47031 | C6: =COUNTIFS(Termine!$A$6:$A$204,A6,Termine!$S$6:$S$204,"veröffentlicht") -> 0 | G6: =IF(OR(E6="",F6="",N(E6)=0),"",F6/E6)
A7: 2 | B7: =IF($D$3="","",$D$3+7*(A7-1)) -> 47038 | C7: =COUNTIFS(Termine!$A$6:$A$204,A7,Termine!$S$6:$S$204,"veröffentlicht") -> 0 | G7: =IF(OR(E7="",F7="",N(E7)=0),"",F7/E7)
A8: 3 | B8: =IF($D$3="","",$D$3+7*(A8-1)) -> 47045 | C8: =COUNTIFS(Termine!$A$6:$A$204,A8,Termine!$S$6:$S$204,"veröffentlicht") -> 0 | G8: =IF(OR(E8="",F8="",N(E8)=0),"",F8/E8)
A9: 4 | B9: =IF($D$3="","",$D$3+7*(A9-1)) -> 47052 | C9: =COUNTIFS(Termine!$A$6:$A$204,A9,Termine!$S$6:$S$204,"veröffentlicht") -> 0 | G9: =IF(OR(E9="",F9="",N(E9)=0),"",F9/E9)
A10: 5 | B10: =IF($D$3="","",$D$3+7*(A10-1)) -> 47059 | C10: =COUNTIFS(Termine!$A$6:$A$204,A10,Termine!$S$6:$S$204,"veröffentlicht") -> 0 | G10: =IF(OR(E10="",F10="",N(E10)=0),"",F10/E10)
A11: 6 | B11: =IF($D$3="","",$D$3+7*(A11-1)) -> 47066 | C11: =COUNTIFS(Termine!$A$6:$A$204,A11,Termine!$S$6:$S$204,"veröffentlicht") -> 0 | G11: =IF(OR(E11="",F11="",N(E11)=0),"",F11/E11)
A12: 7 | B12: =IF($D$3="","",$D$3+7*(A12-1)) -> 47073 | C12: =COUNTIFS(Termine!$A$6:$A$204,A12,Termine!$S$6:$S$204,"veröffentlicht") -> 0 | G12: =IF(OR(E12="",F12="",N(E12)=0),"",F12/E12)
A13: 8 | B13: =IF($D$3="","",$D$3+7*(A13-1)) -> 47080 | C13: =COUNTIFS(Termine!$A$6:$A$204,A13,Termine!$S$6:$S$204,"veröffentlicht") -> 0 | G13: =IF(OR(E13="",F13="",N(E13)=0),"",F13/E13)
A14: 9 | B14: =IF($D$3="","",$D$3+7*(A14-1)) -> 47087 | C14: =COUNTIFS(Termine!$A$6:$A$204,A14,Termine!$S$6:$S$204,"veröffentlicht") -> 0 | G14: =IF(OR(E14="",F14="",N(E14)=0),"",F14/E14)
A15: 10 | B15: =IF($D$3="","",$D$3+7*(A15-1)) -> 47094 | C15: =COUNTIFS(Termine!$A$6:$A$204,A15,Termine!$S$6:$S$204,"veröffentlicht") -> 0 | G15: =IF(OR(E15="",F15="",N(E15)=0),"",F15/E15)
A16: 11 | B16: =IF($D$3="","",$D$3+7*(A16-1)) -> 47101 | C16: =COUNTIFS(Termine!$A$6:$A$204,A16,Termine!$S$6:$S$204,"veröffentlicht") -> 0 | G16: =IF(OR(E16="",F16="",N(E16)=0),"",F16/E16)
A17: 12 | B17: =IF($D$3="","",$D$3+7*(A17-1)) -> 47108 | C17: =COUNTIFS(Termine!$A$6:$A$204,A17,Termine!$S$6:$S$204,"veröffentlicht") -> 0 | G17: =IF(OR(E17="",F17="",N(E17)=0),"",F17/E17)
A18: 13 | B18: =IF($D$3="","",$D$3+7*(A18-1)) -> 47115 | C18: =COUNTIFS(Termine!$A$6:$A$204,A18,Termine!$S$6:$S$204,"veröffentlicht") -> 0 | G18: =IF(OR(E18="",F18="",N(E18)=0),"",F18/E18)
A19: Summe / Schnitt | C19: =SUM(C6:C18) -> 0 | D19: =IF(COUNT(D6:D18)=0,"",INDEX(D6:D18,MATCH(9.99E+307,D6:D18))) | E19: =IF(COUNT(E6:E18)=0,"",AVERAGE(E6:E18)) | F19: =IF(COUNT(F6:F18)=0,"",AVERAGE(F6:F18)) | G19: =IF(COUNT(G6:G18)=0,"",AVERAGE(G6:G18)) | H19: =IF(COUNT(H6:H18)=0,"",SUM(H6:H18)) | I19: =IF(COUNT(I6:I18)=0,"",SUM(I6:I18)) | J19: =IF(COUNT(J6:J18)=0,"",SUM(J6:J18)) | K19: =IF(COUNT(K6:K18)=0,"",SUM(K6:K18)) | L19: =IF(COUNT(L6:L18)=0,"",SUM(L6:L18)) | M19: =IF(COUNT(M6:M18)=0,"",SUM(M6:M18)) | N19: =IF(COUNT(N6:N18)=0,"",SUM(N6:N18)) | O19: =IF(COUNT(O6:O18)=0,"",SUM(O6:O18)) | ... S19: =IF(COUNT(S6:S18)=0,"",SUM(S6:S18)) | T19: =IF(COUNT(T6:T18)=0,"",AVERAGE(T6:T18)) | U19: Zeile 19: Summen, außer Aufrufe, Quote und Minuten (Schnitt) und Freigaben (letzter Stand).
A21: Soll-Werte der Gründer — vor dem Start festlegen, nicht nachträglich
B22: Kennzahl | E22: Soll | F22: Ist | G22: Vergleich
B23: Aufrufe Titelframe im Schnitt | F23: =E19 | G23: =IF(E23="","kein Soll festgelegt",IF(F23="","noch kein Ist",IF(F23>=E23,"erreicht","nicht erreicht"))) -> kein Soll festgelegt
B24: Durchhaltequote im Schnitt | F24: =G19 | G24: =IF(E24="","kein Soll festgelegt",IF(F24="","noch kein Ist",IF(F24>=E24,"erreicht","nicht erreicht"))) -> kein Soll festgelegt
B25: Antworten auf Stories, Summe | F25: =H19 | G25: =IF(E25="","kein Soll festgelegt",IF(F25="","noch kein Ist",IF(F25>=E25,"erreicht","nicht erreicht"))) -> kein Soll festgelegt
B26: Geteilt (Stories), Summe | F26: =I19 | G26: =IF(E26="","kein Soll festgelegt",IF(F26="","noch kein Ist",IF(F26>=E26,"erreicht","nicht erreicht"))) -> kein Soll festgelegt
B27: Gespeichert (nur Variante A+), Summe | F27: =M19 | G27: =IF(E27="","kein Soll festgelegt",IF(F27="","noch kein Ist",IF(F27>=E27,"erreicht","nicht erreicht"))) -> kein Soll festgelegt
B28: Anmeldungen über Weiterleitung, Summe | F28: =Q19 | G28: =IF(E28="","kein Soll festgelegt",IF(F28="","noch kein Ist",IF(F28>=E28,"erreicht","nicht erreicht"))) -> kein Soll festgelegt
B29: Freigegebene Veranstalter, letzter Stand | F29: =D19 | G29: =IF(E29="","kein Soll festgelegt",IF(F29="","noch kein Ist",IF(F29>=E29,"erreicht","nicht erreicht"))) -> kein Soll festgelegt
B30: termine@-Einreichungen, Summe | F30: =S19 | G30: =IF(E30="","kein Soll festgelegt",IF(F30="","noch kein Ist",IF(F30>=E30,"erreicht","nicht erreicht"))) -> kein Soll festgelegt
B31: Ist-Minuten im Schnitt — Grenze aus der Abnahme | E31: 180 | F31: =T19 | G31: =IF(E31="","kein Soll festgelegt",IF(F31="","noch kein Ist",IF(F31<E31,"erreicht","nicht erreicht"))) -> noch kein Ist
A33: Nach Woche 13 — die Entscheidung treffen die Gründer
B34: Entscheidung (fortsetzen · Format ändern · einstellen)
B35: Datum
B36: Begründung in zwei Sätzen
B37: Beide Gründer einverstanden (ja/nein)
B39: Die Tabelle stellt gegenüber und empfiehlt nichts. Wer die Kölner Anmeldungen der Warteliste daneben legt, sieht einen Verlauf, keine Zurechnung — ohne Tracking lässt sich nicht sagen, wer über den Terminservice kam.

Sheet Kalender
A1: Kalender — 13 Ausgaben und Anlässe
A2: ENTWURF · Aufgabe A-16 · erstellt 15.09.2026 · Konzept: terminservice-konzept.md (gleicher Ordner) · Nichts wird ohne Freigabe beider Gründer veröffentlicht.
A3: Rechnet vom Startdatum im Blatt „Messung“ (D3). Eine Ausgabe deckt Donnerstag bis Mittwoch ab — auch die Wochentage, weil die Mittwochsfrage aus dem Playbook (Anlass 1) genau dort ansetzt.
A5: Ausgabe | B5: Donnerstag | C5: deckt bis | D5: Anlass in dieser Woche
A6: 1 | B6: =IF(Messung!$D$3="","",Messung!$D$3+7*(A6-1)) -> 47031 | C6: =IF(B6="","",B6+6) -> 47037 | D6: =IFERROR(INDEX($B$24:$B$29,MATCH(A6,$C$24:$C$29,0)),"")
A7: 2 | B7: =IF(Messung!$D$3="","",Messung!$D$3+7*(A7-1)) -> 47038 | C7: =IF(B7="","",B7+6) -> 47044 | D7: =IFERROR(INDEX($B$24:$B$29,MATCH(A7,$C$24:$C$29,0)),"")
A8: 3 | B8: =IF(Messung!$D$3="","",Messung!$D$3+7*(A8-1)) -> 47045 | C8: =IF(B8="","",B8+6) -> 47051 | D8: =IFERROR(INDEX($B$24:$B$29,MATCH(A8,$C$24:$C$29,0)),"")
A9: 4 | B9: =IF(Messung!$D$3="","",Messung!$D$3+7*(A9-1)) -> 47052 | C9: =IF(B9="","",B9+6) -> 47058 | D9: =IFERROR(INDEX($B$24:$B$29,MATCH(A9,$C$24:$C$29,0)),"")
A10: 5 | B10: =IF(Messung!$D$3="","",Messung!$D$3+7*(A10-1)) -> 47059 | C10: =IF(B10="","",B10+6) -> 47065 | D10: =IFERROR(INDEX($B$24:$B$29,MATCH(A10,$C$24:$C$29,0)),"")
A11: 6 | B11: =IF(Messung!$D$3="","",Messung!$D$3+7*(A11-1)) -> 47066 | C11: =IF(B11="","",B11+6) -> 47072 | D11: =IFERROR(INDEX($B$24:$B$29,MATCH(A11,$C$24:$C$29,0)),"") -> Sessionsauftakt Karneval (Samstag)
A12: 7 | B12: =IF(Messung!$D$3="","",Messung!$D$3+7*(A12-1)) -> 47073 | C12: =IF(B12="","",B12+6) -> 47079 | D12: =IFERROR(INDEX($B$24:$B$29,MATCH(A12,$C$24:$C$29,0)),"")
A13: 8 | B13: =IF(Messung!$D$3="","",Messung!$D$3+7*(A13-1)) -> 47080 | C13: =IF(B13="","",B13+6) -> 47086 | D13: =IFERROR(INDEX($B$24:$B$29,MATCH(A13,$C$24:$C$29,0)),"")
A14: 9 | B14: =IF(Messung!$D$3="","",Messung!$D$3+7*(A14-1)) -> 47087 | C14: =IF(B14="","",B14+6) -> 47093 | D14: =IFERROR(INDEX($B$24:$B$29,MATCH(A14,$C$24:$C$29,0)),"") -> Welt-Aids-Tag (Freitag)
A15: 10 | B15: =IF(Messung!$D$3="","",Messung!$D$3+7*(A15-1)) -> 47094 | C15: =IF(B15="","",B15+6) -> 47100 | D15: =IFERROR(INDEX($B$24:$B$29,MATCH(A15,$C$24:$C$29,0)),"")
A16: 11 | B16: =IF(Messung!$D$3="","",Messung!$D$3+7*(A16-1)) -> 47101 | C16: =IF(B16="","",B16+6) -> 47107 | D16: =IFERROR(INDEX($B$24:$B$29,MATCH(A16,$C$24:$C$29,0)),"")
A17: 12 | B17: =IF(Messung!$D$3="","",Messung!$D$3+7*(A17-1)) -> 47108 | C17: =IF(B17="","",B17+6) -> 47114 | D17: =IFERROR(INDEX($B$24:$B$29,MATCH(A17,$C$24:$C$29,0)),"") -> Heiligabend (Sonntag)
A18: 13 | B18: =IF(Messung!$D$3="","",Messung!$D$3+7*(A18-1)) -> 47115 | C18: =IF(B18="","",B18+6) -> 47121 | D18: =IFERROR(INDEX($B$24:$B$29,MATCH(A18,$C$24:$C$29,0)),"") -> Silvester (Sonntag)
D19: Zeigt je Ausgabe den ersten passenden Anlass. Alle Anlässe stehen unten.
A22: Anlässe
A23: Datum | B23: Anlass | C23: fällt in Ausgabe | D23: Regel
A24: 47068 | B24: Sessionsauftakt Karneval (Samstag) | C24: =IF(Messung!$D$3="","",IF(AND(A24>=Messung!$D$3,A24<Messung!$D$3+91),INT((A24-Messung!$D$3)/7)+1,"außerhalb")) -> 6 | D24: Nur Termine freigegebener Vereine und Orte; Sessionstermine laut Playbook-Anlass 5 schon ab Spätsommer sammeln
A25: 47088 | B25: Welt-Aids-Tag (Freitag) | C25: =IF(Messung!$D$3="","",IF(AND(A25>=Messung!$D$3,A25<Messung!$D$3+91),INT((A25-Messung!$D$3)/7)+1,"außerhalb")) -> 9 | D25: Nur mit freigegebenem Gesundheitspartner und echten Test- oder Beratungsterminen — sonst gar nicht (A-05)
A26: 47111 | B26: Heiligabend (Sonntag) | C26: =IF(Messung!$D$3="","",IF(AND(A26>=Messung!$D$3,A26<Messung!$D$3+91),INT((A26-Messung!$D$3)/7)+1,"außerhalb")) -> 12 | D26: Die Ausgabe dieser Woche deckt die Feiertage ab; Öffnungszeiten besonders streng an der Quelle prüfen
A27: 47118 | B27: Silvester (Sonntag) | C27: =IF(Messung!$D$3="","",IF(AND(A27>=Messung!$D$3,A27<Messung!$D$3+91),INT((A27-Messung!$D$3)/7)+1,"außerhalb")) -> 13 | D27: Eine gemeinsame Ausgabe „zwischen den Jahren“ statt zwei halber
A28: 47157 | B28: Weiberfastnacht (Donnerstag) | C28: =IF(Messung!$D$3="","",IF(AND(A28>=Messung!$D$3,A28<Messung!$D$3+91),INT((A28-Messung!$D$3)/7)+1,"außerhalb")) -> außerhalb | D28: Ausgabe erscheint am Mittwoch davor: An Weiberfastnacht beginnt in Köln der Straßenkarneval, am selben Morgen plant niemand mehr
A29: 47161 | B29: Rosenmontag | C29: =IF(Messung!$D$3="","",IF(AND(A29>=Messung!$D$3,A29<Messung!$D$3+91),INT((A29-Messung!$D$3)/7)+1,"außerhalb")) -> außerhalb | D29: Liegt in der Ausgabe vom Mittwoch davor
A31: Szenarien
A32: T0 Anfang Juli 2028: erste Ausgabe 05.10.2028, letzte 28.12.2028 (Roadmapmonat 4 bis 6)
A33: T0 September 2028: erste Ausgabe 07.12.2028, letzte 01.03.2029 (Roadmapmonat 4 bis 6)
A34: Die Weiberfastnacht-Regel: Fällt ein großer Szenetag auf den Donnerstag, erscheint die Ausgabe am Mittwoch davor.
