Workbook

Sheet Anleitung
A1: Finanzmodell Cruizy — Anleitung
A2: Aufgabe A-13 · erstellt 27.07.2026 · Rolle: Finanzmodellierer · Fenster V1 · Grundlage: Handbuch B, Teile II–V · fortgeschrieben 21.09.2026 (A-52: Beschlüsse vom 19. und 21.09.2026)
A4: DIESES MODELL RECHNET. ES ENTSCHEIDET NICHT. Jede Zahl darin ist eine Annahme mit Herkunft — nachlesbar auf dem Blatt „Herkunft & Widersprüche". Wer eine Annahme ändert, sieht die Wirkung sofort bis in die Kennzahlen. Genau dafür ist es gebaut.
A6: Farben
A7: BLAU = Stellhebel. Hier wird geändert. Alles andere rechnet sich daraus.
A8: GELB = von Menschen auszufüllen. Ist-Werte, Entscheidungen, bestätigte Angaben.
A9: WEISS mit Formel = Ergebnis. Nicht überschreiben, sonst bricht die Kette.
A10: BERNSTEIN = Hinweis oder Widerspruch, der bewusst stehen bleibt.
A12: Die Blätter, in der Reihenfolge, in der man sie liest
A13: Blatt | B13: Was darin steht | C13: Wer es anfasst
A14: Annahmen | B14: Sämtliche Stellhebel: Nutzerentwicklung, Monetarisierung mit der Erlöskette je Zahler (2a), weitere Erlösquellen, Kostenstaffel, JMStV-Schalter, Einmalkosten, CSD-Auftritte, laufende Kosten aus Beschlüssen (7a), Kapitalbedarf und Lebenshaltung.
A15: Pessimistisch / Realistisch / Optimistisch | B15: 36 Monatsspalten je Szenario: Nutzer, Zahler, fünf Erlösquellen, Kostenblöcke, Ergebnis, kumulierte Liquidität; nachrichtlich Krankenversicherung und Lebenshaltung. Reine Formeln.
A16: Kennzahlen | B16: Tiefpunkt, Break-even, Kapitalbedarf je Szenario und der Gesamtbedarf mit Lebenshaltung (Nr. 38). Darunter der Abgleich gegen Handbuch B, die vier Prüfwege, die Empfindlichkeit und wie viele Zahler es braucht.
A17: Finanzierungswege | B17: Sechs durchgerechnete Wege, wie die Lücke geschlossen werden könnte, samt Wirkung auf Verwässerung, persönliches Risiko und Handlungsfreiheit.
A18: Ist-Werte | B18: Leer. Ab dem ersten realen Monat werden hier die tatsächlichen Zahlen eingetragen; das Blatt vergleicht automatisch mit dem Plan.
A19: Herkunft & Widersprüche | B19: Für jede Annahme die Quelle — und die fünf Stellen, an denen Handbuch B sich selbst widerspricht. Seit A-52 dazu die Liste aller Änderungen mit ihrer Wirkung.
A21: Was dieses Modell bewusst nicht tut
A22: Es zahlt in keinem Szenario ein Gründergehalt. Handbuch B tut das im optimistischen Fall ab Monat 16 — hier nicht, weil ein Gehalt eine Entscheidung ist und keine Rechengröße. Wer es einplanen will, trägt es als eigene Kostenzeile ein und sieht sofort, was es kostet. Die Lebenshaltung beider Gründer rechnet es seit A-52 mit — nicht als Gehalt, sondern als privaten Bedarf neben der Firma (Blatt „Kennzahlen“, Gesamtbedarf). Es empfiehlt keinen Finanzierungsweg. Das Blatt „Finanzierungswege" stellt sechs Wege nebeneinander und benennt bei jedem, was er mit den Gründern macht — nicht nur, was er einbringt. Die Auswahl ist eine Lebensentscheidung und keine Rechenaufgabe. Es behauptet keine Genauigkeit, die es nicht hat. Der Start liegt frühestens im Sommer 2028; geplant wird ein Jahr später (Nr. 45). Bis dahin ändern sich Preise, Anbieter und Recht. Der Wert dieses Modells liegt nicht in den Zahlen, sondern darin, dass die Größe sichtbar wird, auf die es ankommt.

Sheet Annahmen
A1: Annahmen — alle Stellhebel an einem Ort
A2: Blaue Felder ändern. Alles Weitere rechnet sich daraus. Spalte F nennt die Herkunft jeder Zahl. Fortgeschrieben am 21.09.2026 (A-52): neu die Abschnitte 2a und 7a, geändert 3, 6, 7 und 8.
A4: 1 · Nutzerentwicklung
A5: Größe | B5: Pessimistisch | C5: Realistisch | D5: Optimistisch | F5: Herkunft
A6: MAU Ende Jahr 1 | B6: 4000 | C6: 7500 | D6: 14000 | F6: Handbuch B, Szenarienvergleich
A7: MAU Ende Jahr 2 | B7: 14000 | C7: 24000 | D7: 60000 | F7: Handbuch B, Szenarienvergleich
A8: MAU Ende Jahr 3 | B8: 30000 | C8: 62000 | D8: 150000 | F8: Handbuch B, Szenarienvergleich
A9: Startmonat (erster Monat mit Nutzern) | B9: 2 | C9: 2 | D9: 2 | F9: KALIBRIERT auf die Jahresmittel aus Handbuch B. Entspricht einer geschlossenen Erprobung ab Monat 2.
A10: Rampenexponent Jahr 1 | B10: 1.2 | C10: 1.38 | D10: 1.34 | F10: KALIBRIERT. Wert über 1 = langsamer Start, beschleunigend. Unter 1 = schneller Start, abflachend.
A11: Rampenexponent Jahr 2–3 | B11: 1.34 | C11: 1.28 | D11: 1.26 | F11: KALIBRIERT auf die Jahresmittel aus Handbuch B.
A12: Städte Ende Jahr 1 | B12: 1 | C12: 1 | D12: 1 | F12: Handbuch B: Start in Köln, Dichte vor Fläche
A13: Städte Ende Jahr 2 | B13: 2 | C13: 2 | D13: 3 | F13: abgeleitet aus „Städte Ende Jahr 3" in Handbuch B
A14: Städte Ende Jahr 3 | B14: 2 | C14: 4 | D14: 6 | F14: Handbuch B, Szenarienvergleich
A15: Monatliche Nutzerabwanderung | B15: 0.1 | C15: 0.08 | D15: 0.07 | F15: ANNAHME. Gegenstück zur 30-Tage-Wiederkehr (15/24/30 %) aus Handbuch B. Bestimmt die Zahl der Neuregistrierungen und damit die Prüfkosten.
A16: Rückkehrerquote — Anteil der Abwanderer, der zurückkommt | B16: 0.3 | C16: 0.3 | D16: 0.3 | F16: ANNAHME. Entscheidend für die Prüfkosten: Wer zurückkommt, ist nach dem AVS-Raster der KJM BEREITS identifiziert und muss sich nur noch authentifizieren. Nur echte Neuzugänge kosten Geld.
A17: 30-Tage-Wiederkehr (nachrichtlich) | B17: 0.15 | C17: 0.24 | D17: 0.3 | F17: Handbuch B, Szenarienvergleich — hier nur zur Einordnung, nicht rechenwirksam
A18: Eintrittswahrscheinlichkeit (Schätzung) | B18: 0.4 | C18: 0.35 | D18: 0.1 | F18: Handbuch B. Restliche 15 %: Abbruch vor Monat 24.
A20: 2 · Monetarisierung
A21: Größe | B21: Pessimistisch | C21: Realistisch | D21: Optimistisch | F21: Herkunft
A22: Monetarisierungsstart (Monat) | B22: 18 | C22: 14 | D22: 11 | F22: Handbuch B, Szenarienvergleich
A23: Zielkonversion Jahr 3 | B23: 0.022 | C23: 0.036 | D23: 0.042 | F23: Handbuch B, Szenarienvergleich
A24: Anfangsanteil der Zielkonversion | B24: 0.05 | C24: 0.48 | D24: 0.52 | F24: KALIBRIERT auf die Zahler-Jahresmittel aus Handbuch B (Jahre 2 und 3)
A25: Rampendauer bis Zielkonversion (Monate) | B25: 3 | C25: 22 | D25: 22 | F25: KALIBRIERT
A26: Nettoerlös je Zahler und Monat | B26: =$B$51 -> 7.5593776 | C26: =$B$51 -> 7.5593776 | D26: =$B$51 -> 7.5593776 | F26: Rechnet sich seit A-52 aus der Erlöskette in Abschnitt 2a (Zeile 51) — vorher fest 7,38 € aus Handbuch B. Mit den Werten aus Handbuch B ergibt die Kette dieselben 7,38 € (Probe in Zeile 52).
A28: 2a · Erlöskette je Zahler — zwei Abostufen, Web und Store (Nr. 48, 50, 67 · A-51, A-53)
A29: WAS HIER NEU IST: Bis zum 21.09.2026 stand in Zeile 26 eine feste Zahl aus Handbuch B (7,38 €). Jetzt rechnet sie sich aus Preisen, Laufzeiten, Stufenanteil und Zahlungsweg. Eingeflossen sind drei Beschlüsse und zwei Recherchen: zwei Abostufen plus Unterstützerbeitrag (Nr. 67), Inkognito und Travel im Abo (Nr. 48), Jahresabo vorausgewählt (Nr. 50), die Web-Fassung zuerst und vollständig (A-51) und die tatsächliche Gebühr eines europäischen Zahlungsdienstes statt pauschal 4 Prozent (A-53). Mit den Werten aus Handbuch B ergibt die Kette dieselben 7,38 € — die Probe steht in Zeile 52.
A30: Laufzeit | B30: PLUS, brutto | C30: PRO, brutto | D30: Anteil der Käufe | E30: Monate | F30: Herkunft
A31: 1 Monat | B31: 9 | C31: 17 | D31: 0.45 | E31: 1 | F31: Handbuch B, Preisliste und „Abwanderung nach Laufzeit“: Bruttopreise und Anteil der Käufe je Laufzeit.
A32: 3 Monate | B32: 23 | C32: 43 | D32: 0.2 | E32: 3 | F32: Handbuch B · Nachlass 15 %
A33: 6 Monate | B33: 40 | C33: 76 | D33: 0.15 | E33: 6 | F33: Handbuch B · Nachlass 26 %
A34: 12 Monate | B34: 70 | C34: 132 | D34: 0.2 | E34: 12 | F34: Handbuch B · Nachlass 35 %. Nr. 50: Das Jahresabo ist vorausgewählt, alle Laufzeiten stehen gleich deutlich da — Handbuch B setzt die Vorauswahl bei diesen Anteilen bereits voraus.
A35: Größe | B35: Wert | F35: Herkunft
A36: Anteil PRO an den Zahlern | B36: 0.3 | F36: Handbuch B: 70 % PLUS, 30 % PRO. ENTSCHIEDEN am 26.09.2026 (Nr. 67, Teil 3) nach Nr. 48 und 67: PLUS = Komfort und Inkognito, PRO = alles aus PLUS und dazu Travel — umsehen und schreiben in einer anderen Region (Nr. 77), die Reiseankündigung nur, wenn Nr. 85 so entschieden wird. Ob dann noch 30 % die teurere Stufe wählen, ist die unsicherste Zahl dieses Blocks — Wirkung in der Tabelle ab Zeile 54. — NACHGERECHNET 26.09.2026: 20 % statt 30 % kosten 4.673 € Firmenbedarf und 9.873 € Gesamtbedarf, Break-even Monat 30; 15 % kosten 7.558 € bzw. 15.358 €, Break-even Monat 31. Der PRO-Anteil ist ab dem Monetarisierungsstart beobachtete Kennzahl; zwei Monate unter 20 % lösen eine Neubewertung des Zuschnitts aus (nicht eine Preissenkung).
A37: Umsatzsteuer | B37: 0.19 | F37: Handbuch B: Die Kleinunternehmerregelung greift bei einer GmbH nicht. Österreich 20 %, Schweiz 8,1 % (Skalierungs-Playbook) — für eine Auslandsstadt hier ändern.
A38: Provision der Stores | B38: 0.15 | F38: Handbuch B: 15 % mit dem Small-Business-Programm (muss beantragt werden), sonst 30 %. Sonderbedingungen in der EU nach dem Digital Markets Act sind nicht eingerechnet.
A39: Web-Zahlungsdienst, prozentualer Teil | B39: 0.018 | F39: A-53: Mollie (Amsterdam, lizenziert bei der niederländischen Zentralbank), 1,80 % + 0,25 € je Zahlung mit EWR-Karte, keine Monatsgebühr — abgerufen 20.09.2026. Welcher Dienst es wird, ist noch offen (eu-alternativen-stack.md, Punkt 6).
A40: Web-Zahlungsdienst, fester Teil je Zahlung | B40: 0.25 | F40: A-53, wie oben
A41: Anteil der Zahlungen über das Web | B41: 0.6 | F41: ANNAHME A-52. Handbuch B: 40 %. Höher angesetzt, weil die Web-Fassung zuerst und vollständig erscheint (A-51), Codes nur auf der Webseite eingelöst werden (Nr. 60) und Apple Käufe über das Web in der App anerkennt, sofern sie dort auch als In-App-Kauf angeboten werden (Richtlinie 3.1.3(b), geprüft 21.09.2026). Handbuch B nennt die Verschiebung zum Web ausdrücklich als Hebel.
A42: Ergebnis der Kette | B42: je Zahler und Monat | F42: Probe und Herkunft
A43: Gemischter Monatswert PLUS | B43: =SUMPRODUCT($D$31:$D$34,$B$31:$B$34/$E$31:$E$34) -> 7.75 | F43: über alle Laufzeiten gewichtet
...

Sheet Pessimistisch
A1: Szenario A — Pessimistisch
A2: 36 Monate ab T0 — dem Start in der CSD-Saison; geplant wird ein Jahr nach dem Bestfall Sommer 2028 (Nr. 45). Alles rechnet sich aus dem Blatt „Annahmen“. Kein Gründergehalt in keinem Monat.
A4: Position | B4: M1 | C4: M2 | D4: M3 | E4: M4 | F4: M5 | G4: M6 | H4: M7 | I4: M8 | J4: M9 | K4: M10 | L4: M11 | M4: M12 | N4: M13 | O4: M14 | P4: M15 | Q4: M16 | R4: M17 | S4: M18 | T4: M19 | U4: M20 | V4: M21 | W4: M22 | X4: M23 | Y4: M24 | Z4: M25 | AA4: M26 | AB4: M27 | AC4: M28 | AD4: M29 | AE4: M30 | AF4: M31 | AG4: M32 | AH4: M33 | AI4: M34 | AJ4: M35 | AK4: M36
A5: Monat | B5: 1 | C5: 2 | D5: 3 | E5: 4 | F5: 5 | G5: 6 | H5: 7 | I5: 8 | J5: 9 | K5: 10 | L5: 11 | M5: 12 | N5: 13 | O5: 14 | P5: 15 | Q5: 16 | R5: 17 | S5: 18 | T5: 19 | U5: 20 | V5: 21 | W5: 22 | X5: 23 | Y5: 24 | Z5: 25 | AA5: 26 | AB5: 27 | AC5: 28 | AD5: 29 | AE5: 30 | AF5: 31 | AG5: 32 | AH5: 33 | AI5: 34 | AJ5: 35 | AK5: 36
A6: Jahr | B6: =ROUNDUP(B5/12,0) -> 1 | C6: =ROUNDUP(C5/12,0) -> 1 | D6: =ROUNDUP(D5/12,0) -> 1 | E6: =ROUNDUP(E5/12,0) -> 1 | F6: =ROUNDUP(F5/12,0) -> 1 | G6: =ROUNDUP(G5/12,0) -> 1 | H6: =ROUNDUP(H5/12,0) -> 1 | I6: =ROUNDUP(I5/12,0) -> 1 | ... AK6: =ROUNDUP(AK5/12,0) -> 3
A7: Aktive Nutzer im Monat (MAU) | B7: =IF(B5<Annahmen!$B$9,0,IF(B5<=12,Annahmen!$B$6*((B5-Annahmen!$B$9+1)/(12-Annahmen!$B$9+1))^Annahmen!$B$10,IF(B5<=24,Annahmen!$B$6+(Annahmen!$B$7-Annahmen!$B$6)*((B5-12)/12)^Annahmen!$B$11,Annahmen!$B$7+(Annahmen!$B$8-Annahmen!$B$7)*((B5-24)/12)^Annahmen!$B$11))) -> 0 | C7: =IF(C5<Annahmen!$B$9,0,IF(C5<=12,Annahmen!$B$6*((C5-Annahmen!$B$9+1)/(12-Annahmen!$B$9+1))^Annahmen!$B$10,IF(C5<=24,Annahmen!$B$6+(Annahmen!$B$7-Annahmen!$B$6)*((C5-12)/12)^Annahmen!$B$11,Annahmen!$B$7+(Annahmen!$B$8-Annahmen!$B$7)*((C5-24)/12)^Annahmen!$B$11))) -> 225.10688 | D7: =IF(D5<Annahmen!$B$9,0,IF(D5<=12,Annahmen!$B$6*((D5-Annahmen!$B$9+1)/(12-Annahmen!$B$9+1))^Annahmen!$B$10,IF(D5<=24,Annahmen!$B$6+(Annahmen!$B$7-Annahmen!$B$6)*((D5-12)/12)^Annahmen!$B$11,Annahmen!$B$7+(Annahmen!$B$8-Annahmen!$B$7)*((D5-24)/12)^Annahmen!$B$11))) -> 517.15981 | E7: =IF(E5<Annahmen!$B$9,0,IF(E5<=12,Annahmen!$B$6*((E5-Annahmen!$B$9+1)/(12-Annahmen!$B$9+1))^Annahmen!$B$10,IF(E5<=24,Annahmen!$B$6+(Annahmen!$B$7-Annahmen!$B$6)*((E5-12)/12)^Annahmen!$B$11,Annahmen!$B$7+(Annahmen!$B$8-Annahmen!$B$7)*((E5-24)/12)^Annahmen!$B$11))) -> 841.26782 | F7: =IF(F5<Annahmen!$B$9,0,IF(F5<=12,Annahmen!$B$6*((F5-Annahmen!$B$9+1)/(12-Annahmen!$B$9+1))^Annahmen!$B$10,IF(F5<=24,Annahmen!$B$6+(Annahmen!$B$7-Annahmen!$B$6)*((F5-12)/12)^Annahmen!$B$11,Annahmen!$B$7+(Annahmen!$B$8-Annahmen!$B$7)*((F5-24)/12)^Annahmen!$B$11))) -> 1188.1212 | G7: =IF(G5<Annahmen!$B$9,0,IF(G5<=12,Annahmen!$B$6*((G5-Annahmen!$B$9+1)/(12-Annahmen!$B$9+1))^Annahmen!$B$10,IF(G5<=24,Annahmen!$B$6+(Annahmen!$B$7-Annahmen!$B$6)*((G5-12)/12)^Annahmen!$B$11,Annahmen!$B$7+(Annahmen!$B$8-Annahmen!$B$7)*((G5-24)/12)^Annahmen!$B$11))) -> 1552.9332 | H7: =IF(H5<Annahmen!$B$9,0,IF(H5<=12,Annahmen!$B$6*((H5-Annahmen!$B$9+1)/(12-Annahmen!$B$9+1))^Annahmen!$B$10,IF(H5<=24,Annahmen!$B$6+(Annahmen!$B$7-Annahmen!$B$6)*((H5-12)/12)^Annahmen!$B$11,Annahmen!$B$7+(Annahmen!$B$8-Annahmen!$B$7)*((H5-24)/12)^Annahmen!$B$11))) -> 1932.7259 | I7: =IF(I5<Annahmen!$B$9,0,IF(I5<=12,Annahmen!$B$6*((I5-Annahmen!$B$9+1)/(12-Annahmen!$B$9+1))^Annahmen!$B$10,IF(I5<=24,Annahmen!$B$6+(Annahmen!$B$7-Annahmen!$B$6)*((I5-12)/12)^Annahmen!$B$11,Annahmen!$B$7+(Annahmen!$B$8-Annahmen!$B$7)*((I5-24)/12)^Annahmen!$B$11))) -> 2325.4468 | ... AK7: =IF(AK5<Annahmen!$B$9,0,IF(AK5<=12,Annahmen!$B$6*((AK5-Annahmen!$B$9+1)/(12-Annahmen!$B$9+1))^Annahmen!$B$10,IF(AK5<=24,Annahmen!$B$6+(Annahmen!$B$7-Annahmen!$B$6)*((AK5-12)/12)^Annahmen!$B$11,Annahmen!$B$7+(Annahmen!$B$8-Annahmen!$B$7)*((AK5-24)/12)^Annahmen!$B$11))) -> 30000
A8: Städte | B8: =IF(B5<=12,Annahmen!$B$12,IF(B5<=24,Annahmen!$B$13,Annahmen!$B$14)) -> 1 | C8: =IF(C5<=12,Annahmen!$B$12,IF(C5<=24,Annahmen!$B$13,Annahmen!$B$14)) -> 1 | D8: =IF(D5<=12,Annahmen!$B$12,IF(D5<=24,Annahmen!$B$13,Annahmen!$B$14)) -> 1 | E8: =IF(E5<=12,Annahmen!$B$12,IF(E5<=24,Annahmen!$B$13,Annahmen!$B$14)) -> 1 | F8: =IF(F5<=12,Annahmen!$B$12,IF(F5<=24,Annahmen!$B$13,Annahmen!$B$14)) -> 1 | G8: =IF(G5<=12,Annahmen!$B$12,IF(G5<=24,Annahmen!$B$13,Annahmen!$B$14)) -> 1 | H8: =IF(H5<=12,Annahmen!$B$12,IF(H5<=24,Annahmen!$B$13,Annahmen!$B$14)) -> 1 | I8: =IF(I5<=12,Annahmen!$B$12,IF(I5<=24,Annahmen!$B$13,Annahmen!$B$14)) -> 1 | ... AK8: =IF(AK5<=12,Annahmen!$B$12,IF(AK5<=24,Annahmen!$B$13,Annahmen!$B$14)) -> 2
A9: Neuregistrierungen (Treiber der Prüfkosten) | B9: =MAX(0,B7-0)+B7*Annahmen!$B$15*(1-Annahmen!$B$16) -> 0 | C9: =MAX(0,C7-B7)+C7*Annahmen!$B$15*(1-Annahmen!$B$16) -> 240.86436 | D9: =MAX(0,D7-C7)+D7*Annahmen!$B$15*(1-Annahmen!$B$16) -> 328.25411 | E9: =MAX(0,E7-D7)+E7*Annahmen!$B$15*(1-Annahmen!$B$16) -> 382.99676 | F9: =MAX(0,F7-E7)+F7*Annahmen!$B$15*(1-Annahmen!$B$16) -> 430.02191 | G9: =MAX(0,G7-F7)+G7*Annahmen!$B$15*(1-Annahmen!$B$16) -> 473.51729 | H9: =MAX(0,H7-G7)+H7*Annahmen!$B$15*(1-Annahmen!$B$16) -> 515.08353 | I9: =MAX(0,I7-H7)+I7*Annahmen!$B$15*(1-Annahmen!$B$16) -> 555.50221 | J9: =MAX(0,J7-I7)+J7*Annahmen!$B$15*(1-Annahmen!$B$16) -> 595.20998 | ... AK9: =MAX(0,AK7-AJ7)+AK7*Annahmen!$B$15*(1-Annahmen!$B$16) -> 3860.8747
A10: Konversion zu Zahlern | B10: =IF(B5<Annahmen!$B$22,0,Annahmen!$B$23*(Annahmen!$B$24+(1-Annahmen!$B$24)*MIN(1,(B5-Annahmen!$B$22+1)/Annahmen!$B$25))) -> 0 | C10: =IF(C5<Annahmen!$B$22,0,Annahmen!$B$23*(Annahmen!$B$24+(1-Annahmen!$B$24)*MIN(1,(C5-Annahmen!$B$22+1)/Annahmen!$B$25))) -> 0 | D10: =IF(D5<Annahmen!$B$22,0,Annahmen!$B$23*(Annahmen!$B$24+(1-Annahmen!$B$24)*MIN(1,(D5-Annahmen!$B$22+1)/Annahmen!$B$25))) -> 0 | E10: =IF(E5<Annahmen!$B$22,0,Annahmen!$B$23*(Annahmen!$B$24+(1-Annahmen!$B$24)*MIN(1,(E5-Annahmen!$B$22+1)/Annahmen!$B$25))) -> 0 | F10: =IF(F5<Annahmen!$B$22,0,Annahmen!$B$23*(Annahmen!$B$24+(1-Annahmen!$B$24)*MIN(1,(F5-Annahmen!$B$22+1)/Annahmen!$B$25))) -> 0 | G10: =IF(G5<Annahmen!$B$22,0,Annahmen!$B$23*(Annahmen!$B$24+(1-Annahmen!$B$24)*MIN(1,(G5-Annahmen!$B$22+1)/Annahmen!$B$25))) -> 0 | H10: =IF(H5<Annahmen!$B$22,0,Annahmen!$B$23*(Annahmen!$B$24+(1-Annahmen!$B$24)*MIN(1,(H5-Annahmen!$B$22+1)/Annahmen!$B$25))) -> 0 | I10: =IF(I5<Annahmen!$B$22,0,Annahmen!$B$23*(Annahmen!$B$24+(1-Annahmen!$B$24)*MIN(1,(I5-Annahmen!$B$22+1)/Annahmen!$B$25))) -> 0 | ... AK10: =IF(AK5<Annahmen!$B$22,0,Annahmen!$B$23*(Annahmen!$B$24+(1-Annahmen!$B$24)*MIN(1,(AK5-Annahmen!$B$22+1)/Annahmen!$B$25))) -> 0.022
A11: Zahlende Nutzer | B11: =B7*B10 -> 0 | C11: =C7*C10 -> 0 | D11: =D7*D10 -> 0 | E11: =E7*E10 -> 0 | F11: =F7*F10 -> 0 | G11: =G7*G10 -> 0 | H11: =H7*H10 -> 0 | I11: =I7*I10 -> 0 | ... AK11: =AK7*AK10 -> 660
A12: Staffel-Stützstelle (Hilfsgröße) | B12: =MIN(MATCH(B7,Annahmen!$B$80:$F$80,1),4) -> 1 | C12: =MIN(MATCH(C7,Annahmen!$B$80:$F$80,1),4) -> 1 | D12: =MIN(MATCH(D7,Annahmen!$B$80:$F$80,1),4) -> 1 | E12: =MIN(MATCH(E7,Annahmen!$B$80:$F$80,1),4) -> 1 | F12: =MIN(MATCH(F7,Annahmen!$B$80:$F$80,1),4) -> 1 | G12: =MIN(MATCH(G7,Annahmen!$B$80:$F$80,1),4) -> 1 | H12: =MIN(MATCH(H7,Annahmen!$B$80:$F$80,1),4) -> 1 | I12: =MIN(MATCH(I7,Annahmen!$B$80:$F$80,1),4) -> 1 | ... AK12: =MIN(MATCH(AK7,Annahmen!$B$80:$F$80,1),4) -> 4
A13: ERLÖSE — fünf Quellen (Handbuch B, nach Nr. 65 und 74 neu geschnitten)
A14: Abonnements | B14: =B11*Annahmen!$B$26 -> 0 | C14: =C11*Annahmen!$B$26 -> 0 | D14: =D11*Annahmen!$B$26 -> 0 | E14: =E11*Annahmen!$B$26 -> 0 | F14: =F11*Annahmen!$B$26 -> 0 | G14: =G11*Annahmen!$B$26 -> 0 | H14: =H11*Annahmen!$B$26 -> 0 | I14: =I11*Annahmen!$B$26 -> 0 | ... AK14: =AK11*Annahmen!$B$26 -> 4989.1892
A15: Werkzeugabo für Orte und Veranstalter | B15: =IF(AND(B5>=Annahmen!$B$62,B7>=Annahmen!$B$63),B8*Annahmen!$B$64*Annahmen!$B$65,0) -> 0 | C15: =IF(AND(C5>=Annahmen!$B$62,C7>=Annahmen!$B$63),C8*Annahmen!$B$64*Annahmen!$B$65,0) -> 0 | D15: =IF(AND(D5>=Annahmen!$B$62,D7>=Annahmen!$B$63),D8*Annahmen!$B$64*Annahmen!$B$65,0) -> 0 | E15: =IF(AND(E5>=Annahmen!$B$62,E7>=Annahmen!$B$63),E8*Annahmen!$B$64*Annahmen!$B$65,0) -> 0 | F15: =IF(AND(F5>=Annahmen!$B$62,F7>=Annahmen!$B$63),F8*Annahmen!$B$64*Annahmen!$B$65,0) -> 0 | G15: =IF(AND(G5>=Annahmen!$B$62,G7>=Annahmen!$B$63),G8*Annahmen!$B$64*Annahmen!$B$65,0) -> 0 | H15: =IF(AND(H5>=Annahmen!$B$62,H7>=Annahmen!$B$63),H8*Annahmen!$B$64*Annahmen!$B$65,0) -> 0 | I15: =IF(AND(I5>=Annahmen!$B$62,I7>=Annahmen!$B$63),I8*Annahmen!$B$64*Annahmen!$B$65,0) -> 0 | ... AK15: =IF(AND(AK5>=Annahmen!$B$62,AK7>=Annahmen!$B$63),AK8*Annahmen!$B$64*Annahmen!$B$65,0) -> 290
A16: Veranstaltungen: Anteil an Tickets | B16: =IF(AND(B5>=Annahmen!$B$66,B7>=Annahmen!$B$67),B8*Annahmen!$B$68*Annahmen!$B$69*Annahmen!$B$70*Annahmen!$B$71,0) -> 0 | C16: =IF(AND(C5>=Annahmen!$B$66,C7>=Annahmen!$B$67),C8*Annahmen!$B$68*Annahmen!$B$69*Annahmen!$B$70*Annahmen!$B$71,0) -> 0 | D16: =IF(AND(D5>=Annahmen!$B$66,D7>=Annahmen!$B$67),D8*Annahmen!$B$68*Annahmen!$B$69*Annahmen!$B$70*Annahmen!$B$71,0) -> 0 | E16: =IF(AND(E5>=Annahmen!$B$66,E7>=Annahmen!$B$67),E8*Annahmen!$B$68*Annahmen!$B$69*Annahmen!$B$70*Annahmen!$B$71,0) -> 0 | F16: =IF(AND(F5>=Annahmen!$B$66,F7>=Annahmen!$B$67),F8*Annahmen!$B$68*Annahmen!$B$69*Annahmen!$B$70*Annahmen!$B$71,0) -> 0 | G16: =IF(AND(G5>=Annahmen!$B$66,G7>=Annahmen!$B$67),G8*Annahmen!$B$68*Annahmen!$B$69*Annahmen!$B$70*Annahmen!$B$71,0) -> 0 | H16: =IF(AND(H5>=Annahmen!$B$66,H7>=Annahmen!$B$67),H8*Annahmen!$B$68*Annahmen!$B$69*Annahmen!$B$70*Annahmen!$B$71,0) -> 0 | I16: =IF(AND(I5>=Annahmen!$B$66,I7>=Annahmen!$B$67),I8*Annahmen!$B$68*Annahmen!$B$69*Annahmen!$B$70*Annahmen!$B$71,0) -> 0 | ... AK16: =IF(AND(AK5>=Annahmen!$B$66,AK7>=Annahmen!$B$67),AK8*Annahmen!$B$68*Annahmen!$B$69*Annahmen!$B$70*Annahmen!$B$71,0) -> 460.8
A17: Unterstützerbeiträge | B17: =IF(B5>=Annahmen!$B$72,B7*Annahmen!$B$73,0) -> 0 | C17: =IF(C5>=Annahmen!$B$72,C7*Annahmen!$B$73,0) -> 0 | D17: =IF(D5>=Annahmen!$B$72,D7*Annahmen!$B$73,0) -> 0 | E17: =IF(E5>=Annahmen!$B$72,E7*Annahmen!$B$73,0) -> 0 | F17: =IF(F5>=Annahmen!$B$72,F7*Annahmen!$B$73,0) -> 0 | G17: =IF(G5>=Annahmen!$B$72,G7*Annahmen!$B$73,0) -> 0 | H17: =IF(H5>=Annahmen!$B$72,H7*Annahmen!$B$73,0) -> 0 | I17: =IF(I5>=Annahmen!$B$72,I7*Annahmen!$B$73,0) -> 0 | ... AK17: =IF(AK5>=Annahmen!$B$72,AK7*Annahmen!$B$73,0) -> 450
A18: Gesundheitspartnerschaft | B18: =IF(B5>=Annahmen!$B$74,B8*Annahmen!$B$75,0) -> 0 | C18: =IF(C5>=Annahmen!$B$74,C8*Annahmen!$B$75,0) -> 0 | D18: =IF(D5>=Annahmen!$B$74,D8*Annahmen!$B$75,0) -> 0 | E18: =IF(E5>=Annahmen!$B$74,E8*Annahmen!$B$75,0) -> 0 | F18: =IF(F5>=Annahmen!$B$74,F8*Annahmen!$B$75,0) -> 0 | G18: =IF(G5>=Annahmen!$B$74,G8*Annahmen!$B$75,0) -> 0 | H18: =IF(H5>=Annahmen!$B$74,H8*Annahmen!$B$75,0) -> 0 | I18: =IF(I5>=Annahmen!$B$74,I8*Annahmen!$B$75,0) -> 0 | ... AK18: =IF(AK5>=Annahmen!$B$74,AK8*Annahmen!$B$75,0) -> 534
A19: Erlöse gesamt | B19: =SUM(B14:B18) -> 0 | C19: =SUM(C14:C18) -> 0 | D19: =SUM(D14:D18) -> 0 | E19: =SUM(E14:E18) -> 0 | F19: =SUM(F14:F18) -> 0 | G19: =SUM(G14:G18) -> 0 | H19: =SUM(H14:H18) -> 0 | I19: =SUM(I14:I18) -> 0 | ... AK19: =SUM(AK14:AK18) -> 6723.9892
A21: KOSTEN
A22: Pflichtpositionen (nicht kürzbar) | B22: =INDEX(Annahmen!$B$94:$F$94,B$12)+(B$7-INDEX(Annahmen!$B$80:$F$80,B$12))*(INDEX(Annahmen!$B$94:$F$94,B$12+1)-INDEX(Annahmen!$B$94:$F$94,B$12))/(INDEX(Annahmen!$B$80:$F$80,B$12+1)-INDEX(Annahmen!$B$80:$F$80,B$12)) -> 1000 | C22: =INDEX(Annahmen!$B$94:$F$94,C$12)+(C$7-INDEX(Annahmen!$B$80:$F$80,C$12))*(INDEX(Annahmen!$B$94:$F$94,C$12+1)-INDEX(Annahmen!$B$94:$F$94,C$12))/(INDEX(Annahmen!$B$80:$F$80,C$12+1)-INDEX(Annahmen!$B$80:$F$80,C$12)) -> 1013.5064 | D22: =INDEX(Annahmen!$B$94:$F$94,D$12)+(D$7-INDEX(Annahmen!$B$80:$F$80,D$12))*(INDEX(Annahmen!$B$94:$F$94,D$12+1)-INDEX(Annahmen!$B$94:$F$94,D$12))/(INDEX(Annahmen!$B$80:$F$80,D$12+1)-INDEX(Annahmen!$B$80:$F$80,D$12)) -> 1031.0296 | E22: =INDEX(Annahmen!$B$94:$F$94,E$12)+(E$7-INDEX(Annahmen!$B$80:$F$80,E$12))*(INDEX(Annahmen!$B$94:$F$94,E$12+1)-INDEX(Annahmen!$B$94:$F$94,E$12))/(INDEX(Annahmen!$B$80:$F$80,E$12+1)-INDEX(Annahmen!$B$80:$F$80,E$12)) -> 1050.4761 | F22: =INDEX(Annahmen!$B$94:$F$94,F$12)+(F$7-INDEX(Annahmen!$B$80:$F$80,F$12))*(INDEX(Annahmen!$B$94:$F$94,F$12+1)-INDEX(Annahmen!$B$94:$F$94,F$12))/(INDEX(Annahmen!$B$80:$F$80,F$12+1)-INDEX(Annahmen!$B$80:$F$80,F$12)) -> 1071.2873 | G22: =INDEX(Annahmen!$B$94:$F$94,G$12)+(G$7-INDEX(Annahmen!$B$80:$F$80,G$12))*(INDEX(Annahmen!$B$94:$F$94,G$12+1)-INDEX(Annahmen!$B$94:$F$94,G$12))/(INDEX(Annahmen!$B$80:$F$80,G$12+1)-INDEX(Annahmen!$B$80:$F$80,G$12)) -> 1093.176 | H22: =INDEX(Annahmen!$B$94:$F$94,H$12)+(H$7-INDEX(Annahmen!$B$80:$F$80,H$12))*(INDEX(Annahmen!$B$94:$F$94,H$12+1)-INDEX(Annahmen!$B$94:$F$94,H$12))/(INDEX(Annahmen!$B$80:$F$80,H$12+1)-INDEX(Annahmen!$B$80:$F$80,H$12)) -> 1115.9636 | I22: =INDEX(Annahmen!$B$94:$F$94,I$12)+(I$7-INDEX(Annahmen!$B$80:$F$80,I$12))*(INDEX(Annahmen!$B$94:$F$94,I$12+1)-INDEX(Annahmen!$B$94:$F$94,I$12))/(INDEX(Annahmen!$B$80:$F$80,I$12+1)-INDEX(Annahmen!$B$80:$F$80,I$12)) -> 1139.5268 | ... AK22: =INDEX(Annahmen!$B$94:$F$94,AK$12)+(AK$7-INDEX(Annahmen!$B$80:$F$80,AK$12))*(INDEX(Annahmen!$B$94:$F$94,AK$12+1)-INDEX(Annahmen!$B$94:$F$94,AK$12))/(INDEX(Annahmen!$B$80:$F$80,AK$12+1)-INDEX(Annahmen!$B$80:$F$80,AK$12)) -> 2393.3333
A23: Betrieb (ohne Altersprüfung) | B23: =INDEX(Annahmen!$B$95:$F$95,B$12)+(B$7-INDEX(Annahmen!$B$80:$F$80,B$12))*(INDEX(Annahmen!$B$95:$F$95,B$12+1)-INDEX(Annahmen!$B$95:$F$95,B$12))/(INDEX(Annahmen!$B$80:$F$80,B$12+1)-INDEX(Annahmen!$B$80:$F$80,B$12)) -> 270 | C23: =INDEX(Annahmen!$B$95:$F$95,C$12)+(C$7-INDEX(Annahmen!$B$80:$F$80,C$12))*(INDEX(Annahmen!$B$95:$F$95,C$12+1)-INDEX(Annahmen!$B$95:$F$95,C$12))/(INDEX(Annahmen!$B$80:$F$80,C$12+1)-INDEX(Annahmen!$B$80:$F$80,C$12)) -> 276.30299 | D23: =INDEX(Annahmen!$B$95:$F$95,D$12)+(D$7-INDEX(Annahmen!$B$80:$F$80,D$12))*(INDEX(Annahmen!$B$95:$F$95,D$12+1)-INDEX(Annahmen!$B$95:$F$95,D$12))/(INDEX(Annahmen!$B$80:$F$80,D$12+1)-INDEX(Annahmen!$B$80:$F$80,D$12)) -> 284.48047 | E23: =INDEX(Annahmen!$B$95:$F$95,E$12)+(E$7-INDEX(Annahmen!$B$80:$F$80,E$12))*(INDEX(Annahmen!$B$95:$F$95,E$12+1)-INDEX(Annahmen!$B$95:$F$95,E$12))/(INDEX(Annahmen!$B$80:$F$80,E$12+1)-INDEX(Annahmen!$B$80:$F$80,E$12)) -> 293.5555 | F23: =INDEX(Annahmen!$B$95:$F$95,F$12)+(F$7-INDEX(Annahmen!$B$80:$F$80,F$12))*(INDEX(Annahmen!$B$95:$F$95,F$12+1)-INDEX(Annahmen!$B$95:$F$95,F$12))/(INDEX(Annahmen!$B$80:$F$80,F$12+1)-INDEX(Annahmen!$B$80:$F$80,F$12)) -> 303.26739 | G23: =INDEX(Annahmen!$B$95:$F$95,G$12)+(G$7-INDEX(Annahmen!$B$80:$F$80,G$12))*(INDEX(Annahmen!$B$95:$F$95,G$12+1)-INDEX(Annahmen!$B$95:$F$95,G$12))/(INDEX(Annahmen!$B$80:$F$80,G$12+1)-INDEX(Annahmen!$B$80:$F$80,G$12)) -> 313.48213 | H23: =INDEX(Annahmen!$B$95:$F$95,H$12)+(H$7-INDEX(Annahmen!$B$80:$F$80,H$12))*(INDEX(Annahmen!$B$95:$F$95,H$12+1)-INDEX(Annahmen!$B$95:$F$95,H$12))/(INDEX(Annahmen!$B$80:$F$80,H$12+1)-INDEX(Annahmen!$B$80:$F$80,H$12)) -> 324.11633 | I23: =INDEX(Annahmen!$B$95:$F$95,I$12)+(I$7-INDEX(Annahmen!$B$80:$F$80,I$12))*(INDEX(Annahmen!$B$95:$F$95,I$12+1)-INDEX(Annahmen!$B$95:$F$95,I$12))/(INDEX(Annahmen!$B$80:$F$80,I$12+1)-INDEX(Annahmen!$B$80:$F$80,I$12)) -> 335.11251 | ... AK23: =INDEX(Annahmen!$B$95:$F$95,AK$12)+(AK$7-INDEX(Annahmen!$B$80:$F$80,AK$12))*(INDEX(Annahmen!$B$95:$F$95,AK$12+1)-INDEX(Annahmen!$B$95:$F$95,AK$12))/(INDEX(Annahmen!$B$80:$F$80,AK$12+1)-INDEX(Annahmen!$B$80:$F$80,AK$12)) -> 936.66667
A24: Altersprüfung (Stufe 1 + Stufe 2) ⟵ Schalter | B24: =B9*Annahmen!$B$105+B9*Annahmen!$B$110*Annahmen!$B$111 -> 0 | C24: =C9*Annahmen!$B$105+C9*Annahmen!$B$110*Annahmen!$B$111 -> 137.29269 | D24: =D9*Annahmen!$B$105+D9*Annahmen!$B$110*Annahmen!$B$111 -> 187.10484 | E24: =E9*Annahmen!$B$105+E9*Annahmen!$B$110*Annahmen!$B$111 -> 218.30815 | F24: =F9*Annahmen!$B$105+F9*Annahmen!$B$110*Annahmen!$B$111 -> 245.11249 | G24: =G9*Annahmen!$B$105+G9*Annahmen!$B$110*Annahmen!$B$111 -> 269.90485 | H24: =H9*Annahmen!$B$105+H9*Annahmen!$B$110*Annahmen!$B$111 -> 293.59761 | I24: =I9*Annahmen!$B$105+I9*Annahmen!$B$110*Annahmen!$B$111 -> 316.63626 | ... AK24: =AK9*Annahmen!$B$105+AK9*Annahmen!$B$110*Annahmen!$B$111 -> 2200.6986
A25: SMS-Versand (Z-10) | B25: =B9*Annahmen!$B$146*Annahmen!$B$147*Annahmen!$B$148 -> 0 | C25: =C9*Annahmen!$B$146*Annahmen!$B$147*Annahmen!$B$148 -> 11.272452 | D25: =D9*Annahmen!$B$146*Annahmen!$B$147*Annahmen!$B$148 -> 15.362292 | E25: =E9*Annahmen!$B$146*Annahmen!$B$147*Annahmen!$B$148 -> 17.924248 | F25: =F9*Annahmen!$B$146*Annahmen!$B$147*Annahmen!$B$148 -> 20.125025 | G25: =G9*Annahmen!$B$146*Annahmen!$B$147*Annahmen!$B$148 -> 22.160609 | H25: =H9*Annahmen!$B$146*Annahmen!$B$147*Annahmen!$B$148 -> 24.105909 | I25: =I9*Annahmen!$B$146*Annahmen!$B$147*Annahmen!$B$148 -> 25.997504 | ... AK25: =AK9*Annahmen!$B$146*Annahmen!$B$147*Annahmen!$B$148 -> 180.68894
A26: Personal: Moderation | B26: =INDEX(Annahmen!$B$96:$F$96,B$12)+(B$7-INDEX(Annahmen!$B$80:$F$80,B$12))*(INDEX(Annahmen!$B$96:$F$96,B$12+1)-INDEX(Annahmen!$B$96:$F$96,B$12))/(INDEX(Annahmen!$B$80:$F$80,B$12+1)-INDEX(Annahmen!$B$80:$F$80,B$12)) -> 0 | C26: =INDEX(Annahmen!$B$96:$F$96,C$12)+(C$7-INDEX(Annahmen!$B$80:$F$80,C$12))*(INDEX(Annahmen!$B$96:$F$96,C$12+1)-INDEX(Annahmen!$B$96:$F$96,C$12))/(INDEX(Annahmen!$B$80:$F$80,C$12+1)-INDEX(Annahmen!$B$80:$F$80,C$12)) -> 0 | D26: =INDEX(Annahmen!$B$96:$F$96,D$12)+(D$7-INDEX(Annahmen!$B$80:$F$80,D$12))*(INDEX(Annahmen!$B$96:$F$96,D$12+1)-INDEX(Annahmen!$B$96:$F$96,D$12))/(INDEX(Annahmen!$B$80:$F$80,D$12+1)-INDEX(Annahmen!$B$80:$F$80,D$12)) -> 0 | E26: =INDEX(Annahmen!$B$96:$F$96,E$12)+(E$7-INDEX(Annahmen!$B$80:$F$80,E$12))*(INDEX(Annahmen!$B$96:$F$96,E$12+1)-INDEX(Annahmen!$B$96:$F$96,E$12))/(INDEX(Annahmen!$B$80:$F$80,E$12+1)-INDEX(Annahmen!$B$80:$F$80,E$12)) -> 0 | F26: =INDEX(Annahmen!$B$96:$F$96,F$12)+(F$7-INDEX(Annahmen!$B$80:$F$80,F$12))*(INDEX(Annahmen!$B$96:$F$96,F$12+1)-INDEX(Annahmen!$B$96:$F$96,F$12))/(INDEX(Annahmen!$B$80:$F$80,F$12+1)-INDEX(Annahmen!$B$80:$F$80,F$12)) -> 0 | G26: =INDEX(Annahmen!$B$96:$F$96,G$12)+(G$7-INDEX(Annahmen!$B$80:$F$80,G$12))*(INDEX(Annahmen!$B$96:$F$96,G$12+1)-INDEX(Annahmen!$B$96:$F$96,G$12))/(INDEX(Annahmen!$B$80:$F$80,G$12+1)-INDEX(Annahmen!$B$80:$F$80,G$12)) -> 0 | H26: =INDEX(Annahmen!$B$96:$F$96,H$12)+(H$7-INDEX(Annahmen!$B$80:$F$80,H$12))*(INDEX(Annahmen!$B$96:$F$96,H$12+1)-INDEX(Annahmen!$B$96:$F$96,H$12))/(INDEX(Annahmen!$B$80:$F$80,H$12+1)-INDEX(Annahmen!$B$80:$F$80,H$12)) -> 0 | I26: =INDEX(Annahmen!$B$96:$F$96,I$12)+(I$7-INDEX(Annahmen!$B$80:$F$80,I$12))*(INDEX(Annahmen!$B$96:$F$96,I$12+1)-INDEX(Annahmen!$B$96:$F$96,I$12))/(INDEX(Annahmen!$B$80:$F$80,I$12+1)-INDEX(Annahmen!$B$80:$F$80,I$12)) -> 0 | ... AK26: =INDEX(Annahmen!$B$96:$F$96,AK$12)+(AK$7-INDEX(Annahmen!$B$80:$F$80,AK$12))*(INDEX(Annahmen!$B$96:$F$96,AK$12+1)-INDEX(Annahmen!$B$96:$F$96,AK$12))/(INDEX(Annahmen!$B$80:$F$80,AK$12+1)-INDEX(Annahmen!$B$80:$F$80,AK$12)) -> 2266.6667
A27: Marketing (Barmittel) | B27: =INDEX(Annahmen!$B$97:$F$97,B$12)+(B$7-INDEX(Annahmen!$B$80:$F$80,B$12))*(INDEX(Annahmen!$B$97:$F$97,B$12+1)-INDEX(Annahmen!$B$97:$F$97,B$12))/(INDEX(Annahmen!$B$80:$F$80,B$12+1)-INDEX(Annahmen!$B$80:$F$80,B$12)) -> 150 | C27: =INDEX(Annahmen!$B$97:$F$97,C$12)+(C$7-INDEX(Annahmen!$B$80:$F$80,C$12))*(INDEX(Annahmen!$B$97:$F$97,C$12+1)-INDEX(Annahmen!$B$97:$F$97,C$12))/(INDEX(Annahmen!$B$80:$F$80,C$12+1)-INDEX(Annahmen!$B$80:$F$80,C$12)) -> 154.50214 | D27: =INDEX(Annahmen!$B$97:$F$97,D$12)+(D$7-INDEX(Annahmen!$B$80:$F$80,D$12))*(INDEX(Annahmen!$B$97:$F$97,D$12+1)-INDEX(Annahmen!$B$97:$F$97,D$12))/(INDEX(Annahmen!$B$80:$F$80,D$12+1)-INDEX(Annahmen!$B$80:$F$80,D$12)) -> 160.3432 | E27: =INDEX(Annahmen!$B$97:$F$97,E$12)+(E$7-INDEX(Annahmen!$B$80:$F$80,E$12))*(INDEX(Annahmen!$B$97:$F$97,E$12+1)-INDEX(Annahmen!$B$97:$F$97,E$12))/(INDEX(Annahmen!$B$80:$F$80,E$12+1)-INDEX(Annahmen!$B$80:$F$80,E$12)) -> 166.82536 | F27: =INDEX(Annahmen!$B$97:$F$97,F$12)+(F$7-INDEX(Annahmen!$B$80:$F$80,F$12))*(INDEX(Annahmen!$B$97:$F$97,F$12+1)-INDEX(Annahmen!$B$97:$F$97,F$12))/(INDEX(Annahmen!$B$80:$F$80,F$12+1)-INDEX(Annahmen!$B$80:$F$80,F$12)) -> 173.76242 | G27: =INDEX(Annahmen!$B$97:$F$97,G$12)+(G$7-INDEX(Annahmen!$B$80:$F$80,G$12))*(INDEX(Annahmen!$B$97:$F$97,G$12+1)-INDEX(Annahmen!$B$97:$F$97,G$12))/(INDEX(Annahmen!$B$80:$F$80,G$12+1)-INDEX(Annahmen!$B$80:$F$80,G$12)) -> 181.05866 | H27: =INDEX(Annahmen!$B$97:$F$97,H$12)+(H$7-INDEX(Annahmen!$B$80:$F$80,H$12))*(INDEX(Annahmen!$B$97:$F$97,H$12+1)-INDEX(Annahmen!$B$97:$F$97,H$12))/(INDEX(Annahmen!$B$80:$F$80,H$12+1)-INDEX(Annahmen!$B$80:$F$80,H$12)) -> 188.65452 | I27: =INDEX(Annahmen!$B$97:$F$97,I$12)+(I$7-INDEX(Annahmen!$B$80:$F$80,I$12))*(INDEX(Annahmen!$B$97:$F$97,I$12+1)-INDEX(Annahmen!$B$97:$F$97,I$12))/(INDEX(Annahmen!$B$80:$F$80,I$12+1)-INDEX(Annahmen!$B$80:$F$80,I$12)) -> 196.50894 | ... AK27: =INDEX(Annahmen!$B$97:$F$97,AK$12)+(AK$7-INDEX(Annahmen!$B$80:$F$80,AK$12))*(INDEX(Annahmen!$B$97:$F$97,AK$12+1)-INDEX(Annahmen!$B$97:$F$97,AK$12))/(INDEX(Annahmen!$B$80:$F$80,AK$12+1)-INDEX(Annahmen!$B$80:$F$80,AK$12)) -> 800
A28: Eigene Veranstaltungen (Nr. 74) | B28: =IF(B5>=Annahmen!$B$145,B8*Annahmen!$B$144/12,0) -> 166.66667 | C28: =IF(C5>=Annahmen!$B$145,C8*Annahmen!$B$144/12,0) -> 166.66667 | D28: =IF(D5>=Annahmen!$B$145,D8*Annahmen!$B$144/12,0) -> 166.66667 | E28: =IF(E5>=Annahmen!$B$145,E8*Annahmen!$B$144/12,0) -> 166.66667 | F28: =IF(F5>=Annahmen!$B$145,F8*Annahmen!$B$144/12,0) -> 166.66667 | G28: =IF(G5>=Annahmen!$B$145,G8*Annahmen!$B$144/12,0) -> 166.66667 | H28: =IF(H5>=Annahmen!$B$145,H8*Annahmen!$B$144/12,0) -> 166.66667 | I28: =IF(I5>=Annahmen!$B$145,I8*Annahmen!$B$144/12,0) -> 166.66667 | ... AK28: =IF(AK5>=Annahmen!$B$145,AK8*Annahmen!$B$144/12,0) -> 333.33333
A29: CSD-Auftritte (zum Start und Folgejahre) | B29: =IF(B5=Annahmen!$B$136,Annahmen!$B$135,0)+IF(B5=Annahmen!$B$138,Annahmen!$B$137,0)+IF(B5=Annahmen!$B$140,Annahmen!$B$139,0) -> 10000 | C29: =IF(C5=Annahmen!$B$136,Annahmen!$B$135,0)+IF(C5=Annahmen!$B$138,Annahmen!$B$137,0)+IF(C5=Annahmen!$B$140,Annahmen!$B$139,0) -> 0 | D29: =IF(D5=Annahmen!$B$136,Annahmen!$B$135,0)+IF(D5=Annahmen!$B$138,Annahmen!$B$137,0)+IF(D5=Annahmen!$B$140,Annahmen!$B$139,0) -> 0 | E29: =IF(E5=Annahmen!$B$136,Annahmen!$B$135,0)+IF(E5=Annahmen!$B$138,Annahmen!$B$137,0)+IF(E5=Annahmen!$B$140,Annahmen!$B$139,0) -> 0 | F29: =IF(F5=Annahmen!$B$136,Annahmen!$B$135,0)+IF(F5=Annahmen!$B$138,Annahmen!$B$137,0)+IF(F5=Annahmen!$B$140,Annahmen!$B$139,0) -> 0 | G29: =IF(G5=Annahmen!$B$136,Annahmen!$B$135,0)+IF(G5=Annahmen!$B$138,Annahmen!$B$137,0)+IF(G5=Annahmen!$B$140,Annahmen!$B$139,0) -> 0 | H29: =IF(H5=Annahmen!$B$136,Annahmen!$B$135,0)+IF(H5=Annahmen!$B$138,Annahmen!$B$137,0)+IF(H5=Annahmen!$B$140,Annahmen!$B$139,0) -> 0 | I29: =IF(I5=Annahmen!$B$136,Annahmen!$B$135,0)+IF(I5=Annahmen!$B$138,Annahmen!$B$137,0)+IF(I5=Annahmen!$B$140,Annahmen!$B$139,0) -> 0 | ... AK29: =IF(AK5=Annahmen!$B$136,Annahmen!$B$135,0)+IF(AK5=Annahmen!$B$138,Annahmen!$B$137,0)+IF(AK5=Annahmen!$B$140,Annahmen!$B$139,0) -> 0
A30: Einmalkosten | B30: =SUMIF(Annahmen!$C$116:$C$129,B5,Annahmen!$B$116:$B$129) -> 26700 | C30: =SUMIF(Annahmen!$C$116:$C$129,C5,Annahmen!$B$116:$B$129) -> 2700 | D30: =SUMIF(Annahmen!$C$116:$C$129,D5,Annahmen!$B$116:$B$129) -> 11500 | E30: =SUMIF(Annahmen!$C$116:$C$129,E5,Annahmen!$B$116:$B$129) -> 4500 | F30: =SUMIF(Annahmen!$C$116:$C$129,F5,Annahmen!$B$116:$B$129) -> 3000 | G30: =SUMIF(Annahmen!$C$116:$C$129,G5,Annahmen!$B$116:$B$129) -> 2000 | H30: =SUMIF(Annahmen!$C$116:$C$129,H5,Annahmen!$B$116:$B$129) -> 0 | I30: =SUMIF(Annahmen!$C$116:$C$129,I5,Annahmen!$B$116:$B$129) -> 5500 | ... AK30: =SUMIF(Annahmen!$C$116:$C$129,AK5,Annahmen!$B$116:$B$129) -> 0
A31: Kosten gesamt | B31: =SUM(B22:B30) -> 38286.667 | C31: =SUM(C22:C30) -> 4459.5433 | D31: =SUM(D22:D30) -> 13344.987 | E31: =SUM(E22:E30) -> 6413.756 | F31: =SUM(F22:F30) -> 4980.2213 | G31: =SUM(G22:G30) -> 4046.4489 | H31: =SUM(H22:H30) -> 2113.1046 | I31: =SUM(I22:I30) -> 7680.4487 | ... AK31: =SUM(AK22:AK30) -> 9111.3875
A33: Ergebnis je Monat | B33: =B19-B31 -> -38286.667 | C33: =C19-C31 -> -4459.5433 | D33: =D19-D31 -> -13344.987 | E33: =E19-E31 -> -6413.756 | F33: =F19-F31 -> -4980.2213 | G33: =G19-G31 -> -4046.4489 | H33: =H19-H31 -> -2113.1046 | I33: =I19-I31 -> -7680.4487 | ... AK33: =AK19-AK31 -> -2387.3983
A34: Kumulierte Liquidität | B34: =B33 -> -38286.667 | C34: =B34+C33 -> -42746.21 | D34: =C34+D33 -> -56091.197 | E34: =D34+E33 -> -62504.953 | F34: =E34+F33 -> -67485.174 | G34: =F34+G33 -> -71531.623 | H34: =G34+H33 -> -73644.728 | I34: =H34+I33 -> -81325.177 | J34: =I34+J33 -> -83573.764 | ... AK34: =AJ34+AK33 -> -145217.21
A36: nachrichtlich: Krankenversicherung privat, kumuliert | B36: =Annahmen!$B$154*Annahmen!$B$155 -> 400 | C36: =B36+Annahmen!$B$154*Annahmen!$B$155 -> 800 | D36: =C36+Annahmen!$B$154*Annahmen!$B$155 -> 1200 | E36: =D36+Annahmen!$B$154*Annahmen!$B$155 -> 1600 | F36: =E36+Annahmen!$B$154*Annahmen!$B$155 -> 2000 | G36: =F36+Annahmen!$B$154*Annahmen!$B$155 -> 2400 | H36: =G36+Annahmen!$B$154*Annahmen!$B$155 -> 2800 | I36: =H36+Annahmen!$B$154*Annahmen!$B$155 -> 3200 | J36: =I36+Annahmen!$B$154*Annahmen!$B$155 -> 3600 | ... AK36: =AJ36+Annahmen!$B$154*Annahmen!$B$155 -> 14400
A37: nachrichtlich: Lebenshaltung beider Gründer, kumuliert | B37: =Annahmen!$B$156*Annahmen!$B$155 -> 2200 | C37: =B37+Annahmen!$B$156*Annahmen!$B$155 -> 4400 | D37: =C37+Annahmen!$B$156*Annahmen!$B$155 -> 6600 | E37: =D37+Annahmen!$B$156*Annahmen!$B$155 -> 8800 | F37: =E37+Annahmen!$B$156*Annahmen!$B$155 -> 11000 | G37: =F37+Annahmen!$B$156*Annahmen!$B$155 -> 13200 | H37: =G37+Annahmen!$B$156*Annahmen!$B$155 -> 15400 | I37: =H37+Annahmen!$B$156*Annahmen!$B$155 -> 17600 | J37: =I37+Annahmen!$B$156*Annahmen!$B$155 -> 19800 | ... AK37: =AJ37+Annahmen!$B$156*Annahmen!$B$155 -> 79200
A39: Jahressummen (rechnen sich)
A40: Größe | B40: Jahr 1 | C40: Jahr 2 | D40: Jahr 3 | E40: 36 Monate
A41: MAU im Jahresmittel | B41: =AVERAGE(B7:M7) -> 1835.3359 | C41: =AVERAGE(N7:Y7) -> 8696.7502 | D41: =AVERAGE(Z7:AK7) -> 21514.8 | E41: =AVERAGE(B7:AK7) -> 10682.296
A42: Zahlende Nutzer im Mittel | B42: =AVERAGE(B11:M11) -> 0 | C42: =AVERAGE(N11:Y11) -> 125.23178 | D42: =AVERAGE(Z11:AK11) -> 473.32561 | E42: =AVERAGE(B11:AK11) -> 199.51913
A43: Erlöse gesamt | B43: =SUM(B19:M19) -> 0 | C43: =SUM(N19:Y19) -> 17270.137 | D43: =SUM(Z19:AK19) -> 59922.828 | E43: =SUM(B19:AK19) -> 77192.965
A44: Kosten gesamt | B44: =SUM(B31:M31) -> 90736.705 | C44: =SUM(N31:Y31) -> 42736.239 | D44: =SUM(Z31:AK31) -> 88937.234 | E44: =SUM(B31:AK31) -> 222410.18
A45: Ergebnis | B45: =SUM(B33:M33) -> -90736.705 | C45: =SUM(N33:Y33) -> -25466.103 | D45: =SUM(Z33:AK33) -> -29014.406 | E45: =SUM(B33:AK33) -> -145217.21

Sheet Realistisch
A1: Szenario B — Realistisch
A2: 36 Monate ab T0 — dem Start in der CSD-Saison; geplant wird ein Jahr nach dem Bestfall Sommer 2028 (Nr. 45). Alles rechnet sich aus dem Blatt „Annahmen“. Kein Gründergehalt in keinem Monat.
A4: Position | B4: M1 | C4: M2 | D4: M3 | E4: M4 | F4: M5 | G4: M6 | H4: M7 | I4: M8 | J4: M9 | K4: M10 | L4: M11 | M4: M12 | N4: M13 | O4: M14 | P4: M15 | Q4: M16 | R4: M17 | S4: M18 | T4: M19 | U4: M20 | V4: M21 | W4: M22 | X4: M23 | Y4: M24 | Z4: M25 | AA4: M26 | AB4: M27 | AC4: M28 | AD4: M29 | AE4: M30 | AF4: M31 | AG4: M32 | AH4: M33 | AI4: M34 | AJ4: M35 | AK4: M36
A5: Monat | B5: 1 | C5: 2 | D5: 3 | E5: 4 | F5: 5 | G5: 6 | H5: 7 | I5: 8 | J5: 9 | K5: 10 | L5: 11 | M5: 12 | N5: 13 | O5: 14 | P5: 15 | Q5: 16 | R5: 17 | S5: 18 | T5: 19 | U5: 20 | V5: 21 | W5: 22 | X5: 23 | Y5: 24 | Z5: 25 | AA5: 26 | AB5: 27 | AC5: 28 | AD5: 29 | AE5: 30 | AF5: 31 | AG5: 32 | AH5: 33 | AI5: 34 | AJ5: 35 | AK5: 36
A6: Jahr | B6: =ROUNDUP(B5/12,0) -> 1 | C6: =ROUNDUP(C5/12,0) -> 1 | D6: =ROUNDUP(D5/12,0) -> 1 | E6: =ROUNDUP(E5/12,0) -> 1 | F6: =ROUNDUP(F5/12,0) -> 1 | G6: =ROUNDUP(G5/12,0) -> 1 | H6: =ROUNDUP(H5/12,0) -> 1 | I6: =ROUNDUP(I5/12,0) -> 1 | ... AK6: =ROUNDUP(AK5/12,0) -> 3
A7: Aktive Nutzer im Monat (MAU) | B7: =IF(B5<Annahmen!$C$9,0,IF(B5<=12,Annahmen!$C$6*((B5-Annahmen!$C$9+1)/(12-Annahmen!$C$9+1))^Annahmen!$C$10,IF(B5<=24,Annahmen!$C$6+(Annahmen!$C$7-Annahmen!$C$6)*((B5-12)/12)^Annahmen!$C$11,Annahmen!$C$7+(Annahmen!$C$8-Annahmen!$C$7)*((B5-24)/12)^Annahmen!$C$11))) -> 0 | C7: =IF(C5<Annahmen!$C$9,0,IF(C5<=12,Annahmen!$C$6*((C5-Annahmen!$C$9+1)/(12-Annahmen!$C$9+1))^Annahmen!$C$10,IF(C5<=24,Annahmen!$C$6+(Annahmen!$C$7-Annahmen!$C$6)*((C5-12)/12)^Annahmen!$C$11,Annahmen!$C$7+(Annahmen!$C$8-Annahmen!$C$7)*((C5-24)/12)^Annahmen!$C$11))) -> 274.11914 | D7: =IF(D5<Annahmen!$C$9,0,IF(D5<=12,Annahmen!$C$6*((D5-Annahmen!$C$9+1)/(12-Annahmen!$C$9+1))^Annahmen!$C$10,IF(D5<=24,Annahmen!$C$6+(Annahmen!$C$7-Annahmen!$C$6)*((D5-12)/12)^Annahmen!$C$11,Annahmen!$C$7+(Annahmen!$C$8-Annahmen!$C$7)*((D5-24)/12)^Annahmen!$C$11))) -> 713.44542 | E7: =IF(E5<Annahmen!$C$9,0,IF(E5<=12,Annahmen!$C$6*((E5-Annahmen!$C$9+1)/(12-Annahmen!$C$9+1))^Annahmen!$C$10,IF(E5<=24,Annahmen!$C$6+(Annahmen!$C$7-Annahmen!$C$6)*((E5-12)/12)^Annahmen!$C$11,Annahmen!$C$7+(Annahmen!$C$8-Annahmen!$C$7)*((E5-24)/12)^Annahmen!$C$11))) -> 1248.4372 | F7: =IF(F5<Annahmen!$C$9,0,IF(F5<=12,Annahmen!$C$6*((F5-Annahmen!$C$9+1)/(12-Annahmen!$C$9+1))^Annahmen!$C$10,IF(F5<=24,Annahmen!$C$6+(Annahmen!$C$7-Annahmen!$C$6)*((F5-12)/12)^Annahmen!$C$11,Annahmen!$C$7+(Annahmen!$C$8-Annahmen!$C$7)*((F5-24)/12)^Annahmen!$C$11))) -> 1856.8728 | G7: =IF(G5<Annahmen!$C$9,0,IF(G5<=12,Annahmen!$C$6*((G5-Annahmen!$C$9+1)/(12-Annahmen!$C$9+1))^Annahmen!$C$10,IF(G5<=24,Annahmen!$C$6+(Annahmen!$C$7-Annahmen!$C$6)*((G5-12)/12)^Annahmen!$C$11,Annahmen!$C$7+(Annahmen!$C$8-Annahmen!$C$7)*((G5-24)/12)^Annahmen!$C$11))) -> 2526.4922 | H7: =IF(H5<Annahmen!$C$9,0,IF(H5<=12,Annahmen!$C$6*((H5-Annahmen!$C$9+1)/(12-Annahmen!$C$9+1))^Annahmen!$C$10,IF(H5<=24,Annahmen!$C$6+(Annahmen!$C$7-Annahmen!$C$6)*((H5-12)/12)^Annahmen!$C$11,Annahmen!$C$7+(Annahmen!$C$8-Annahmen!$C$7)*((H5-24)/12)^Annahmen!$C$11))) -> 3249.2871 | I7: =IF(I5<Annahmen!$C$9,0,IF(I5<=12,Annahmen!$C$6*((I5-Annahmen!$C$9+1)/(12-Annahmen!$C$9+1))^Annahmen!$C$10,IF(I5<=24,Annahmen!$C$6+(Annahmen!$C$7-Annahmen!$C$6)*((I5-12)/12)^Annahmen!$C$11,Annahmen!$C$7+(Annahmen!$C$8-Annahmen!$C$7)*((I5-24)/12)^Annahmen!$C$11))) -> 4019.5242 | ... AK7: =IF(AK5<Annahmen!$C$9,0,IF(AK5<=12,Annahmen!$C$6*((AK5-Annahmen!$C$9+1)/(12-Annahmen!$C$9+1))^Annahmen!$C$10,IF(AK5<=24,Annahmen!$C$6+(Annahmen!$C$7-Annahmen!$C$6)*((AK5-12)/12)^Annahmen!$C$11,Annahmen!$C$7+(Annahmen!$C$8-Annahmen!$C$7)*((AK5-24)/12)^Annahmen!$C$11))) -> 62000
A8: Städte | B8: =IF(B5<=12,Annahmen!$C$12,IF(B5<=24,Annahmen!$C$13,Annahmen!$C$14)) -> 1 | C8: =IF(C5<=12,Annahmen!$C$12,IF(C5<=24,Annahmen!$C$13,Annahmen!$C$14)) -> 1 | D8: =IF(D5<=12,Annahmen!$C$12,IF(D5<=24,Annahmen!$C$13,Annahmen!$C$14)) -> 1 | E8: =IF(E5<=12,Annahmen!$C$12,IF(E5<=24,Annahmen!$C$13,Annahmen!$C$14)) -> 1 | F8: =IF(F5<=12,Annahmen!$C$12,IF(F5<=24,Annahmen!$C$13,Annahmen!$C$14)) -> 1 | G8: =IF(G5<=12,Annahmen!$C$12,IF(G5<=24,Annahmen!$C$13,Annahmen!$C$14)) -> 1 | H8: =IF(H5<=12,Annahmen!$C$12,IF(H5<=24,Annahmen!$C$13,Annahmen!$C$14)) -> 1 | I8: =IF(I5<=12,Annahmen!$C$12,IF(I5<=24,Annahmen!$C$13,Annahmen!$C$14)) -> 1 | ... AK8: =IF(AK5<=12,Annahmen!$C$12,IF(AK5<=24,Annahmen!$C$13,Annahmen!$C$14)) -> 4
A9: Neuregistrierungen (Treiber der Prüfkosten) | B9: =MAX(0,B7-0)+B7*Annahmen!$C$15*(1-Annahmen!$C$16) -> 0 | C9: =MAX(0,C7-B7)+C7*Annahmen!$C$15*(1-Annahmen!$C$16) -> 289.46981 | D9: =MAX(0,D7-C7)+D7*Annahmen!$C$15*(1-Annahmen!$C$16) -> 479.27922 | E9: =MAX(0,E7-D7)+E7*Annahmen!$C$15*(1-Annahmen!$C$16) -> 604.90423 | F9: =MAX(0,F7-E7)+F7*Annahmen!$C$15*(1-Annahmen!$C$16) -> 712.42047 | G9: =MAX(0,G7-F7)+G7*Annahmen!$C$15*(1-Annahmen!$C$16) -> 811.10301 | H9: =MAX(0,H7-G7)+H7*Annahmen!$C$15*(1-Annahmen!$C$16) -> 904.75494 | I9: =MAX(0,I7-H7)+I7*Annahmen!$C$15*(1-Annahmen!$C$16) -> 995.33053 | J9: =MAX(0,J7-I7)+J7*Annahmen!$C$15*(1-Annahmen!$C$16) -> 1083.968 | ... AK9: =MAX(0,AK7-AJ7)+AK7*Annahmen!$C$15*(1-Annahmen!$C$16) -> 7477.0632
A10: Konversion zu Zahlern | B10: =IF(B5<Annahmen!$C$22,0,Annahmen!$C$23*(Annahmen!$C$24+(1-Annahmen!$C$24)*MIN(1,(B5-Annahmen!$C$22+1)/Annahmen!$C$25))) -> 0 | C10: =IF(C5<Annahmen!$C$22,0,Annahmen!$C$23*(Annahmen!$C$24+(1-Annahmen!$C$24)*MIN(1,(C5-Annahmen!$C$22+1)/Annahmen!$C$25))) -> 0 | D10: =IF(D5<Annahmen!$C$22,0,Annahmen!$C$23*(Annahmen!$C$24+(1-Annahmen!$C$24)*MIN(1,(D5-Annahmen!$C$22+1)/Annahmen!$C$25))) -> 0 | E10: =IF(E5<Annahmen!$C$22,0,Annahmen!$C$23*(Annahmen!$C$24+(1-Annahmen!$C$24)*MIN(1,(E5-Annahmen!$C$22+1)/Annahmen!$C$25))) -> 0 | F10: =IF(F5<Annahmen!$C$22,0,Annahmen!$C$23*(Annahmen!$C$24+(1-Annahmen!$C$24)*MIN(1,(F5-Annahmen!$C$22+1)/Annahmen!$C$25))) -> 0 | G10: =IF(G5<Annahmen!$C$22,0,Annahmen!$C$23*(Annahmen!$C$24+(1-Annahmen!$C$24)*MIN(1,(G5-Annahmen!$C$22+1)/Annahmen!$C$25))) -> 0 | H10: =IF(H5<Annahmen!$C$22,0,Annahmen!$C$23*(Annahmen!$C$24+(1-Annahmen!$C$24)*MIN(1,(H5-Annahmen!$C$22+1)/Annahmen!$C$25))) -> 0 | I10: =IF(I5<Annahmen!$C$22,0,Annahmen!$C$23*(Annahmen!$C$24+(1-Annahmen!$C$24)*MIN(1,(I5-Annahmen!$C$22+1)/Annahmen!$C$25))) -> 0 | ... AK10: =IF(AK5<Annahmen!$C$22,0,Annahmen!$C$23*(Annahmen!$C$24+(1-Annahmen!$C$24)*MIN(1,(AK5-Annahmen!$C$22+1)/Annahmen!$C$25))) -> 0.036
A11: Zahlende Nutzer | B11: =B7*B10 -> 0 | C11: =C7*C10 -> 0 | D11: =D7*D10 -> 0 | E11: =E7*E10 -> 0 | F11: =F7*F10 -> 0 | G11: =G7*G10 -> 0 | H11: =H7*H10 -> 0 | I11: =I7*I10 -> 0 | ... AK11: =AK7*AK10 -> 2232
A12: Staffel-Stützstelle (Hilfsgröße) | B12: =MIN(MATCH(B7,Annahmen!$B$80:$F$80,1),4) -> 1 | C12: =MIN(MATCH(C7,Annahmen!$B$80:$F$80,1),4) -> 1 | D12: =MIN(MATCH(D7,Annahmen!$B$80:$F$80,1),4) -> 1 | E12: =MIN(MATCH(E7,Annahmen!$B$80:$F$80,1),4) -> 1 | F12: =MIN(MATCH(F7,Annahmen!$B$80:$F$80,1),4) -> 1 | G12: =MIN(MATCH(G7,Annahmen!$B$80:$F$80,1),4) -> 1 | H12: =MIN(MATCH(H7,Annahmen!$B$80:$F$80,1),4) -> 1 | I12: =MIN(MATCH(I7,Annahmen!$B$80:$F$80,1),4) -> 1 | ... AK12: =MIN(MATCH(AK7,Annahmen!$B$80:$F$80,1),4) -> 4
A13: ERLÖSE — fünf Quellen (Handbuch B, nach Nr. 65 und 74 neu geschnitten)
A14: Abonnements | B14: =B11*Annahmen!$C$26 -> 0 | C14: =C11*Annahmen!$C$26 -> 0 | D14: =D11*Annahmen!$C$26 -> 0 | E14: =E11*Annahmen!$C$26 -> 0 | F14: =F11*Annahmen!$C$26 -> 0 | G14: =G11*Annahmen!$C$26 -> 0 | H14: =H11*Annahmen!$C$26 -> 0 | I14: =I11*Annahmen!$C$26 -> 0 | ... AK14: =AK11*Annahmen!$C$26 -> 16872.531
A15: Werkzeugabo für Orte und Veranstalter | B15: =IF(AND(B5>=Annahmen!$C$62,B7>=Annahmen!$C$63),B8*Annahmen!$C$64*Annahmen!$C$65,0) -> 0 | C15: =IF(AND(C5>=Annahmen!$C$62,C7>=Annahmen!$C$63),C8*Annahmen!$C$64*Annahmen!$C$65,0) -> 0 | D15: =IF(AND(D5>=Annahmen!$C$62,D7>=Annahmen!$C$63),D8*Annahmen!$C$64*Annahmen!$C$65,0) -> 0 | E15: =IF(AND(E5>=Annahmen!$C$62,E7>=Annahmen!$C$63),E8*Annahmen!$C$64*Annahmen!$C$65,0) -> 0 | F15: =IF(AND(F5>=Annahmen!$C$62,F7>=Annahmen!$C$63),F8*Annahmen!$C$64*Annahmen!$C$65,0) -> 0 | G15: =IF(AND(G5>=Annahmen!$C$62,G7>=Annahmen!$C$63),G8*Annahmen!$C$64*Annahmen!$C$65,0) -> 0 | H15: =IF(AND(H5>=Annahmen!$C$62,H7>=Annahmen!$C$63),H8*Annahmen!$C$64*Annahmen!$C$65,0) -> 0 | I15: =IF(AND(I5>=Annahmen!$C$62,I7>=Annahmen!$C$63),I8*Annahmen!$C$64*Annahmen!$C$65,0) -> 0 | ... AK15: =IF(AND(AK5>=Annahmen!$C$62,AK7>=Annahmen!$C$63),AK8*Annahmen!$C$64*Annahmen!$C$65,0) -> 580
A16: Veranstaltungen: Anteil an Tickets | B16: =IF(AND(B5>=Annahmen!$C$66,B7>=Annahmen!$C$67),B8*Annahmen!$C$68*Annahmen!$C$69*Annahmen!$C$70*Annahmen!$C$71,0) -> 0 | C16: =IF(AND(C5>=Annahmen!$C$66,C7>=Annahmen!$C$67),C8*Annahmen!$C$68*Annahmen!$C$69*Annahmen!$C$70*Annahmen!$C$71,0) -> 0 | D16: =IF(AND(D5>=Annahmen!$C$66,D7>=Annahmen!$C$67),D8*Annahmen!$C$68*Annahmen!$C$69*Annahmen!$C$70*Annahmen!$C$71,0) -> 0 | E16: =IF(AND(E5>=Annahmen!$C$66,E7>=Annahmen!$C$67),E8*Annahmen!$C$68*Annahmen!$C$69*Annahmen!$C$70*Annahmen!$C$71,0) -> 0 | F16: =IF(AND(F5>=Annahmen!$C$66,F7>=Annahmen!$C$67),F8*Annahmen!$C$68*Annahmen!$C$69*Annahmen!$C$70*Annahmen!$C$71,0) -> 0 | G16: =IF(AND(G5>=Annahmen!$C$66,G7>=Annahmen!$C$67),G8*Annahmen!$C$68*Annahmen!$C$69*Annahmen!$C$70*Annahmen!$C$71,0) -> 0 | H16: =IF(AND(H5>=Annahmen!$C$66,H7>=Annahmen!$C$67),H8*Annahmen!$C$68*Annahmen!$C$69*Annahmen!$C$70*Annahmen!$C$71,0) -> 0 | I16: =IF(AND(I5>=Annahmen!$C$66,I7>=Annahmen!$C$67),I8*Annahmen!$C$68*Annahmen!$C$69*Annahmen!$C$70*Annahmen!$C$71,0) -> 0 | ... AK16: =IF(AND(AK5>=Annahmen!$C$66,AK7>=Annahmen!$C$67),AK8*Annahmen!$C$68*Annahmen!$C$69*Annahmen!$C$70*Annahmen!$C$71,0) -> 921.6
A17: Unterstützerbeiträge | B17: =IF(B5>=Annahmen!$C$72,B7*Annahmen!$C$73,0) -> 0 | C17: =IF(C5>=Annahmen!$C$72,C7*Annahmen!$C$73,0) -> 0 | D17: =IF(D5>=Annahmen!$C$72,D7*Annahmen!$C$73,0) -> 0 | E17: =IF(E5>=Annahmen!$C$72,E7*Annahmen!$C$73,0) -> 0 | F17: =IF(F5>=Annahmen!$C$72,F7*Annahmen!$C$73,0) -> 0 | G17: =IF(G5>=Annahmen!$C$72,G7*Annahmen!$C$73,0) -> 0 | H17: =IF(H5>=Annahmen!$C$72,H7*Annahmen!$C$73,0) -> 0 | I17: =IF(I5>=Annahmen!$C$72,I7*Annahmen!$C$73,0) -> 0 | ... AK17: =IF(AK5>=Annahmen!$C$72,AK7*Annahmen!$C$73,0) -> 930
A18: Gesundheitspartnerschaft | B18: =IF(B5>=Annahmen!$C$74,B8*Annahmen!$C$75,0) -> 0 | C18: =IF(C5>=Annahmen!$C$74,C8*Annahmen!$C$75,0) -> 0 | D18: =IF(D5>=Annahmen!$C$74,D8*Annahmen!$C$75,0) -> 0 | E18: =IF(E5>=Annahmen!$C$74,E8*Annahmen!$C$75,0) -> 0 | F18: =IF(F5>=Annahmen!$C$74,F8*Annahmen!$C$75,0) -> 0 | G18: =IF(G5>=Annahmen!$C$74,G8*Annahmen!$C$75,0) -> 0 | H18: =IF(H5>=Annahmen!$C$74,H8*Annahmen!$C$75,0) -> 0 | I18: =IF(I5>=Annahmen!$C$74,I8*Annahmen!$C$75,0) -> 0 | ... AK18: =IF(AK5>=Annahmen!$C$74,AK8*Annahmen!$C$75,0) -> 1068
A19: Erlöse gesamt | B19: =SUM(B14:B18) -> 0 | C19: =SUM(C14:C18) -> 0 | D19: =SUM(D14:D18) -> 0 | E19: =SUM(E14:E18) -> 0 | F19: =SUM(F14:F18) -> 0 | G19: =SUM(G14:G18) -> 0 | H19: =SUM(H14:H18) -> 0 | I19: =SUM(I14:I18) -> 0 | ... AK19: =SUM(AK14:AK18) -> 20372.131
A21: KOSTEN
A22: Pflichtpositionen (nicht kürzbar) | B22: =INDEX(Annahmen!$B$94:$F$94,B$12)+(B$7-INDEX(Annahmen!$B$80:$F$80,B$12))*(INDEX(Annahmen!$B$94:$F$94,B$12+1)-INDEX(Annahmen!$B$94:$F$94,B$12))/(INDEX(Annahmen!$B$80:$F$80,B$12+1)-INDEX(Annahmen!$B$80:$F$80,B$12)) -> 1000 | C22: =INDEX(Annahmen!$B$94:$F$94,C$12)+(C$7-INDEX(Annahmen!$B$80:$F$80,C$12))*(INDEX(Annahmen!$B$94:$F$94,C$12+1)-INDEX(Annahmen!$B$94:$F$94,C$12))/(INDEX(Annahmen!$B$80:$F$80,C$12+1)-INDEX(Annahmen!$B$80:$F$80,C$12)) -> 1016.4471 | D22: =INDEX(Annahmen!$B$94:$F$94,D$12)+(D$7-INDEX(Annahmen!$B$80:$F$80,D$12))*(INDEX(Annahmen!$B$94:$F$94,D$12+1)-INDEX(Annahmen!$B$94:$F$94,D$12))/(INDEX(Annahmen!$B$80:$F$80,D$12+1)-INDEX(Annahmen!$B$80:$F$80,D$12)) -> 1042.8067 | E22: =INDEX(Annahmen!$B$94:$F$94,E$12)+(E$7-INDEX(Annahmen!$B$80:$F$80,E$12))*(INDEX(Annahmen!$B$94:$F$94,E$12+1)-INDEX(Annahmen!$B$94:$F$94,E$12))/(INDEX(Annahmen!$B$80:$F$80,E$12+1)-INDEX(Annahmen!$B$80:$F$80,E$12)) -> 1074.9062 | F22: =INDEX(Annahmen!$B$94:$F$94,F$12)+(F$7-INDEX(Annahmen!$B$80:$F$80,F$12))*(INDEX(Annahmen!$B$94:$F$94,F$12+1)-INDEX(Annahmen!$B$94:$F$94,F$12))/(INDEX(Annahmen!$B$80:$F$80,F$12+1)-INDEX(Annahmen!$B$80:$F$80,F$12)) -> 1111.4124 | G22: =INDEX(Annahmen!$B$94:$F$94,G$12)+(G$7-INDEX(Annahmen!$B$80:$F$80,G$12))*(INDEX(Annahmen!$B$94:$F$94,G$12+1)-INDEX(Annahmen!$B$94:$F$94,G$12))/(INDEX(Annahmen!$B$80:$F$80,G$12+1)-INDEX(Annahmen!$B$80:$F$80,G$12)) -> 1151.5895 | H22: =INDEX(Annahmen!$B$94:$F$94,H$12)+(H$7-INDEX(Annahmen!$B$80:$F$80,H$12))*(INDEX(Annahmen!$B$94:$F$94,H$12+1)-INDEX(Annahmen!$B$94:$F$94,H$12))/(INDEX(Annahmen!$B$80:$F$80,H$12+1)-INDEX(Annahmen!$B$80:$F$80,H$12)) -> 1194.9572 | I22: =INDEX(Annahmen!$B$94:$F$94,I$12)+(I$7-INDEX(Annahmen!$B$80:$F$80,I$12))*(INDEX(Annahmen!$B$94:$F$94,I$12+1)-INDEX(Annahmen!$B$94:$F$94,I$12))/(INDEX(Annahmen!$B$80:$F$80,I$12+1)-INDEX(Annahmen!$B$80:$F$80,I$12)) -> 1241.1715 | ... AK22: =INDEX(Annahmen!$B$94:$F$94,AK$12)+(AK$7-INDEX(Annahmen!$B$80:$F$80,AK$12))*(INDEX(Annahmen!$B$94:$F$94,AK$12+1)-INDEX(Annahmen!$B$94:$F$94,AK$12))/(INDEX(Annahmen!$B$80:$F$80,AK$12+1)-INDEX(Annahmen!$B$80:$F$80,AK$12)) -> 3684
A23: Betrieb (ohne Altersprüfung) | B23: =INDEX(Annahmen!$B$95:$F$95,B$12)+(B$7-INDEX(Annahmen!$B$80:$F$80,B$12))*(INDEX(Annahmen!$B$95:$F$95,B$12+1)-INDEX(Annahmen!$B$95:$F$95,B$12))/(INDEX(Annahmen!$B$80:$F$80,B$12+1)-INDEX(Annahmen!$B$80:$F$80,B$12)) -> 270 | C23: =INDEX(Annahmen!$B$95:$F$95,C$12)+(C$7-INDEX(Annahmen!$B$80:$F$80,C$12))*(INDEX(Annahmen!$B$95:$F$95,C$12+1)-INDEX(Annahmen!$B$95:$F$95,C$12))/(INDEX(Annahmen!$B$80:$F$80,C$12+1)-INDEX(Annahmen!$B$80:$F$80,C$12)) -> 277.67534 | D23: =INDEX(Annahmen!$B$95:$F$95,D$12)+(D$7-INDEX(Annahmen!$B$80:$F$80,D$12))*(INDEX(Annahmen!$B$95:$F$95,D$12+1)-INDEX(Annahmen!$B$95:$F$95,D$12))/(INDEX(Annahmen!$B$80:$F$80,D$12+1)-INDEX(Annahmen!$B$80:$F$80,D$12)) -> 289.97647 | E23: =INDEX(Annahmen!$B$95:$F$95,E$12)+(E$7-INDEX(Annahmen!$B$80:$F$80,E$12))*(INDEX(Annahmen!$B$95:$F$95,E$12+1)-INDEX(Annahmen!$B$95:$F$95,E$12))/(INDEX(Annahmen!$B$80:$F$80,E$12+1)-INDEX(Annahmen!$B$80:$F$80,E$12)) -> 304.95624 | F23: =INDEX(Annahmen!$B$95:$F$95,F$12)+(F$7-INDEX(Annahmen!$B$80:$F$80,F$12))*(INDEX(Annahmen!$B$95:$F$95,F$12+1)-INDEX(Annahmen!$B$95:$F$95,F$12))/(INDEX(Annahmen!$B$80:$F$80,F$12+1)-INDEX(Annahmen!$B$80:$F$80,F$12)) -> 321.99244 | G23: =INDEX(Annahmen!$B$95:$F$95,G$12)+(G$7-INDEX(Annahmen!$B$80:$F$80,G$12))*(INDEX(Annahmen!$B$95:$F$95,G$12+1)-INDEX(Annahmen!$B$95:$F$95,G$12))/(INDEX(Annahmen!$B$80:$F$80,G$12+1)-INDEX(Annahmen!$B$80:$F$80,G$12)) -> 340.74178 | H23: =INDEX(Annahmen!$B$95:$F$95,H$12)+(H$7-INDEX(Annahmen!$B$80:$F$80,H$12))*(INDEX(Annahmen!$B$95:$F$95,H$12+1)-INDEX(Annahmen!$B$95:$F$95,H$12))/(INDEX(Annahmen!$B$80:$F$80,H$12+1)-INDEX(Annahmen!$B$80:$F$80,H$12)) -> 360.98004 | I23: =INDEX(Annahmen!$B$95:$F$95,I$12)+(I$7-INDEX(Annahmen!$B$80:$F$80,I$12))*(INDEX(Annahmen!$B$95:$F$95,I$12+1)-INDEX(Annahmen!$B$95:$F$95,I$12))/(INDEX(Annahmen!$B$80:$F$80,I$12+1)-INDEX(Annahmen!$B$80:$F$80,I$12)) -> 382.54668 | ... AK23: =INDEX(Annahmen!$B$95:$F$95,AK$12)+(AK$7-INDEX(Annahmen!$B$80:$F$80,AK$12))*(INDEX(Annahmen!$B$95:$F$95,AK$12+1)-INDEX(Annahmen!$B$95:$F$95,AK$12))/(INDEX(Annahmen!$B$80:$F$80,AK$12+1)-INDEX(Annahmen!$B$80:$F$80,AK$12)) -> 1598
A24: Altersprüfung (Stufe 1 + Stufe 2) ⟵ Schalter | B24: =B9*Annahmen!$B$105+B9*Annahmen!$B$110*Annahmen!$B$111 -> 0 | C24: =C9*Annahmen!$B$105+C9*Annahmen!$B$110*Annahmen!$B$111 -> 164.99779 | D24: =D9*Annahmen!$B$105+D9*Annahmen!$B$110*Annahmen!$B$111 -> 273.18916 | E24: =E9*Annahmen!$B$105+E9*Annahmen!$B$110*Annahmen!$B$111 -> 344.79541 | F24: =F9*Annahmen!$B$105+F9*Annahmen!$B$110*Annahmen!$B$111 -> 406.07967 | G24: =G9*Annahmen!$B$105+G9*Annahmen!$B$110*Annahmen!$B$111 -> 462.32872 | H24: =H9*Annahmen!$B$105+H9*Annahmen!$B$110*Annahmen!$B$111 -> 515.71032 | I24: =I9*Annahmen!$B$105+I9*Annahmen!$B$110*Annahmen!$B$111 -> 567.3384 | ... AK24: =AK9*Annahmen!$B$105+AK9*Annahmen!$B$110*Annahmen!$B$111 -> 4261.926
A25: SMS-Versand (Z-10) | B25: =B9*Annahmen!$C$146*Annahmen!$C$147*Annahmen!$C$148 -> 0 | C25: =C9*Annahmen!$C$146*Annahmen!$C$147*Annahmen!$C$148 -> 13.547187 | D25: =D9*Annahmen!$C$146*Annahmen!$C$147*Annahmen!$C$148 -> 22.430268 | E25: =E9*Annahmen!$C$146*Annahmen!$C$147*Annahmen!$C$148 -> 28.309518 | F25: =F9*Annahmen!$C$146*Annahmen!$C$147*Annahmen!$C$148 -> 33.341278 | G25: =G9*Annahmen!$C$146*Annahmen!$C$147*Annahmen!$C$148 -> 37.959621 | H25: =H9*Annahmen!$C$146*Annahmen!$C$147*Annahmen!$C$148 -> 42.342531 | I25: =I9*Annahmen!$C$146*Annahmen!$C$147*Annahmen!$C$148 -> 46.581469 | ... AK25: =AK9*Annahmen!$C$146*Annahmen!$C$147*Annahmen!$C$148 -> 349.92656
A26: Personal: Moderation | B26: =INDEX(Annahmen!$B$96:$F$96,B$12)+(B$7-INDEX(Annahmen!$B$80:$F$80,B$12))*(INDEX(Annahmen!$B$96:$F$96,B$12+1)-INDEX(Annahmen!$B$96:$F$96,B$12))/(INDEX(Annahmen!$B$80:$F$80,B$12+1)-INDEX(Annahmen!$B$80:$F$80,B$12)) -> 0 | C26: =INDEX(Annahmen!$B$96:$F$96,C$12)+(C$7-INDEX(Annahmen!$B$80:$F$80,C$12))*(INDEX(Annahmen!$B$96:$F$96,C$12+1)-INDEX(Annahmen!$B$96:$F$96,C$12))/(INDEX(Annahmen!$B$80:$F$80,C$12+1)-INDEX(Annahmen!$B$80:$F$80,C$12)) -> 0 | D26: =INDEX(Annahmen!$B$96:$F$96,D$12)+(D$7-INDEX(Annahmen!$B$80:$F$80,D$12))*(INDEX(Annahmen!$B$96:$F$96,D$12+1)-INDEX(Annahmen!$B$96:$F$96,D$12))/(INDEX(Annahmen!$B$80:$F$80,D$12+1)-INDEX(Annahmen!$B$80:$F$80,D$12)) -> 0 | E26: =INDEX(Annahmen!$B$96:$F$96,E$12)+(E$7-INDEX(Annahmen!$B$80:$F$80,E$12))*(INDEX(Annahmen!$B$96:$F$96,E$12+1)-INDEX(Annahmen!$B$96:$F$96,E$12))/(INDEX(Annahmen!$B$80:$F$80,E$12+1)-INDEX(Annahmen!$B$80:$F$80,E$12)) -> 0 | F26: =INDEX(Annahmen!$B$96:$F$96,F$12)+(F$7-INDEX(Annahmen!$B$80:$F$80,F$12))*(INDEX(Annahmen!$B$96:$F$96,F$12+1)-INDEX(Annahmen!$B$96:$F$96,F$12))/(INDEX(Annahmen!$B$80:$F$80,F$12+1)-INDEX(Annahmen!$B$80:$F$80,F$12)) -> 0 | G26: =INDEX(Annahmen!$B$96:$F$96,G$12)+(G$7-INDEX(Annahmen!$B$80:$F$80,G$12))*(INDEX(Annahmen!$B$96:$F$96,G$12+1)-INDEX(Annahmen!$B$96:$F$96,G$12))/(INDEX(Annahmen!$B$80:$F$80,G$12+1)-INDEX(Annahmen!$B$80:$F$80,G$12)) -> 0 | H26: =INDEX(Annahmen!$B$96:$F$96,H$12)+(H$7-INDEX(Annahmen!$B$80:$F$80,H$12))*(INDEX(Annahmen!$B$96:$F$96,H$12+1)-INDEX(Annahmen!$B$96:$F$96,H$12))/(INDEX(Annahmen!$B$80:$F$80,H$12+1)-INDEX(Annahmen!$B$80:$F$80,H$12)) -> 0 | I26: =INDEX(Annahmen!$B$96:$F$96,I$12)+(I$7-INDEX(Annahmen!$B$80:$F$80,I$12))*(INDEX(Annahmen!$B$96:$F$96,I$12+1)-INDEX(Annahmen!$B$96:$F$96,I$12))/(INDEX(Annahmen!$B$80:$F$80,I$12+1)-INDEX(Annahmen!$B$80:$F$80,I$12)) -> 0 | ... AK26: =INDEX(Annahmen!$B$96:$F$96,AK$12)+(AK$7-INDEX(Annahmen!$B$80:$F$80,AK$12))*(INDEX(Annahmen!$B$96:$F$96,AK$12+1)-INDEX(Annahmen!$B$96:$F$96,AK$12))/(INDEX(Annahmen!$B$80:$F$80,AK$12+1)-INDEX(Annahmen!$B$80:$F$80,AK$12)) -> 4080
A27: Marketing (Barmittel) | B27: =INDEX(Annahmen!$B$97:$F$97,B$12)+(B$7-INDEX(Annahmen!$B$80:$F$80,B$12))*(INDEX(Annahmen!$B$97:$F$97,B$12+1)-INDEX(Annahmen!$B$97:$F$97,B$12))/(INDEX(Annahmen!$B$80:$F$80,B$12+1)-INDEX(Annahmen!$B$80:$F$80,B$12)) -> 150 | C27: =INDEX(Annahmen!$B$97:$F$97,C$12)+(C$7-INDEX(Annahmen!$B$80:$F$80,C$12))*(INDEX(Annahmen!$B$97:$F$97,C$12+1)-INDEX(Annahmen!$B$97:$F$97,C$12))/(INDEX(Annahmen!$B$80:$F$80,C$12+1)-INDEX(Annahmen!$B$80:$F$80,C$12)) -> 155.48238 | D27: =INDEX(Annahmen!$B$97:$F$97,D$12)+(D$7-INDEX(Annahmen!$B$80:$F$80,D$12))*(INDEX(Annahmen!$B$97:$F$97,D$12+1)-INDEX(Annahmen!$B$97:$F$97,D$12))/(INDEX(Annahmen!$B$80:$F$80,D$12+1)-INDEX(Annahmen!$B$80:$F$80,D$12)) -> 164.26891 | E27: =INDEX(Annahmen!$B$97:$F$97,E$12)+(E$7-INDEX(Annahmen!$B$80:$F$80,E$12))*(INDEX(Annahmen!$B$97:$F$97,E$12+1)-INDEX(Annahmen!$B$97:$F$97,E$12))/(INDEX(Annahmen!$B$80:$F$80,E$12+1)-INDEX(Annahmen!$B$80:$F$80,E$12)) -> 174.96874 | F27: =INDEX(Annahmen!$B$97:$F$97,F$12)+(F$7-INDEX(Annahmen!$B$80:$F$80,F$12))*(INDEX(Annahmen!$B$97:$F$97,F$12+1)-INDEX(Annahmen!$B$97:$F$97,F$12))/(INDEX(Annahmen!$B$80:$F$80,F$12+1)-INDEX(Annahmen!$B$80:$F$80,F$12)) -> 187.13746 | G27: =INDEX(Annahmen!$B$97:$F$97,G$12)+(G$7-INDEX(Annahmen!$B$80:$F$80,G$12))*(INDEX(Annahmen!$B$97:$F$97,G$12+1)-INDEX(Annahmen!$B$97:$F$97,G$12))/(INDEX(Annahmen!$B$80:$F$80,G$12+1)-INDEX(Annahmen!$B$80:$F$80,G$12)) -> 200.52984 | H27: =INDEX(Annahmen!$B$97:$F$97,H$12)+(H$7-INDEX(Annahmen!$B$80:$F$80,H$12))*(INDEX(Annahmen!$B$97:$F$97,H$12+1)-INDEX(Annahmen!$B$97:$F$97,H$12))/(INDEX(Annahmen!$B$80:$F$80,H$12+1)-INDEX(Annahmen!$B$80:$F$80,H$12)) -> 214.98574 | I27: =INDEX(Annahmen!$B$97:$F$97,I$12)+(I$7-INDEX(Annahmen!$B$80:$F$80,I$12))*(INDEX(Annahmen!$B$97:$F$97,I$12+1)-INDEX(Annahmen!$B$97:$F$97,I$12))/(INDEX(Annahmen!$B$80:$F$80,I$12+1)-INDEX(Annahmen!$B$80:$F$80,I$12)) -> 230.39048 | ... AK27: =INDEX(Annahmen!$B$97:$F$97,AK$12)+(AK$7-INDEX(Annahmen!$B$80:$F$80,AK$12))*(INDEX(Annahmen!$B$97:$F$97,AK$12+1)-INDEX(Annahmen!$B$97:$F$97,AK$12))/(INDEX(Annahmen!$B$80:$F$80,AK$12+1)-INDEX(Annahmen!$B$80:$F$80,AK$12)) -> 1440
A28: Eigene Veranstaltungen (Nr. 74) | B28: =IF(B5>=Annahmen!$C$145,B8*Annahmen!$C$144/12,0) -> 166.66667 | C28: =IF(C5>=Annahmen!$C$145,C8*Annahmen!$C$144/12,0) -> 166.66667 | D28: =IF(D5>=Annahmen!$C$145,D8*Annahmen!$C$144/12,0) -> 166.66667 | E28: =IF(E5>=Annahmen!$C$145,E8*Annahmen!$C$144/12,0) -> 166.66667 | F28: =IF(F5>=Annahmen!$C$145,F8*Annahmen!$C$144/12,0) -> 166.66667 | G28: =IF(G5>=Annahmen!$C$145,G8*Annahmen!$C$144/12,0) -> 166.66667 | H28: =IF(H5>=Annahmen!$C$145,H8*Annahmen!$C$144/12,0) -> 166.66667 | I28: =IF(I5>=Annahmen!$C$145,I8*Annahmen!$C$144/12,0) -> 166.66667 | ... AK28: =IF(AK5>=Annahmen!$C$145,AK8*Annahmen!$C$144/12,0) -> 666.66667
A29: CSD-Auftritte (zum Start und Folgejahre) | B29: =IF(B5=Annahmen!$C$136,Annahmen!$C$135,0)+IF(B5=Annahmen!$C$138,Annahmen!$C$137,0)+IF(B5=Annahmen!$C$140,Annahmen!$C$139,0) -> 6000 | C29: =IF(C5=Annahmen!$C$136,Annahmen!$C$135,0)+IF(C5=Annahmen!$C$138,Annahmen!$C$137,0)+IF(C5=Annahmen!$C$140,Annahmen!$C$139,0) -> 0 | D29: =IF(D5=Annahmen!$C$136,Annahmen!$C$135,0)+IF(D5=Annahmen!$C$138,Annahmen!$C$137,0)+IF(D5=Annahmen!$C$140,Annahmen!$C$139,0) -> 0 | E29: =IF(E5=Annahmen!$C$136,Annahmen!$C$135,0)+IF(E5=Annahmen!$C$138,Annahmen!$C$137,0)+IF(E5=Annahmen!$C$140,Annahmen!$C$139,0) -> 0 | F29: =IF(F5=Annahmen!$C$136,Annahmen!$C$135,0)+IF(F5=Annahmen!$C$138,Annahmen!$C$137,0)+IF(F5=Annahmen!$C$140,Annahmen!$C$139,0) -> 0 | G29: =IF(G5=Annahmen!$C$136,Annahmen!$C$135,0)+IF(G5=Annahmen!$C$138,Annahmen!$C$137,0)+IF(G5=Annahmen!$C$140,Annahmen!$C$139,0) -> 0 | H29: =IF(H5=Annahmen!$C$136,Annahmen!$C$135,0)+IF(H5=Annahmen!$C$138,Annahmen!$C$137,0)+IF(H5=Annahmen!$C$140,Annahmen!$C$139,0) -> 0 | I29: =IF(I5=Annahmen!$C$136,Annahmen!$C$135,0)+IF(I5=Annahmen!$C$138,Annahmen!$C$137,0)+IF(I5=Annahmen!$C$140,Annahmen!$C$139,0) -> 0 | ... AK29: =IF(AK5=Annahmen!$C$136,Annahmen!$C$135,0)+IF(AK5=Annahmen!$C$138,Annahmen!$C$137,0)+IF(AK5=Annahmen!$C$140,Annahmen!$C$139,0) -> 0
